2021-05-17 00:03:52,182 - INFO: Started server process [12244]
2021-05-17 00:03:52,182 - INFO: Waiting for application startup.
2021-05-17 00:03:52,183 - INFO: Application startup complete.
2021-05-17 00:03:54,652 - ERROR: Exception in ASGI application
Traceback (most recent call last):
  File "c:\users\lucas\appdata\local\pypoetry\cache\virtualenvs\app-r1mvpay6-py3.8\lib\site-packages\uvicorn\protocols\http\h11_impl.py", line 396, in run_asgi
    result = await app(self.scope, self.receive, self.send)
  File "c:\users\lucas\appdata\local\pypoetry\cache\virtualenvs\app-r1mvpay6-py3.8\lib\site-packages\uvicorn\middleware\proxy_headers.py", line 45, in __call__
    return await self.app(scope, receive, send)
  File "c:\users\lucas\appdata\local\pypoetry\cache\virtualenvs\app-r1mvpay6-py3.8\lib\site-packages\fastapi\applications.py", line 199, in __call__
    await super().__call__(scope, receive, send)
  File "c:\users\lucas\appdata\local\pypoetry\cache\virtualenvs\app-r1mvpay6-py3.8\lib\site-packages\starlette\applications.py", line 112, in __call__
    await self.middleware_stack(scope, receive, send)
  File "c:\users\lucas\appdata\local\pypoetry\cache\virtualenvs\app-r1mvpay6-py3.8\lib\site-packages\starlette\middleware\errors.py", line 181, in __call__
    raise exc from None
  File "c:\users\lucas\appdata\local\pypoetry\cache\virtualenvs\app-r1mvpay6-py3.8\lib\site-packages\starlette\middleware\errors.py", line 159, in __call__
    await self.app(scope, receive, _send)
  File "c:\users\lucas\appdata\local\pypoetry\cache\virtualenvs\app-r1mvpay6-py3.8\lib\site-packages\starlette\exceptions.py", line 82, in __call__
    raise exc from None
  File "c:\users\lucas\appdata\local\pypoetry\cache\virtualenvs\app-r1mvpay6-py3.8\lib\site-packages\starlette\exceptions.py", line 71, in __call__
    await self.app(scope, receive, sender)
  File "c:\users\lucas\appdata\local\pypoetry\cache\virtualenvs\app-r1mvpay6-py3.8\lib\site-packages\starlette\routing.py", line 580, in __call__
    await route.handle(scope, receive, send)
  File "c:\users\lucas\appdata\local\pypoetry\cache\virtualenvs\app-r1mvpay6-py3.8\lib\site-packages\starlette\routing.py", line 241, in handle
    await self.app(scope, receive, send)
  File "c:\users\lucas\appdata\local\pypoetry\cache\virtualenvs\app-r1mvpay6-py3.8\lib\site-packages\starlette\routing.py", line 52, in app
    response = await func(request)
  File "c:\users\lucas\appdata\local\pypoetry\cache\virtualenvs\app-r1mvpay6-py3.8\lib\site-packages\fastapi\routing.py", line 201, in app
    raw_response = await run_endpoint_function(
  File "c:\users\lucas\appdata\local\pypoetry\cache\virtualenvs\app-r1mvpay6-py3.8\lib\site-packages\fastapi\routing.py", line 148, in run_endpoint_function
    return await dependant.call(**values)
  File ".\app\main.py", line 58, in get_cats
    logger.info('Querying all cats that have {} as coat length.'.format(coat_length))
NameError: name 'logger' is not defined
2021-05-17 00:04:07,722 - INFO: Started server process [16832]
2021-05-17 00:04:07,723 - INFO: Waiting for application startup.
2021-05-17 00:04:07,723 - INFO: Application startup complete.
2021-05-17 00:04:33,309 - INFO: Started server process [17076]
2021-05-17 00:04:33,309 - INFO: Waiting for application startup.
2021-05-17 00:04:33,309 - INFO: Application startup complete.
2021-05-17 00:04:33,402 - INFO: Querying all cats that have 4 as coat length.
2021-05-17 00:10:07,161 - INFO: Started server process [7596]
2021-05-17 00:10:07,161 - INFO: Waiting for application startup.
2021-05-17 00:10:07,161 - INFO: Application startup complete.
2021-05-17 00:10:18,356 - INFO: Querying all cats that have asdsad as breed.
2021-05-17 00:10:45,293 - ERROR: Body type must be Small, Medium or Large
2021-05-17 00:11:06,067 - INFO: Added asdasd cat from asdasd, with 1 coat length, Small body type and dassda pattern.
2021-05-17 00:11:39,607 - ERROR: Breed already exists.
2021-05-17 00:11:47,647 - ERROR: Body type must be Small, Medium or Large
2021-05-17 00:12:05,984 - INFO: Started server process [12484]
2021-05-17 00:12:05,985 - INFO: Waiting for application startup.
2021-05-17 00:12:05,985 - INFO: Application startup complete.
2021-05-17 00:12:22,334 - ERROR: Exception in ASGI application
Traceback (most recent call last):
  File "c:\users\lucas\appdata\local\pypoetry\cache\virtualenvs\app-r1mvpay6-py3.8\lib\site-packages\uvicorn\protocols\http\h11_impl.py", line 396, in run_asgi
    result = await app(self.scope, self.receive, self.send)
  File "c:\users\lucas\appdata\local\pypoetry\cache\virtualenvs\app-r1mvpay6-py3.8\lib\site-packages\uvicorn\middleware\proxy_headers.py", line 45, in __call__
    return await self.app(scope, receive, send)
  File "c:\users\lucas\appdata\local\pypoetry\cache\virtualenvs\app-r1mvpay6-py3.8\lib\site-packages\fastapi\applications.py", line 199, in __call__
    await super().__call__(scope, receive, send)
  File "c:\users\lucas\appdata\local\pypoetry\cache\virtualenvs\app-r1mvpay6-py3.8\lib\site-packages\starlette\applications.py", line 112, in __call__
    await self.middleware_stack(scope, receive, send)
  File "c:\users\lucas\appdata\local\pypoetry\cache\virtualenvs\app-r1mvpay6-py3.8\lib\site-packages\starlette\middleware\errors.py", line 181, in __call__
    raise exc from None
  File "c:\users\lucas\appdata\local\pypoetry\cache\virtualenvs\app-r1mvpay6-py3.8\lib\site-packages\starlette\middleware\errors.py", line 159, in __call__
    await self.app(scope, receive, _send)
  File "c:\users\lucas\appdata\local\pypoetry\cache\virtualenvs\app-r1mvpay6-py3.8\lib\site-packages\starlette\exceptions.py", line 82, in __call__
    raise exc from None
  File "c:\users\lucas\appdata\local\pypoetry\cache\virtualenvs\app-r1mvpay6-py3.8\lib\site-packages\starlette\exceptions.py", line 71, in __call__
    await self.app(scope, receive, sender)
  File "c:\users\lucas\appdata\local\pypoetry\cache\virtualenvs\app-r1mvpay6-py3.8\lib\site-packages\starlette\routing.py", line 580, in __call__
    await route.handle(scope, receive, send)
  File "c:\users\lucas\appdata\local\pypoetry\cache\virtualenvs\app-r1mvpay6-py3.8\lib\site-packages\starlette\routing.py", line 241, in handle
    await self.app(scope, receive, send)
  File "c:\users\lucas\appdata\local\pypoetry\cache\virtualenvs\app-r1mvpay6-py3.8\lib\site-packages\starlette\routing.py", line 52, in app
    response = await func(request)
  File "c:\users\lucas\appdata\local\pypoetry\cache\virtualenvs\app-r1mvpay6-py3.8\lib\site-packages\fastapi\routing.py", line 201, in app
    raw_response = await run_endpoint_function(
  File "c:\users\lucas\appdata\local\pypoetry\cache\virtualenvs\app-r1mvpay6-py3.8\lib\site-packages\fastapi\routing.py", line 148, in run_endpoint_function
    return await dependant.call(**values)
  File ".\app\main.py", line 98, in add_cat
    if body_type.captalize() not in body_types:
AttributeError: 'str' object has no attribute 'captalize'
2021-05-17 00:12:57,121 - INFO: Started server process [3740]
2021-05-17 00:12:57,122 - INFO: Waiting for application startup.
2021-05-17 00:12:57,122 - INFO: Application startup complete.
2021-05-17 00:13:08,083 - ERROR: Exception in ASGI application
Traceback (most recent call last):
  File "c:\users\lucas\appdata\local\pypoetry\cache\virtualenvs\app-r1mvpay6-py3.8\lib\site-packages\uvicorn\protocols\http\h11_impl.py", line 396, in run_asgi
    result = await app(self.scope, self.receive, self.send)
  File "c:\users\lucas\appdata\local\pypoetry\cache\virtualenvs\app-r1mvpay6-py3.8\lib\site-packages\uvicorn\middleware\proxy_headers.py", line 45, in __call__
    return await self.app(scope, receive, send)
  File "c:\users\lucas\appdata\local\pypoetry\cache\virtualenvs\app-r1mvpay6-py3.8\lib\site-packages\fastapi\applications.py", line 199, in __call__
    await super().__call__(scope, receive, send)
  File "c:\users\lucas\appdata\local\pypoetry\cache\virtualenvs\app-r1mvpay6-py3.8\lib\site-packages\starlette\applications.py", line 112, in __call__
    await self.middleware_stack(scope, receive, send)
  File "c:\users\lucas\appdata\local\pypoetry\cache\virtualenvs\app-r1mvpay6-py3.8\lib\site-packages\starlette\middleware\errors.py", line 181, in __call__
    raise exc from None
  File "c:\users\lucas\appdata\local\pypoetry\cache\virtualenvs\app-r1mvpay6-py3.8\lib\site-packages\starlette\middleware\errors.py", line 159, in __call__
    await self.app(scope, receive, _send)
  File "c:\users\lucas\appdata\local\pypoetry\cache\virtualenvs\app-r1mvpay6-py3.8\lib\site-packages\starlette\exceptions.py", line 82, in __call__
    raise exc from None
  File "c:\users\lucas\appdata\local\pypoetry\cache\virtualenvs\app-r1mvpay6-py3.8\lib\site-packages\starlette\exceptions.py", line 71, in __call__
    await self.app(scope, receive, sender)
  File "c:\users\lucas\appdata\local\pypoetry\cache\virtualenvs\app-r1mvpay6-py3.8\lib\site-packages\starlette\routing.py", line 580, in __call__
    await route.handle(scope, receive, send)
  File "c:\users\lucas\appdata\local\pypoetry\cache\virtualenvs\app-r1mvpay6-py3.8\lib\site-packages\starlette\routing.py", line 241, in handle
    await self.app(scope, receive, send)
  File "c:\users\lucas\appdata\local\pypoetry\cache\virtualenvs\app-r1mvpay6-py3.8\lib\site-packages\starlette\routing.py", line 52, in app
    response = await func(request)
  File "c:\users\lucas\appdata\local\pypoetry\cache\virtualenvs\app-r1mvpay6-py3.8\lib\site-packages\fastapi\routing.py", line 201, in app
    raw_response = await run_endpoint_function(
  File "c:\users\lucas\appdata\local\pypoetry\cache\virtualenvs\app-r1mvpay6-py3.8\lib\site-packages\fastapi\routing.py", line 148, in run_endpoint_function
    return await dependant.call(**values)
  File ".\app\main.py", line 94, in add_cat
    new_cat['body_type'] = body_type.captalize()
AttributeError: 'str' object has no attribute 'captalize'
2021-05-17 00:15:26,536 - INFO: Started server process [8392]
2021-05-17 00:15:26,537 - INFO: Waiting for application startup.
2021-05-17 00:15:26,537 - INFO: Application startup complete.
2021-05-17 00:15:36,170 - ERROR: Exception in ASGI application
Traceback (most recent call last):
  File "c:\users\lucas\appdata\local\pypoetry\cache\virtualenvs\app-r1mvpay6-py3.8\lib\site-packages\uvicorn\protocols\http\h11_impl.py", line 396, in run_asgi
    result = await app(self.scope, self.receive, self.send)
  File "c:\users\lucas\appdata\local\pypoetry\cache\virtualenvs\app-r1mvpay6-py3.8\lib\site-packages\uvicorn\middleware\proxy_headers.py", line 45, in __call__
    return await self.app(scope, receive, send)
  File "c:\users\lucas\appdata\local\pypoetry\cache\virtualenvs\app-r1mvpay6-py3.8\lib\site-packages\fastapi\applications.py", line 199, in __call__
    await super().__call__(scope, receive, send)
  File "c:\users\lucas\appdata\local\pypoetry\cache\virtualenvs\app-r1mvpay6-py3.8\lib\site-packages\starlette\applications.py", line 112, in __call__
    await self.middleware_stack(scope, receive, send)
  File "c:\users\lucas\appdata\local\pypoetry\cache\virtualenvs\app-r1mvpay6-py3.8\lib\site-packages\starlette\middleware\errors.py", line 181, in __call__
    raise exc from None
  File "c:\users\lucas\appdata\local\pypoetry\cache\virtualenvs\app-r1mvpay6-py3.8\lib\site-packages\starlette\middleware\errors.py", line 159, in __call__
    await self.app(scope, receive, _send)
  File "c:\users\lucas\appdata\local\pypoetry\cache\virtualenvs\app-r1mvpay6-py3.8\lib\site-packages\starlette\exceptions.py", line 82, in __call__
    raise exc from None
  File "c:\users\lucas\appdata\local\pypoetry\cache\virtualenvs\app-r1mvpay6-py3.8\lib\site-packages\starlette\exceptions.py", line 71, in __call__
    await self.app(scope, receive, sender)
  File "c:\users\lucas\appdata\local\pypoetry\cache\virtualenvs\app-r1mvpay6-py3.8\lib\site-packages\starlette\routing.py", line 580, in __call__
    await route.handle(scope, receive, send)
  File "c:\users\lucas\appdata\local\pypoetry\cache\virtualenvs\app-r1mvpay6-py3.8\lib\site-packages\starlette\routing.py", line 241, in handle
    await self.app(scope, receive, send)
  File "c:\users\lucas\appdata\local\pypoetry\cache\virtualenvs\app-r1mvpay6-py3.8\lib\site-packages\starlette\routing.py", line 52, in app
    response = await func(request)
  File "c:\users\lucas\appdata\local\pypoetry\cache\virtualenvs\app-r1mvpay6-py3.8\lib\site-packages\fastapi\routing.py", line 201, in app
    raw_response = await run_endpoint_function(
  File "c:\users\lucas\appdata\local\pypoetry\cache\virtualenvs\app-r1mvpay6-py3.8\lib\site-packages\fastapi\routing.py", line 148, in run_endpoint_function
    return await dependant.call(**values)
  File ".\app\main.py", line 94, in add_cat
    body_type = body_type.captalize()
AttributeError: 'str' object has no attribute 'captalize'
2021-05-17 00:17:19,778 - INFO: Started server process [5176]
2021-05-17 00:17:19,779 - INFO: Waiting for application startup.
2021-05-17 00:17:19,779 - INFO: Application startup complete.
2021-05-17 00:17:29,748 - ERROR: Body type must be Small, Medium or Large
2021-05-17 00:18:49,743 - INFO: Started server process [14316]
2021-05-17 00:18:49,744 - INFO: Waiting for application startup.
2021-05-17 00:18:49,744 - INFO: Application startup complete.
2021-05-17 00:19:00,579 - ERROR: Body type must be Small, Medium or Large
2021-05-17 00:19:24,187 - INFO: Started server process [7320]
2021-05-17 00:19:24,187 - INFO: Waiting for application startup.
2021-05-17 00:19:24,187 - INFO: Application startup complete.
2021-05-17 00:19:32,717 - INFO: Added asdasd cat from asdasd, with 1 coat length, Small body type and asasda pattern.
2021-05-17 00:20:44,781 - INFO: Started server process [14692]
2021-05-17 00:20:44,782 - INFO: Waiting for application startup.
2021-05-17 00:20:44,782 - INFO: Application startup complete.
2021-05-17 00:21:37,779 - INFO: Started server process [2400]
2021-05-17 00:21:37,779 - INFO: Waiting for application startup.
2021-05-17 00:21:37,780 - INFO: Application startup complete.
2021-05-17 00:21:54,076 - INFO: Added Asdasd cat from Adsdas, with 2 coat length, Large body type and Dads pattern.
2021-05-17 00:24:28,286 - INFO: Started server process [2560]
2021-05-17 00:24:28,287 - INFO: Waiting for application startup.
2021-05-17 00:24:28,287 - INFO: Application startup complete.
2021-05-17 00:31:53,155 - INFO: Started server process [6028]
2021-05-17 00:31:53,156 - INFO: Waiting for application startup.
2021-05-17 00:31:53,156 - INFO: Application startup complete.
2021-05-17 00:32:06,222 - INFO: Started server process [9980]
2021-05-17 00:32:06,222 - INFO: Waiting for application startup.
2021-05-17 00:32:06,223 - INFO: Application startup complete.
2021-05-17 00:32:30,684 - ERROR: Exception in ASGI application
Traceback (most recent call last):
  File "c:\users\lucas\appdata\local\pypoetry\cache\virtualenvs\app-r1mvpay6-py3.8\lib\site-packages\uvicorn\protocols\http\h11_impl.py", line 396, in run_asgi
    result = await app(self.scope, self.receive, self.send)
  File "c:\users\lucas\appdata\local\pypoetry\cache\virtualenvs\app-r1mvpay6-py3.8\lib\site-packages\uvicorn\middleware\proxy_headers.py", line 45, in __call__
    return await self.app(scope, receive, send)
  File "c:\users\lucas\appdata\local\pypoetry\cache\virtualenvs\app-r1mvpay6-py3.8\lib\site-packages\fastapi\applications.py", line 199, in __call__
    await super().__call__(scope, receive, send)
  File "c:\users\lucas\appdata\local\pypoetry\cache\virtualenvs\app-r1mvpay6-py3.8\lib\site-packages\starlette\applications.py", line 112, in __call__
    await self.middleware_stack(scope, receive, send)
  File "c:\users\lucas\appdata\local\pypoetry\cache\virtualenvs\app-r1mvpay6-py3.8\lib\site-packages\starlette\middleware\errors.py", line 181, in __call__
    raise exc from None
  File "c:\users\lucas\appdata\local\pypoetry\cache\virtualenvs\app-r1mvpay6-py3.8\lib\site-packages\starlette\middleware\errors.py", line 159, in __call__
    await self.app(scope, receive, _send)
  File "c:\users\lucas\appdata\local\pypoetry\cache\virtualenvs\app-r1mvpay6-py3.8\lib\site-packages\starlette\exceptions.py", line 82, in __call__
    raise exc from None
  File "c:\users\lucas\appdata\local\pypoetry\cache\virtualenvs\app-r1mvpay6-py3.8\lib\site-packages\starlette\exceptions.py", line 71, in __call__
    await self.app(scope, receive, sender)
  File "c:\users\lucas\appdata\local\pypoetry\cache\virtualenvs\app-r1mvpay6-py3.8\lib\site-packages\starlette\routing.py", line 580, in __call__
    await route.handle(scope, receive, send)
  File "c:\users\lucas\appdata\local\pypoetry\cache\virtualenvs\app-r1mvpay6-py3.8\lib\site-packages\starlette\routing.py", line 241, in handle
    await self.app(scope, receive, send)
  File "c:\users\lucas\appdata\local\pypoetry\cache\virtualenvs\app-r1mvpay6-py3.8\lib\site-packages\starlette\routing.py", line 52, in app
    response = await func(request)
  File "c:\users\lucas\appdata\local\pypoetry\cache\virtualenvs\app-r1mvpay6-py3.8\lib\site-packages\fastapi\routing.py", line 201, in app
    raw_response = await run_endpoint_function(
  File "c:\users\lucas\appdata\local\pypoetry\cache\virtualenvs\app-r1mvpay6-py3.8\lib\site-packages\fastapi\routing.py", line 148, in run_endpoint_function
    return await dependant.call(**values)
  File ".\app\main.py", line 123, in update_cat
    if (cat.breed == breed):
AttributeError: 'dict' object has no attribute 'breed'
2021-05-17 00:33:13,362 - INFO: Started server process [16624]
2021-05-17 00:33:13,362 - INFO: Waiting for application startup.
2021-05-17 00:33:13,363 - INFO: Application startup complete.
2021-05-17 00:33:29,336 - ERROR: Exception in ASGI application
Traceback (most recent call last):
  File "c:\users\lucas\appdata\local\pypoetry\cache\virtualenvs\app-r1mvpay6-py3.8\lib\site-packages\uvicorn\protocols\http\h11_impl.py", line 396, in run_asgi
    result = await app(self.scope, self.receive, self.send)
  File "c:\users\lucas\appdata\local\pypoetry\cache\virtualenvs\app-r1mvpay6-py3.8\lib\site-packages\uvicorn\middleware\proxy_headers.py", line 45, in __call__
    return await self.app(scope, receive, send)
  File "c:\users\lucas\appdata\local\pypoetry\cache\virtualenvs\app-r1mvpay6-py3.8\lib\site-packages\fastapi\applications.py", line 199, in __call__
    await super().__call__(scope, receive, send)
  File "c:\users\lucas\appdata\local\pypoetry\cache\virtualenvs\app-r1mvpay6-py3.8\lib\site-packages\starlette\applications.py", line 112, in __call__
    await self.middleware_stack(scope, receive, send)
  File "c:\users\lucas\appdata\local\pypoetry\cache\virtualenvs\app-r1mvpay6-py3.8\lib\site-packages\starlette\middleware\errors.py", line 181, in __call__
    raise exc from None
  File "c:\users\lucas\appdata\local\pypoetry\cache\virtualenvs\app-r1mvpay6-py3.8\lib\site-packages\starlette\middleware\errors.py", line 159, in __call__
    await self.app(scope, receive, _send)
  File "c:\users\lucas\appdata\local\pypoetry\cache\virtualenvs\app-r1mvpay6-py3.8\lib\site-packages\starlette\exceptions.py", line 82, in __call__
    raise exc from None
  File "c:\users\lucas\appdata\local\pypoetry\cache\virtualenvs\app-r1mvpay6-py3.8\lib\site-packages\starlette\exceptions.py", line 71, in __call__
    await self.app(scope, receive, sender)
  File "c:\users\lucas\appdata\local\pypoetry\cache\virtualenvs\app-r1mvpay6-py3.8\lib\site-packages\starlette\routing.py", line 580, in __call__
    await route.handle(scope, receive, send)
  File "c:\users\lucas\appdata\local\pypoetry\cache\virtualenvs\app-r1mvpay6-py3.8\lib\site-packages\starlette\routing.py", line 241, in handle
    await self.app(scope, receive, send)
  File "c:\users\lucas\appdata\local\pypoetry\cache\virtualenvs\app-r1mvpay6-py3.8\lib\site-packages\starlette\routing.py", line 52, in app
    response = await func(request)
  File "c:\users\lucas\appdata\local\pypoetry\cache\virtualenvs\app-r1mvpay6-py3.8\lib\site-packages\fastapi\routing.py", line 201, in app
    raw_response = await run_endpoint_function(
  File "c:\users\lucas\appdata\local\pypoetry\cache\virtualenvs\app-r1mvpay6-py3.8\lib\site-packages\fastapi\routing.py", line 148, in run_endpoint_function
    return await dependant.call(**values)
  File ".\app\main.py", line 121, in update_cat
    if (cat.breed == breed):
AttributeError: 'dict' object has no attribute 'breed'
2021-05-17 00:34:16,248 - INFO: Started server process [17304]
2021-05-17 00:34:16,248 - INFO: Waiting for application startup.
2021-05-17 00:34:16,248 - INFO: Application startup complete.
2021-05-17 00:34:19,206 - ERROR: Exception in ASGI application
Traceback (most recent call last):
  File "c:\users\lucas\appdata\local\pypoetry\cache\virtualenvs\app-r1mvpay6-py3.8\lib\site-packages\uvicorn\protocols\http\h11_impl.py", line 396, in run_asgi
    result = await app(self.scope, self.receive, self.send)
  File "c:\users\lucas\appdata\local\pypoetry\cache\virtualenvs\app-r1mvpay6-py3.8\lib\site-packages\uvicorn\middleware\proxy_headers.py", line 45, in __call__
    return await self.app(scope, receive, send)
  File "c:\users\lucas\appdata\local\pypoetry\cache\virtualenvs\app-r1mvpay6-py3.8\lib\site-packages\fastapi\applications.py", line 199, in __call__
    await super().__call__(scope, receive, send)
  File "c:\users\lucas\appdata\local\pypoetry\cache\virtualenvs\app-r1mvpay6-py3.8\lib\site-packages\starlette\applications.py", line 112, in __call__
    await self.middleware_stack(scope, receive, send)
  File "c:\users\lucas\appdata\local\pypoetry\cache\virtualenvs\app-r1mvpay6-py3.8\lib\site-packages\starlette\middleware\errors.py", line 181, in __call__
    raise exc from None
  File "c:\users\lucas\appdata\local\pypoetry\cache\virtualenvs\app-r1mvpay6-py3.8\lib\site-packages\starlette\middleware\errors.py", line 159, in __call__
    await self.app(scope, receive, _send)
  File "c:\users\lucas\appdata\local\pypoetry\cache\virtualenvs\app-r1mvpay6-py3.8\lib\site-packages\starlette\exceptions.py", line 82, in __call__
    raise exc from None
  File "c:\users\lucas\appdata\local\pypoetry\cache\virtualenvs\app-r1mvpay6-py3.8\lib\site-packages\starlette\exceptions.py", line 71, in __call__
    await self.app(scope, receive, sender)
  File "c:\users\lucas\appdata\local\pypoetry\cache\virtualenvs\app-r1mvpay6-py3.8\lib\site-packages\starlette\routing.py", line 580, in __call__
    await route.handle(scope, receive, send)
  File "c:\users\lucas\appdata\local\pypoetry\cache\virtualenvs\app-r1mvpay6-py3.8\lib\site-packages\starlette\routing.py", line 241, in handle
    await self.app(scope, receive, send)
  File "c:\users\lucas\appdata\local\pypoetry\cache\virtualenvs\app-r1mvpay6-py3.8\lib\site-packages\starlette\routing.py", line 52, in app
    response = await func(request)
  File "c:\users\lucas\appdata\local\pypoetry\cache\virtualenvs\app-r1mvpay6-py3.8\lib\site-packages\fastapi\routing.py", line 201, in app
    raw_response = await run_endpoint_function(
  File "c:\users\lucas\appdata\local\pypoetry\cache\virtualenvs\app-r1mvpay6-py3.8\lib\site-packages\fastapi\routing.py", line 148, in run_endpoint_function
    return await dependant.call(**values)
  File ".\app\main.py", line 121, in update_cat
    if (Cat.breed == breed):
AttributeError: type object 'Cat' has no attribute 'breed'
2021-05-17 00:34:22,447 - INFO: Started server process [8824]
2021-05-17 00:34:22,447 - INFO: Waiting for application startup.
2021-05-17 00:34:22,448 - INFO: Application startup complete.
2021-05-17 00:34:28,610 - INFO: Started server process [13412]
2021-05-17 00:34:28,610 - INFO: Waiting for application startup.
2021-05-17 00:34:28,611 - INFO: Application startup complete.
2021-05-17 00:34:37,651 - ERROR: Exception in ASGI application
Traceback (most recent call last):
  File "c:\users\lucas\appdata\local\pypoetry\cache\virtualenvs\app-r1mvpay6-py3.8\lib\site-packages\uvicorn\protocols\http\h11_impl.py", line 396, in run_asgi
    result = await app(self.scope, self.receive, self.send)
  File "c:\users\lucas\appdata\local\pypoetry\cache\virtualenvs\app-r1mvpay6-py3.8\lib\site-packages\uvicorn\middleware\proxy_headers.py", line 45, in __call__
    return await self.app(scope, receive, send)
  File "c:\users\lucas\appdata\local\pypoetry\cache\virtualenvs\app-r1mvpay6-py3.8\lib\site-packages\fastapi\applications.py", line 199, in __call__
    await super().__call__(scope, receive, send)
  File "c:\users\lucas\appdata\local\pypoetry\cache\virtualenvs\app-r1mvpay6-py3.8\lib\site-packages\starlette\applications.py", line 112, in __call__
    await self.middleware_stack(scope, receive, send)
  File "c:\users\lucas\appdata\local\pypoetry\cache\virtualenvs\app-r1mvpay6-py3.8\lib\site-packages\starlette\middleware\errors.py", line 181, in __call__
    raise exc from None
  File "c:\users\lucas\appdata\local\pypoetry\cache\virtualenvs\app-r1mvpay6-py3.8\lib\site-packages\starlette\middleware\errors.py", line 159, in __call__
    await self.app(scope, receive, _send)
  File "c:\users\lucas\appdata\local\pypoetry\cache\virtualenvs\app-r1mvpay6-py3.8\lib\site-packages\starlette\exceptions.py", line 82, in __call__
    raise exc from None
  File "c:\users\lucas\appdata\local\pypoetry\cache\virtualenvs\app-r1mvpay6-py3.8\lib\site-packages\starlette\exceptions.py", line 71, in __call__
    await self.app(scope, receive, sender)
  File "c:\users\lucas\appdata\local\pypoetry\cache\virtualenvs\app-r1mvpay6-py3.8\lib\site-packages\starlette\routing.py", line 580, in __call__
    await route.handle(scope, receive, send)
  File "c:\users\lucas\appdata\local\pypoetry\cache\virtualenvs\app-r1mvpay6-py3.8\lib\site-packages\starlette\routing.py", line 241, in handle
    await self.app(scope, receive, send)
  File "c:\users\lucas\appdata\local\pypoetry\cache\virtualenvs\app-r1mvpay6-py3.8\lib\site-packages\starlette\routing.py", line 52, in app
    response = await func(request)
  File "c:\users\lucas\appdata\local\pypoetry\cache\virtualenvs\app-r1mvpay6-py3.8\lib\site-packages\fastapi\routing.py", line 201, in app
    raw_response = await run_endpoint_function(
  File "c:\users\lucas\appdata\local\pypoetry\cache\virtualenvs\app-r1mvpay6-py3.8\lib\site-packages\fastapi\routing.py", line 148, in run_endpoint_function
    return await dependant.call(**values)
  File ".\app\main.py", line 122, in update_cat
    update_cat = cat.dict()
AttributeError: 'dict' object has no attribute 'dict'
2021-05-17 00:35:48,400 - INFO: Started server process [10408]
2021-05-17 00:35:48,400 - INFO: Waiting for application startup.
2021-05-17 00:35:48,401 - INFO: Application startup complete.
2021-05-17 00:36:02,971 - ERROR: Exception in ASGI application
Traceback (most recent call last):
  File "c:\users\lucas\appdata\local\pypoetry\cache\virtualenvs\app-r1mvpay6-py3.8\lib\site-packages\uvicorn\protocols\http\h11_impl.py", line 396, in run_asgi
    result = await app(self.scope, self.receive, self.send)
  File "c:\users\lucas\appdata\local\pypoetry\cache\virtualenvs\app-r1mvpay6-py3.8\lib\site-packages\uvicorn\middleware\proxy_headers.py", line 45, in __call__
    return await self.app(scope, receive, send)
  File "c:\users\lucas\appdata\local\pypoetry\cache\virtualenvs\app-r1mvpay6-py3.8\lib\site-packages\fastapi\applications.py", line 199, in __call__
    await super().__call__(scope, receive, send)
  File "c:\users\lucas\appdata\local\pypoetry\cache\virtualenvs\app-r1mvpay6-py3.8\lib\site-packages\starlette\applications.py", line 112, in __call__
    await self.middleware_stack(scope, receive, send)
  File "c:\users\lucas\appdata\local\pypoetry\cache\virtualenvs\app-r1mvpay6-py3.8\lib\site-packages\starlette\middleware\errors.py", line 181, in __call__
    raise exc from None
  File "c:\users\lucas\appdata\local\pypoetry\cache\virtualenvs\app-r1mvpay6-py3.8\lib\site-packages\starlette\middleware\errors.py", line 159, in __call__
    await self.app(scope, receive, _send)
  File "c:\users\lucas\appdata\local\pypoetry\cache\virtualenvs\app-r1mvpay6-py3.8\lib\site-packages\starlette\exceptions.py", line 82, in __call__
    raise exc from None
  File "c:\users\lucas\appdata\local\pypoetry\cache\virtualenvs\app-r1mvpay6-py3.8\lib\site-packages\starlette\exceptions.py", line 71, in __call__
    await self.app(scope, receive, sender)
  File "c:\users\lucas\appdata\local\pypoetry\cache\virtualenvs\app-r1mvpay6-py3.8\lib\site-packages\starlette\routing.py", line 580, in __call__
    await route.handle(scope, receive, send)
  File "c:\users\lucas\appdata\local\pypoetry\cache\virtualenvs\app-r1mvpay6-py3.8\lib\site-packages\starlette\routing.py", line 241, in handle
    await self.app(scope, receive, send)
  File "c:\users\lucas\appdata\local\pypoetry\cache\virtualenvs\app-r1mvpay6-py3.8\lib\site-packages\starlette\routing.py", line 52, in app
    response = await func(request)
  File "c:\users\lucas\appdata\local\pypoetry\cache\virtualenvs\app-r1mvpay6-py3.8\lib\site-packages\fastapi\routing.py", line 201, in app
    raw_response = await run_endpoint_function(
  File "c:\users\lucas\appdata\local\pypoetry\cache\virtualenvs\app-r1mvpay6-py3.8\lib\site-packages\fastapi\routing.py", line 148, in run_endpoint_function
    return await dependant.call(**values)
  File ".\app\main.py", line 122, in update_cat
    update_cat = cat.dict()
AttributeError: 'dict' object has no attribute 'dict'
2021-05-17 00:37:14,893 - INFO: Started server process [8684]
2021-05-17 00:37:14,894 - INFO: Waiting for application startup.
2021-05-17 00:37:14,894 - INFO: Application startup complete.
2021-05-17 00:37:15,977 - ERROR: Body type must be Small, Medium or Large
2021-05-17 00:37:33,871 - INFO: Started server process [15420]
2021-05-17 00:37:33,871 - INFO: Waiting for application startup.
2021-05-17 00:37:33,871 - INFO: Application startup complete.
2021-05-17 00:38:14,985 - INFO: Started server process [10236]
2021-05-17 00:38:14,986 - INFO: Waiting for application startup.
2021-05-17 00:38:14,986 - INFO: Application startup complete.
2021-05-17 00:38:17,255 - WARNING: Cat not found.
2021-05-17 00:38:31,890 - ERROR: Body type must be Small, Medium or Large
2021-05-17 00:38:47,707 - ERROR: Coat length must be equal or greater than 0.
2021-05-17 00:39:02,754 - ERROR: Exception in ASGI application
Traceback (most recent call last):
  File "c:\users\lucas\appdata\local\pypoetry\cache\virtualenvs\app-r1mvpay6-py3.8\lib\site-packages\uvicorn\protocols\http\h11_impl.py", line 396, in run_asgi
    result = await app(self.scope, self.receive, self.send)
  File "c:\users\lucas\appdata\local\pypoetry\cache\virtualenvs\app-r1mvpay6-py3.8\lib\site-packages\uvicorn\middleware\proxy_headers.py", line 45, in __call__
    return await self.app(scope, receive, send)
  File "c:\users\lucas\appdata\local\pypoetry\cache\virtualenvs\app-r1mvpay6-py3.8\lib\site-packages\fastapi\applications.py", line 199, in __call__
    await super().__call__(scope, receive, send)
  File "c:\users\lucas\appdata\local\pypoetry\cache\virtualenvs\app-r1mvpay6-py3.8\lib\site-packages\starlette\applications.py", line 112, in __call__
    await self.middleware_stack(scope, receive, send)
  File "c:\users\lucas\appdata\local\pypoetry\cache\virtualenvs\app-r1mvpay6-py3.8\lib\site-packages\starlette\middleware\errors.py", line 181, in __call__
    raise exc from None
  File "c:\users\lucas\appdata\local\pypoetry\cache\virtualenvs\app-r1mvpay6-py3.8\lib\site-packages\starlette\middleware\errors.py", line 159, in __call__
    await self.app(scope, receive, _send)
  File "c:\users\lucas\appdata\local\pypoetry\cache\virtualenvs\app-r1mvpay6-py3.8\lib\site-packages\starlette\exceptions.py", line 82, in __call__
    raise exc from None
  File "c:\users\lucas\appdata\local\pypoetry\cache\virtualenvs\app-r1mvpay6-py3.8\lib\site-packages\starlette\exceptions.py", line 71, in __call__
    await self.app(scope, receive, sender)
  File "c:\users\lucas\appdata\local\pypoetry\cache\virtualenvs\app-r1mvpay6-py3.8\lib\site-packages\starlette\routing.py", line 580, in __call__
    await route.handle(scope, receive, send)
  File "c:\users\lucas\appdata\local\pypoetry\cache\virtualenvs\app-r1mvpay6-py3.8\lib\site-packages\starlette\routing.py", line 241, in handle
    await self.app(scope, receive, send)
  File "c:\users\lucas\appdata\local\pypoetry\cache\virtualenvs\app-r1mvpay6-py3.8\lib\site-packages\starlette\routing.py", line 52, in app
    response = await func(request)
  File "c:\users\lucas\appdata\local\pypoetry\cache\virtualenvs\app-r1mvpay6-py3.8\lib\site-packages\fastapi\routing.py", line 201, in app
    raw_response = await run_endpoint_function(
  File "c:\users\lucas\appdata\local\pypoetry\cache\virtualenvs\app-r1mvpay6-py3.8\lib\site-packages\fastapi\routing.py", line 148, in run_endpoint_function
    return await dependant.call(**values)
  File ".\app\main.py", line 147, in update_cat
    cats.update(update_cat)
AttributeError: 'list' object has no attribute 'update'
2021-05-17 00:40:41,080 - INFO: Started server process [13500]
2021-05-17 00:40:41,080 - INFO: Waiting for application startup.
2021-05-17 00:40:41,081 - INFO: Application startup complete.
2021-05-17 00:40:43,403 - ERROR: Exception in ASGI application
Traceback (most recent call last):
  File "c:\users\lucas\appdata\local\pypoetry\cache\virtualenvs\app-r1mvpay6-py3.8\lib\site-packages\uvicorn\protocols\http\h11_impl.py", line 396, in run_asgi
    result = await app(self.scope, self.receive, self.send)
  File "c:\users\lucas\appdata\local\pypoetry\cache\virtualenvs\app-r1mvpay6-py3.8\lib\site-packages\uvicorn\middleware\proxy_headers.py", line 45, in __call__
    return await self.app(scope, receive, send)
  File "c:\users\lucas\appdata\local\pypoetry\cache\virtualenvs\app-r1mvpay6-py3.8\lib\site-packages\fastapi\applications.py", line 199, in __call__
    await super().__call__(scope, receive, send)
  File "c:\users\lucas\appdata\local\pypoetry\cache\virtualenvs\app-r1mvpay6-py3.8\lib\site-packages\starlette\applications.py", line 112, in __call__
    await self.middleware_stack(scope, receive, send)
  File "c:\users\lucas\appdata\local\pypoetry\cache\virtualenvs\app-r1mvpay6-py3.8\lib\site-packages\starlette\middleware\errors.py", line 181, in __call__
    raise exc from None
  File "c:\users\lucas\appdata\local\pypoetry\cache\virtualenvs\app-r1mvpay6-py3.8\lib\site-packages\starlette\middleware\errors.py", line 159, in __call__
    await self.app(scope, receive, _send)
  File "c:\users\lucas\appdata\local\pypoetry\cache\virtualenvs\app-r1mvpay6-py3.8\lib\site-packages\starlette\exceptions.py", line 82, in __call__
    raise exc from None
  File "c:\users\lucas\appdata\local\pypoetry\cache\virtualenvs\app-r1mvpay6-py3.8\lib\site-packages\starlette\exceptions.py", line 71, in __call__
    await self.app(scope, receive, sender)
  File "c:\users\lucas\appdata\local\pypoetry\cache\virtualenvs\app-r1mvpay6-py3.8\lib\site-packages\starlette\routing.py", line 580, in __call__
    await route.handle(scope, receive, send)
  File "c:\users\lucas\appdata\local\pypoetry\cache\virtualenvs\app-r1mvpay6-py3.8\lib\site-packages\starlette\routing.py", line 241, in handle
    await self.app(scope, receive, send)
  File "c:\users\lucas\appdata\local\pypoetry\cache\virtualenvs\app-r1mvpay6-py3.8\lib\site-packages\starlette\routing.py", line 52, in app
    response = await func(request)
  File "c:\users\lucas\appdata\local\pypoetry\cache\virtualenvs\app-r1mvpay6-py3.8\lib\site-packages\fastapi\routing.py", line 201, in app
    raw_response = await run_endpoint_function(
  File "c:\users\lucas\appdata\local\pypoetry\cache\virtualenvs\app-r1mvpay6-py3.8\lib\site-packages\fastapi\routing.py", line 148, in run_endpoint_function
    return await dependant.call(**values)
  File ".\app\main.py", line 147, in update_cat
    cats.update(update_cat)
AttributeError: 'list' object has no attribute 'update'
2021-05-17 00:43:51,884 - INFO: Started server process [10016]
2021-05-17 00:43:51,885 - INFO: Waiting for application startup.
2021-05-17 00:43:51,885 - INFO: Application startup complete.
2021-05-17 00:44:01,742 - WARNING: Cat not found.
2021-05-17 00:44:08,774 - ERROR: Body type must be Small, Medium or Large
2021-05-17 00:44:14,275 - INFO: Updated Siamese cat from Dasdsad, with 1 coat length, Small body type and Asddsa pattern.
2021-05-17 00:44:14,276 - ERROR: Exception in ASGI application
Traceback (most recent call last):
  File "c:\users\lucas\appdata\local\pypoetry\cache\virtualenvs\app-r1mvpay6-py3.8\lib\site-packages\uvicorn\protocols\http\h11_impl.py", line 396, in run_asgi
    result = await app(self.scope, self.receive, self.send)
  File "c:\users\lucas\appdata\local\pypoetry\cache\virtualenvs\app-r1mvpay6-py3.8\lib\site-packages\uvicorn\middleware\proxy_headers.py", line 45, in __call__
    return await self.app(scope, receive, send)
  File "c:\users\lucas\appdata\local\pypoetry\cache\virtualenvs\app-r1mvpay6-py3.8\lib\site-packages\fastapi\applications.py", line 199, in __call__
    await super().__call__(scope, receive, send)
  File "c:\users\lucas\appdata\local\pypoetry\cache\virtualenvs\app-r1mvpay6-py3.8\lib\site-packages\starlette\applications.py", line 112, in __call__
    await self.middleware_stack(scope, receive, send)
  File "c:\users\lucas\appdata\local\pypoetry\cache\virtualenvs\app-r1mvpay6-py3.8\lib\site-packages\starlette\middleware\errors.py", line 181, in __call__
    raise exc from None
  File "c:\users\lucas\appdata\local\pypoetry\cache\virtualenvs\app-r1mvpay6-py3.8\lib\site-packages\starlette\middleware\errors.py", line 159, in __call__
    await self.app(scope, receive, _send)
  File "c:\users\lucas\appdata\local\pypoetry\cache\virtualenvs\app-r1mvpay6-py3.8\lib\site-packages\starlette\exceptions.py", line 82, in __call__
    raise exc from None
  File "c:\users\lucas\appdata\local\pypoetry\cache\virtualenvs\app-r1mvpay6-py3.8\lib\site-packages\starlette\exceptions.py", line 71, in __call__
    await self.app(scope, receive, sender)
  File "c:\users\lucas\appdata\local\pypoetry\cache\virtualenvs\app-r1mvpay6-py3.8\lib\site-packages\starlette\routing.py", line 580, in __call__
    await route.handle(scope, receive, send)
  File "c:\users\lucas\appdata\local\pypoetry\cache\virtualenvs\app-r1mvpay6-py3.8\lib\site-packages\starlette\routing.py", line 241, in handle
    await self.app(scope, receive, send)
  File "c:\users\lucas\appdata\local\pypoetry\cache\virtualenvs\app-r1mvpay6-py3.8\lib\site-packages\starlette\routing.py", line 52, in app
    response = await func(request)
  File "c:\users\lucas\appdata\local\pypoetry\cache\virtualenvs\app-r1mvpay6-py3.8\lib\site-packages\fastapi\routing.py", line 209, in app
    response_data = await serialize_response(
  File "c:\users\lucas\appdata\local\pypoetry\cache\virtualenvs\app-r1mvpay6-py3.8\lib\site-packages\fastapi\routing.py", line 126, in serialize_response
    raise ValidationError(errors, field.type_)
pydantic.error_wrappers.ValidationError: 1 validation error for Cat
response
  value is not a valid list (type=type_error.list)
2021-05-17 00:45:06,261 - INFO: Started server process [13252]
2021-05-17 00:45:06,262 - INFO: Waiting for application startup.
2021-05-17 00:45:06,262 - INFO: Application startup complete.
2021-05-17 00:45:09,115 - INFO: Updated Siamese cat from Dasdsad, with 1 coat length, Small body type and Asddsa pattern.
2021-05-17 00:45:09,116 - ERROR: Exception in ASGI application
Traceback (most recent call last):
  File "c:\users\lucas\appdata\local\pypoetry\cache\virtualenvs\app-r1mvpay6-py3.8\lib\site-packages\uvicorn\protocols\http\h11_impl.py", line 396, in run_asgi
    result = await app(self.scope, self.receive, self.send)
  File "c:\users\lucas\appdata\local\pypoetry\cache\virtualenvs\app-r1mvpay6-py3.8\lib\site-packages\uvicorn\middleware\proxy_headers.py", line 45, in __call__
    return await self.app(scope, receive, send)
  File "c:\users\lucas\appdata\local\pypoetry\cache\virtualenvs\app-r1mvpay6-py3.8\lib\site-packages\fastapi\applications.py", line 199, in __call__
    await super().__call__(scope, receive, send)
  File "c:\users\lucas\appdata\local\pypoetry\cache\virtualenvs\app-r1mvpay6-py3.8\lib\site-packages\starlette\applications.py", line 112, in __call__
    await self.middleware_stack(scope, receive, send)
  File "c:\users\lucas\appdata\local\pypoetry\cache\virtualenvs\app-r1mvpay6-py3.8\lib\site-packages\starlette\middleware\errors.py", line 181, in __call__
    raise exc from None
  File "c:\users\lucas\appdata\local\pypoetry\cache\virtualenvs\app-r1mvpay6-py3.8\lib\site-packages\starlette\middleware\errors.py", line 159, in __call__
    await self.app(scope, receive, _send)
  File "c:\users\lucas\appdata\local\pypoetry\cache\virtualenvs\app-r1mvpay6-py3.8\lib\site-packages\starlette\exceptions.py", line 82, in __call__
    raise exc from None
  File "c:\users\lucas\appdata\local\pypoetry\cache\virtualenvs\app-r1mvpay6-py3.8\lib\site-packages\starlette\exceptions.py", line 71, in __call__
    await self.app(scope, receive, sender)
  File "c:\users\lucas\appdata\local\pypoetry\cache\virtualenvs\app-r1mvpay6-py3.8\lib\site-packages\starlette\routing.py", line 580, in __call__
    await route.handle(scope, receive, send)
  File "c:\users\lucas\appdata\local\pypoetry\cache\virtualenvs\app-r1mvpay6-py3.8\lib\site-packages\starlette\routing.py", line 241, in handle
    await self.app(scope, receive, send)
  File "c:\users\lucas\appdata\local\pypoetry\cache\virtualenvs\app-r1mvpay6-py3.8\lib\site-packages\starlette\routing.py", line 52, in app
    response = await func(request)
  File "c:\users\lucas\appdata\local\pypoetry\cache\virtualenvs\app-r1mvpay6-py3.8\lib\site-packages\fastapi\routing.py", line 209, in app
    response_data = await serialize_response(
  File "c:\users\lucas\appdata\local\pypoetry\cache\virtualenvs\app-r1mvpay6-py3.8\lib\site-packages\fastapi\routing.py", line 126, in serialize_response
    raise ValidationError(errors, field.type_)
pydantic.error_wrappers.ValidationError: 1 validation error for Cat
response
  value is not a valid list (type=type_error.list)
2021-05-17 00:45:19,142 - INFO: Started server process [10408]
2021-05-17 00:45:19,143 - INFO: Waiting for application startup.
2021-05-17 00:45:19,143 - INFO: Application startup complete.
2021-05-17 00:45:28,821 - ERROR: Exception in ASGI application
Traceback (most recent call last):
  File "c:\users\lucas\appdata\local\pypoetry\cache\virtualenvs\app-r1mvpay6-py3.8\lib\site-packages\uvicorn\protocols\http\h11_impl.py", line 396, in run_asgi
    result = await app(self.scope, self.receive, self.send)
  File "c:\users\lucas\appdata\local\pypoetry\cache\virtualenvs\app-r1mvpay6-py3.8\lib\site-packages\uvicorn\middleware\proxy_headers.py", line 45, in __call__
    return await self.app(scope, receive, send)
  File "c:\users\lucas\appdata\local\pypoetry\cache\virtualenvs\app-r1mvpay6-py3.8\lib\site-packages\fastapi\applications.py", line 199, in __call__
    await super().__call__(scope, receive, send)
  File "c:\users\lucas\appdata\local\pypoetry\cache\virtualenvs\app-r1mvpay6-py3.8\lib\site-packages\starlette\applications.py", line 112, in __call__
    await self.middleware_stack(scope, receive, send)
  File "c:\users\lucas\appdata\local\pypoetry\cache\virtualenvs\app-r1mvpay6-py3.8\lib\site-packages\starlette\middleware\errors.py", line 181, in __call__
    raise exc from None
  File "c:\users\lucas\appdata\local\pypoetry\cache\virtualenvs\app-r1mvpay6-py3.8\lib\site-packages\starlette\middleware\errors.py", line 159, in __call__
    await self.app(scope, receive, _send)
  File "c:\users\lucas\appdata\local\pypoetry\cache\virtualenvs\app-r1mvpay6-py3.8\lib\site-packages\starlette\exceptions.py", line 82, in __call__
    raise exc from None
  File "c:\users\lucas\appdata\local\pypoetry\cache\virtualenvs\app-r1mvpay6-py3.8\lib\site-packages\starlette\exceptions.py", line 71, in __call__
    await self.app(scope, receive, sender)
  File "c:\users\lucas\appdata\local\pypoetry\cache\virtualenvs\app-r1mvpay6-py3.8\lib\site-packages\starlette\routing.py", line 580, in __call__
    await route.handle(scope, receive, send)
  File "c:\users\lucas\appdata\local\pypoetry\cache\virtualenvs\app-r1mvpay6-py3.8\lib\site-packages\starlette\routing.py", line 241, in handle
    await self.app(scope, receive, send)
  File "c:\users\lucas\appdata\local\pypoetry\cache\virtualenvs\app-r1mvpay6-py3.8\lib\site-packages\starlette\routing.py", line 52, in app
    response = await func(request)
  File "c:\users\lucas\appdata\local\pypoetry\cache\virtualenvs\app-r1mvpay6-py3.8\lib\site-packages\fastapi\routing.py", line 201, in app
    raw_response = await run_endpoint_function(
  File "c:\users\lucas\appdata\local\pypoetry\cache\virtualenvs\app-r1mvpay6-py3.8\lib\site-packages\fastapi\routing.py", line 148, in run_endpoint_function
    return await dependant.call(**values)
  File ".\app\main.py", line 147, in update_cat
    cats.update(update_cat)
AttributeError: 'list' object has no attribute 'update'
2021-05-17 00:45:58,070 - INFO: Started server process [712]
2021-05-17 00:45:58,071 - INFO: Waiting for application startup.
2021-05-17 00:45:58,071 - INFO: Application startup complete.
2021-05-17 00:46:00,204 - INFO: Updated Siamese cat from Asdsad, with 1 coat length, Small body type and Sadds pattern.
2021-05-17 00:46:00,205 - ERROR: Exception in ASGI application
Traceback (most recent call last):
  File "c:\users\lucas\appdata\local\pypoetry\cache\virtualenvs\app-r1mvpay6-py3.8\lib\site-packages\uvicorn\protocols\http\h11_impl.py", line 396, in run_asgi
    result = await app(self.scope, self.receive, self.send)
  File "c:\users\lucas\appdata\local\pypoetry\cache\virtualenvs\app-r1mvpay6-py3.8\lib\site-packages\uvicorn\middleware\proxy_headers.py", line 45, in __call__
    return await self.app(scope, receive, send)
  File "c:\users\lucas\appdata\local\pypoetry\cache\virtualenvs\app-r1mvpay6-py3.8\lib\site-packages\fastapi\applications.py", line 199, in __call__
    await super().__call__(scope, receive, send)
  File "c:\users\lucas\appdata\local\pypoetry\cache\virtualenvs\app-r1mvpay6-py3.8\lib\site-packages\starlette\applications.py", line 112, in __call__
    await self.middleware_stack(scope, receive, send)
  File "c:\users\lucas\appdata\local\pypoetry\cache\virtualenvs\app-r1mvpay6-py3.8\lib\site-packages\starlette\middleware\errors.py", line 181, in __call__
    raise exc from None
  File "c:\users\lucas\appdata\local\pypoetry\cache\virtualenvs\app-r1mvpay6-py3.8\lib\site-packages\starlette\middleware\errors.py", line 159, in __call__
    await self.app(scope, receive, _send)
  File "c:\users\lucas\appdata\local\pypoetry\cache\virtualenvs\app-r1mvpay6-py3.8\lib\site-packages\starlette\exceptions.py", line 82, in __call__
    raise exc from None
  File "c:\users\lucas\appdata\local\pypoetry\cache\virtualenvs\app-r1mvpay6-py3.8\lib\site-packages\starlette\exceptions.py", line 71, in __call__
    await self.app(scope, receive, sender)
  File "c:\users\lucas\appdata\local\pypoetry\cache\virtualenvs\app-r1mvpay6-py3.8\lib\site-packages\starlette\routing.py", line 580, in __call__
    await route.handle(scope, receive, send)
  File "c:\users\lucas\appdata\local\pypoetry\cache\virtualenvs\app-r1mvpay6-py3.8\lib\site-packages\starlette\routing.py", line 241, in handle
    await self.app(scope, receive, send)
  File "c:\users\lucas\appdata\local\pypoetry\cache\virtualenvs\app-r1mvpay6-py3.8\lib\site-packages\starlette\routing.py", line 52, in app
    response = await func(request)
  File "c:\users\lucas\appdata\local\pypoetry\cache\virtualenvs\app-r1mvpay6-py3.8\lib\site-packages\fastapi\routing.py", line 209, in app
    response_data = await serialize_response(
  File "c:\users\lucas\appdata\local\pypoetry\cache\virtualenvs\app-r1mvpay6-py3.8\lib\site-packages\fastapi\routing.py", line 126, in serialize_response
    raise ValidationError(errors, field.type_)
pydantic.error_wrappers.ValidationError: 1 validation error for Cat
response
  value is not a valid list (type=type_error.list)
2021-05-17 00:46:05,719 - INFO: Started server process [11436]
2021-05-17 00:46:05,719 - INFO: Waiting for application startup.
2021-05-17 00:46:05,720 - INFO: Application startup complete.
2021-05-17 00:46:10,127 - ERROR: Exception in ASGI application
Traceback (most recent call last):
  File "c:\users\lucas\appdata\local\pypoetry\cache\virtualenvs\app-r1mvpay6-py3.8\lib\site-packages\uvicorn\protocols\http\h11_impl.py", line 396, in run_asgi
    result = await app(self.scope, self.receive, self.send)
  File "c:\users\lucas\appdata\local\pypoetry\cache\virtualenvs\app-r1mvpay6-py3.8\lib\site-packages\uvicorn\middleware\proxy_headers.py", line 45, in __call__
    return await self.app(scope, receive, send)
  File "c:\users\lucas\appdata\local\pypoetry\cache\virtualenvs\app-r1mvpay6-py3.8\lib\site-packages\fastapi\applications.py", line 199, in __call__
    await super().__call__(scope, receive, send)
  File "c:\users\lucas\appdata\local\pypoetry\cache\virtualenvs\app-r1mvpay6-py3.8\lib\site-packages\starlette\applications.py", line 112, in __call__
    await self.middleware_stack(scope, receive, send)
  File "c:\users\lucas\appdata\local\pypoetry\cache\virtualenvs\app-r1mvpay6-py3.8\lib\site-packages\starlette\middleware\errors.py", line 181, in __call__
    raise exc from None
  File "c:\users\lucas\appdata\local\pypoetry\cache\virtualenvs\app-r1mvpay6-py3.8\lib\site-packages\starlette\middleware\errors.py", line 159, in __call__
    await self.app(scope, receive, _send)
  File "c:\users\lucas\appdata\local\pypoetry\cache\virtualenvs\app-r1mvpay6-py3.8\lib\site-packages\starlette\exceptions.py", line 82, in __call__
    raise exc from None
  File "c:\users\lucas\appdata\local\pypoetry\cache\virtualenvs\app-r1mvpay6-py3.8\lib\site-packages\starlette\exceptions.py", line 71, in __call__
    await self.app(scope, receive, sender)
  File "c:\users\lucas\appdata\local\pypoetry\cache\virtualenvs\app-r1mvpay6-py3.8\lib\site-packages\starlette\routing.py", line 580, in __call__
    await route.handle(scope, receive, send)
  File "c:\users\lucas\appdata\local\pypoetry\cache\virtualenvs\app-r1mvpay6-py3.8\lib\site-packages\starlette\routing.py", line 241, in handle
    await self.app(scope, receive, send)
  File "c:\users\lucas\appdata\local\pypoetry\cache\virtualenvs\app-r1mvpay6-py3.8\lib\site-packages\starlette\routing.py", line 52, in app
    response = await func(request)
  File "c:\users\lucas\appdata\local\pypoetry\cache\virtualenvs\app-r1mvpay6-py3.8\lib\site-packages\fastapi\routing.py", line 201, in app
    raw_response = await run_endpoint_function(
  File "c:\users\lucas\appdata\local\pypoetry\cache\virtualenvs\app-r1mvpay6-py3.8\lib\site-packages\fastapi\routing.py", line 148, in run_endpoint_function
    return await dependant.call(**values)
  File ".\app\main.py", line 147, in update_cat
    cats.update(update_cat)
AttributeError: 'list' object has no attribute 'update'
2021-05-17 00:49:42,825 - INFO: Started server process [5688]
2021-05-17 00:49:42,825 - INFO: Waiting for application startup.
2021-05-17 00:49:42,826 - INFO: Application startup complete.
2021-05-17 00:49:45,521 - INFO: Started server process [13372]
2021-05-17 00:49:45,522 - INFO: Waiting for application startup.
2021-05-17 00:49:45,522 - INFO: Application startup complete.
2021-05-17 00:49:46,951 - INFO: Started server process [14104]
2021-05-17 00:49:46,952 - INFO: Waiting for application startup.
2021-05-17 00:49:46,952 - INFO: Application startup complete.
2021-05-17 00:49:51,132 - INFO: Started server process [9936]
2021-05-17 00:49:51,132 - INFO: Waiting for application startup.
2021-05-17 00:49:51,133 - INFO: Application startup complete.
2021-05-17 00:49:55,210 - ERROR: Exception in ASGI application
Traceback (most recent call last):
  File "c:\users\lucas\appdata\local\pypoetry\cache\virtualenvs\app-r1mvpay6-py3.8\lib\site-packages\uvicorn\protocols\http\h11_impl.py", line 396, in run_asgi
    result = await app(self.scope, self.receive, self.send)
  File "c:\users\lucas\appdata\local\pypoetry\cache\virtualenvs\app-r1mvpay6-py3.8\lib\site-packages\uvicorn\middleware\proxy_headers.py", line 45, in __call__
    return await self.app(scope, receive, send)
  File "c:\users\lucas\appdata\local\pypoetry\cache\virtualenvs\app-r1mvpay6-py3.8\lib\site-packages\fastapi\applications.py", line 199, in __call__
    await super().__call__(scope, receive, send)
  File "c:\users\lucas\appdata\local\pypoetry\cache\virtualenvs\app-r1mvpay6-py3.8\lib\site-packages\starlette\applications.py", line 112, in __call__
    await self.middleware_stack(scope, receive, send)
  File "c:\users\lucas\appdata\local\pypoetry\cache\virtualenvs\app-r1mvpay6-py3.8\lib\site-packages\starlette\middleware\errors.py", line 181, in __call__
    raise exc from None
  File "c:\users\lucas\appdata\local\pypoetry\cache\virtualenvs\app-r1mvpay6-py3.8\lib\site-packages\starlette\middleware\errors.py", line 159, in __call__
    await self.app(scope, receive, _send)
  File "c:\users\lucas\appdata\local\pypoetry\cache\virtualenvs\app-r1mvpay6-py3.8\lib\site-packages\starlette\exceptions.py", line 82, in __call__
    raise exc from None
  File "c:\users\lucas\appdata\local\pypoetry\cache\virtualenvs\app-r1mvpay6-py3.8\lib\site-packages\starlette\exceptions.py", line 71, in __call__
    await self.app(scope, receive, sender)
  File "c:\users\lucas\appdata\local\pypoetry\cache\virtualenvs\app-r1mvpay6-py3.8\lib\site-packages\starlette\routing.py", line 580, in __call__
    await route.handle(scope, receive, send)
  File "c:\users\lucas\appdata\local\pypoetry\cache\virtualenvs\app-r1mvpay6-py3.8\lib\site-packages\starlette\routing.py", line 241, in handle
    await self.app(scope, receive, send)
  File "c:\users\lucas\appdata\local\pypoetry\cache\virtualenvs\app-r1mvpay6-py3.8\lib\site-packages\starlette\routing.py", line 52, in app
    response = await func(request)
  File "c:\users\lucas\appdata\local\pypoetry\cache\virtualenvs\app-r1mvpay6-py3.8\lib\site-packages\fastapi\routing.py", line 201, in app
    raw_response = await run_endpoint_function(
  File "c:\users\lucas\appdata\local\pypoetry\cache\virtualenvs\app-r1mvpay6-py3.8\lib\site-packages\fastapi\routing.py", line 148, in run_endpoint_function
    return await dependant.call(**values)
  File ".\app\main.py", line 147, in update_cat
    cats.update(update_cat)
AttributeError: 'list' object has no attribute 'update'
2021-05-17 00:51:12,519 - INFO: Started server process [16860]
2021-05-17 00:51:12,519 - INFO: Waiting for application startup.
2021-05-17 00:51:12,520 - INFO: Application startup complete.
2021-05-17 00:51:15,305 - ERROR: Exception in ASGI application
Traceback (most recent call last):
  File "c:\users\lucas\appdata\local\pypoetry\cache\virtualenvs\app-r1mvpay6-py3.8\lib\site-packages\uvicorn\protocols\http\h11_impl.py", line 396, in run_asgi
    result = await app(self.scope, self.receive, self.send)
  File "c:\users\lucas\appdata\local\pypoetry\cache\virtualenvs\app-r1mvpay6-py3.8\lib\site-packages\uvicorn\middleware\proxy_headers.py", line 45, in __call__
    return await self.app(scope, receive, send)
  File "c:\users\lucas\appdata\local\pypoetry\cache\virtualenvs\app-r1mvpay6-py3.8\lib\site-packages\fastapi\applications.py", line 199, in __call__
    await super().__call__(scope, receive, send)
  File "c:\users\lucas\appdata\local\pypoetry\cache\virtualenvs\app-r1mvpay6-py3.8\lib\site-packages\starlette\applications.py", line 112, in __call__
    await self.middleware_stack(scope, receive, send)
  File "c:\users\lucas\appdata\local\pypoetry\cache\virtualenvs\app-r1mvpay6-py3.8\lib\site-packages\starlette\middleware\errors.py", line 181, in __call__
    raise exc from None
  File "c:\users\lucas\appdata\local\pypoetry\cache\virtualenvs\app-r1mvpay6-py3.8\lib\site-packages\starlette\middleware\errors.py", line 159, in __call__
    await self.app(scope, receive, _send)
  File "c:\users\lucas\appdata\local\pypoetry\cache\virtualenvs\app-r1mvpay6-py3.8\lib\site-packages\starlette\exceptions.py", line 82, in __call__
    raise exc from None
  File "c:\users\lucas\appdata\local\pypoetry\cache\virtualenvs\app-r1mvpay6-py3.8\lib\site-packages\starlette\exceptions.py", line 71, in __call__
    await self.app(scope, receive, sender)
  File "c:\users\lucas\appdata\local\pypoetry\cache\virtualenvs\app-r1mvpay6-py3.8\lib\site-packages\starlette\routing.py", line 580, in __call__
    await route.handle(scope, receive, send)
  File "c:\users\lucas\appdata\local\pypoetry\cache\virtualenvs\app-r1mvpay6-py3.8\lib\site-packages\starlette\routing.py", line 241, in handle
    await self.app(scope, receive, send)
  File "c:\users\lucas\appdata\local\pypoetry\cache\virtualenvs\app-r1mvpay6-py3.8\lib\site-packages\starlette\routing.py", line 52, in app
    response = await func(request)
  File "c:\users\lucas\appdata\local\pypoetry\cache\virtualenvs\app-r1mvpay6-py3.8\lib\site-packages\fastapi\routing.py", line 201, in app
    raw_response = await run_endpoint_function(
  File "c:\users\lucas\appdata\local\pypoetry\cache\virtualenvs\app-r1mvpay6-py3.8\lib\site-packages\fastapi\routing.py", line 148, in run_endpoint_function
    return await dependant.call(**values)
  File ".\app\main.py", line 147, in update_cat
    cats.update(update_cat)
AttributeError: 'list' object has no attribute 'update'
2021-05-17 00:51:59,554 - INFO: Started server process [18176]
2021-05-17 00:51:59,555 - INFO: Waiting for application startup.
2021-05-17 00:51:59,555 - INFO: Application startup complete.
2021-05-17 00:52:00,776 - ERROR: Exception in ASGI application
Traceback (most recent call last):
  File "c:\users\lucas\appdata\local\pypoetry\cache\virtualenvs\app-r1mvpay6-py3.8\lib\site-packages\uvicorn\protocols\http\h11_impl.py", line 396, in run_asgi
    result = await app(self.scope, self.receive, self.send)
  File "c:\users\lucas\appdata\local\pypoetry\cache\virtualenvs\app-r1mvpay6-py3.8\lib\site-packages\uvicorn\middleware\proxy_headers.py", line 45, in __call__
    return await self.app(scope, receive, send)
  File "c:\users\lucas\appdata\local\pypoetry\cache\virtualenvs\app-r1mvpay6-py3.8\lib\site-packages\fastapi\applications.py", line 199, in __call__
    await super().__call__(scope, receive, send)
  File "c:\users\lucas\appdata\local\pypoetry\cache\virtualenvs\app-r1mvpay6-py3.8\lib\site-packages\starlette\applications.py", line 112, in __call__
    await self.middleware_stack(scope, receive, send)
  File "c:\users\lucas\appdata\local\pypoetry\cache\virtualenvs\app-r1mvpay6-py3.8\lib\site-packages\starlette\middleware\errors.py", line 181, in __call__
    raise exc from None
  File "c:\users\lucas\appdata\local\pypoetry\cache\virtualenvs\app-r1mvpay6-py3.8\lib\site-packages\starlette\middleware\errors.py", line 159, in __call__
    await self.app(scope, receive, _send)
  File "c:\users\lucas\appdata\local\pypoetry\cache\virtualenvs\app-r1mvpay6-py3.8\lib\site-packages\starlette\exceptions.py", line 82, in __call__
    raise exc from None
  File "c:\users\lucas\appdata\local\pypoetry\cache\virtualenvs\app-r1mvpay6-py3.8\lib\site-packages\starlette\exceptions.py", line 71, in __call__
    await self.app(scope, receive, sender)
  File "c:\users\lucas\appdata\local\pypoetry\cache\virtualenvs\app-r1mvpay6-py3.8\lib\site-packages\starlette\routing.py", line 580, in __call__
    await route.handle(scope, receive, send)
  File "c:\users\lucas\appdata\local\pypoetry\cache\virtualenvs\app-r1mvpay6-py3.8\lib\site-packages\starlette\routing.py", line 241, in handle
    await self.app(scope, receive, send)
  File "c:\users\lucas\appdata\local\pypoetry\cache\virtualenvs\app-r1mvpay6-py3.8\lib\site-packages\starlette\routing.py", line 52, in app
    response = await func(request)
  File "c:\users\lucas\appdata\local\pypoetry\cache\virtualenvs\app-r1mvpay6-py3.8\lib\site-packages\fastapi\routing.py", line 201, in app
    raw_response = await run_endpoint_function(
  File "c:\users\lucas\appdata\local\pypoetry\cache\virtualenvs\app-r1mvpay6-py3.8\lib\site-packages\fastapi\routing.py", line 148, in run_endpoint_function
    return await dependant.call(**values)
  File ".\app\main.py", line 123, in update_cat
    update_cat = cat.dict()
AttributeError: 'dict' object has no attribute 'dict'
2021-05-17 00:53:54,737 - INFO: Started server process [18220]
2021-05-17 00:53:54,737 - INFO: Waiting for application startup.
2021-05-17 00:53:54,737 - INFO: Application startup complete.
2021-05-17 00:53:54,960 - ERROR: Exception in ASGI application
Traceback (most recent call last):
  File "c:\users\lucas\appdata\local\pypoetry\cache\virtualenvs\app-r1mvpay6-py3.8\lib\site-packages\uvicorn\protocols\http\h11_impl.py", line 396, in run_asgi
    result = await app(self.scope, self.receive, self.send)
  File "c:\users\lucas\appdata\local\pypoetry\cache\virtualenvs\app-r1mvpay6-py3.8\lib\site-packages\uvicorn\middleware\proxy_headers.py", line 45, in __call__
    return await self.app(scope, receive, send)
  File "c:\users\lucas\appdata\local\pypoetry\cache\virtualenvs\app-r1mvpay6-py3.8\lib\site-packages\fastapi\applications.py", line 199, in __call__
    await super().__call__(scope, receive, send)
  File "c:\users\lucas\appdata\local\pypoetry\cache\virtualenvs\app-r1mvpay6-py3.8\lib\site-packages\starlette\applications.py", line 112, in __call__
    await self.middleware_stack(scope, receive, send)
  File "c:\users\lucas\appdata\local\pypoetry\cache\virtualenvs\app-r1mvpay6-py3.8\lib\site-packages\starlette\middleware\errors.py", line 181, in __call__
    raise exc from None
  File "c:\users\lucas\appdata\local\pypoetry\cache\virtualenvs\app-r1mvpay6-py3.8\lib\site-packages\starlette\middleware\errors.py", line 159, in __call__
    await self.app(scope, receive, _send)
  File "c:\users\lucas\appdata\local\pypoetry\cache\virtualenvs\app-r1mvpay6-py3.8\lib\site-packages\starlette\exceptions.py", line 82, in __call__
    raise exc from None
  File "c:\users\lucas\appdata\local\pypoetry\cache\virtualenvs\app-r1mvpay6-py3.8\lib\site-packages\starlette\exceptions.py", line 71, in __call__
    await self.app(scope, receive, sender)
  File "c:\users\lucas\appdata\local\pypoetry\cache\virtualenvs\app-r1mvpay6-py3.8\lib\site-packages\starlette\routing.py", line 580, in __call__
    await route.handle(scope, receive, send)
  File "c:\users\lucas\appdata\local\pypoetry\cache\virtualenvs\app-r1mvpay6-py3.8\lib\site-packages\starlette\routing.py", line 241, in handle
    await self.app(scope, receive, send)
  File "c:\users\lucas\appdata\local\pypoetry\cache\virtualenvs\app-r1mvpay6-py3.8\lib\site-packages\starlette\routing.py", line 52, in app
    response = await func(request)
  File "c:\users\lucas\appdata\local\pypoetry\cache\virtualenvs\app-r1mvpay6-py3.8\lib\site-packages\fastapi\routing.py", line 201, in app
    raw_response = await run_endpoint_function(
  File "c:\users\lucas\appdata\local\pypoetry\cache\virtualenvs\app-r1mvpay6-py3.8\lib\site-packages\fastapi\routing.py", line 148, in run_endpoint_function
    return await dependant.call(**values)
  File ".\app\main.py", line 123, in update_cat
    cat = cat.dict()
AttributeError: 'dict' object has no attribute 'dict'
2021-05-17 00:54:03,806 - INFO: Started server process [16928]
2021-05-17 00:54:03,806 - INFO: Waiting for application startup.
2021-05-17 00:54:03,807 - INFO: Application startup complete.
2021-05-17 00:55:15,341 - INFO: Started server process [17464]
2021-05-17 00:55:15,341 - INFO: Waiting for application startup.
2021-05-17 00:55:15,341 - INFO: Application startup complete.
2021-05-17 00:55:16,405 - ERROR: Exception in ASGI application
Traceback (most recent call last):
  File "c:\users\lucas\appdata\local\pypoetry\cache\virtualenvs\app-r1mvpay6-py3.8\lib\site-packages\uvicorn\protocols\http\h11_impl.py", line 396, in run_asgi
    result = await app(self.scope, self.receive, self.send)
  File "c:\users\lucas\appdata\local\pypoetry\cache\virtualenvs\app-r1mvpay6-py3.8\lib\site-packages\uvicorn\middleware\proxy_headers.py", line 45, in __call__
    return await self.app(scope, receive, send)
  File "c:\users\lucas\appdata\local\pypoetry\cache\virtualenvs\app-r1mvpay6-py3.8\lib\site-packages\fastapi\applications.py", line 199, in __call__
    await super().__call__(scope, receive, send)
  File "c:\users\lucas\appdata\local\pypoetry\cache\virtualenvs\app-r1mvpay6-py3.8\lib\site-packages\starlette\applications.py", line 112, in __call__
    await self.middleware_stack(scope, receive, send)
  File "c:\users\lucas\appdata\local\pypoetry\cache\virtualenvs\app-r1mvpay6-py3.8\lib\site-packages\starlette\middleware\errors.py", line 181, in __call__
    raise exc from None
  File "c:\users\lucas\appdata\local\pypoetry\cache\virtualenvs\app-r1mvpay6-py3.8\lib\site-packages\starlette\middleware\errors.py", line 159, in __call__
    await self.app(scope, receive, _send)
  File "c:\users\lucas\appdata\local\pypoetry\cache\virtualenvs\app-r1mvpay6-py3.8\lib\site-packages\starlette\exceptions.py", line 82, in __call__
    raise exc from None
  File "c:\users\lucas\appdata\local\pypoetry\cache\virtualenvs\app-r1mvpay6-py3.8\lib\site-packages\starlette\exceptions.py", line 71, in __call__
    await self.app(scope, receive, sender)
  File "c:\users\lucas\appdata\local\pypoetry\cache\virtualenvs\app-r1mvpay6-py3.8\lib\site-packages\starlette\routing.py", line 580, in __call__
    await route.handle(scope, receive, send)
  File "c:\users\lucas\appdata\local\pypoetry\cache\virtualenvs\app-r1mvpay6-py3.8\lib\site-packages\starlette\routing.py", line 241, in handle
    await self.app(scope, receive, send)
  File "c:\users\lucas\appdata\local\pypoetry\cache\virtualenvs\app-r1mvpay6-py3.8\lib\site-packages\starlette\routing.py", line 52, in app
    response = await func(request)
  File "c:\users\lucas\appdata\local\pypoetry\cache\virtualenvs\app-r1mvpay6-py3.8\lib\site-packages\fastapi\routing.py", line 201, in app
    raw_response = await run_endpoint_function(
  File "c:\users\lucas\appdata\local\pypoetry\cache\virtualenvs\app-r1mvpay6-py3.8\lib\site-packages\fastapi\routing.py", line 148, in run_endpoint_function
    return await dependant.call(**values)
  File ".\app\main.py", line 122, in update_cat
    return cats.update(cat)
AttributeError: 'list' object has no attribute 'update'
2021-05-17 00:57:01,184 - INFO: Started server process [18292]
2021-05-17 00:57:01,184 - INFO: Waiting for application startup.
2021-05-17 00:57:01,184 - INFO: Application startup complete.
2021-05-17 00:57:02,021 - ERROR: Exception in ASGI application
Traceback (most recent call last):
  File "c:\users\lucas\appdata\local\pypoetry\cache\virtualenvs\app-r1mvpay6-py3.8\lib\site-packages\uvicorn\protocols\http\h11_impl.py", line 396, in run_asgi
    result = await app(self.scope, self.receive, self.send)
  File "c:\users\lucas\appdata\local\pypoetry\cache\virtualenvs\app-r1mvpay6-py3.8\lib\site-packages\uvicorn\middleware\proxy_headers.py", line 45, in __call__
    return await self.app(scope, receive, send)
  File "c:\users\lucas\appdata\local\pypoetry\cache\virtualenvs\app-r1mvpay6-py3.8\lib\site-packages\fastapi\applications.py", line 199, in __call__
    await super().__call__(scope, receive, send)
  File "c:\users\lucas\appdata\local\pypoetry\cache\virtualenvs\app-r1mvpay6-py3.8\lib\site-packages\starlette\applications.py", line 112, in __call__
    await self.middleware_stack(scope, receive, send)
  File "c:\users\lucas\appdata\local\pypoetry\cache\virtualenvs\app-r1mvpay6-py3.8\lib\site-packages\starlette\middleware\errors.py", line 181, in __call__
    raise exc from None
  File "c:\users\lucas\appdata\local\pypoetry\cache\virtualenvs\app-r1mvpay6-py3.8\lib\site-packages\starlette\middleware\errors.py", line 159, in __call__
    await self.app(scope, receive, _send)
  File "c:\users\lucas\appdata\local\pypoetry\cache\virtualenvs\app-r1mvpay6-py3.8\lib\site-packages\starlette\exceptions.py", line 82, in __call__
    raise exc from None
  File "c:\users\lucas\appdata\local\pypoetry\cache\virtualenvs\app-r1mvpay6-py3.8\lib\site-packages\starlette\exceptions.py", line 71, in __call__
    await self.app(scope, receive, sender)
  File "c:\users\lucas\appdata\local\pypoetry\cache\virtualenvs\app-r1mvpay6-py3.8\lib\site-packages\starlette\routing.py", line 580, in __call__
    await route.handle(scope, receive, send)
  File "c:\users\lucas\appdata\local\pypoetry\cache\virtualenvs\app-r1mvpay6-py3.8\lib\site-packages\starlette\routing.py", line 241, in handle
    await self.app(scope, receive, send)
  File "c:\users\lucas\appdata\local\pypoetry\cache\virtualenvs\app-r1mvpay6-py3.8\lib\site-packages\starlette\routing.py", line 52, in app
    response = await func(request)
  File "c:\users\lucas\appdata\local\pypoetry\cache\virtualenvs\app-r1mvpay6-py3.8\lib\site-packages\fastapi\routing.py", line 201, in app
    raw_response = await run_endpoint_function(
  File "c:\users\lucas\appdata\local\pypoetry\cache\virtualenvs\app-r1mvpay6-py3.8\lib\site-packages\fastapi\routing.py", line 148, in run_endpoint_function
    return await dependant.call(**values)
  File ".\app\main.py", line 147, in update_cat
    cats.update(update_cat)
AttributeError: 'list' object has no attribute 'update'
2021-05-17 00:57:37,007 - INFO: Started server process [9004]
2021-05-17 00:57:37,007 - INFO: Waiting for application startup.
2021-05-17 00:57:37,007 - INFO: Application startup complete.
2021-05-17 00:57:42,021 - ERROR: Exception in ASGI application
Traceback (most recent call last):
  File "c:\users\lucas\appdata\local\pypoetry\cache\virtualenvs\app-r1mvpay6-py3.8\lib\site-packages\uvicorn\protocols\http\h11_impl.py", line 396, in run_asgi
    result = await app(self.scope, self.receive, self.send)
  File "c:\users\lucas\appdata\local\pypoetry\cache\virtualenvs\app-r1mvpay6-py3.8\lib\site-packages\uvicorn\middleware\proxy_headers.py", line 45, in __call__
    return await self.app(scope, receive, send)
  File "c:\users\lucas\appdata\local\pypoetry\cache\virtualenvs\app-r1mvpay6-py3.8\lib\site-packages\fastapi\applications.py", line 199, in __call__
    await super().__call__(scope, receive, send)
  File "c:\users\lucas\appdata\local\pypoetry\cache\virtualenvs\app-r1mvpay6-py3.8\lib\site-packages\starlette\applications.py", line 112, in __call__
    await self.middleware_stack(scope, receive, send)
  File "c:\users\lucas\appdata\local\pypoetry\cache\virtualenvs\app-r1mvpay6-py3.8\lib\site-packages\starlette\middleware\errors.py", line 181, in __call__
    raise exc from None
  File "c:\users\lucas\appdata\local\pypoetry\cache\virtualenvs\app-r1mvpay6-py3.8\lib\site-packages\starlette\middleware\errors.py", line 159, in __call__
    await self.app(scope, receive, _send)
  File "c:\users\lucas\appdata\local\pypoetry\cache\virtualenvs\app-r1mvpay6-py3.8\lib\site-packages\starlette\exceptions.py", line 82, in __call__
    raise exc from None
  File "c:\users\lucas\appdata\local\pypoetry\cache\virtualenvs\app-r1mvpay6-py3.8\lib\site-packages\starlette\exceptions.py", line 71, in __call__
    await self.app(scope, receive, sender)
  File "c:\users\lucas\appdata\local\pypoetry\cache\virtualenvs\app-r1mvpay6-py3.8\lib\site-packages\starlette\routing.py", line 580, in __call__
    await route.handle(scope, receive, send)
  File "c:\users\lucas\appdata\local\pypoetry\cache\virtualenvs\app-r1mvpay6-py3.8\lib\site-packages\starlette\routing.py", line 241, in handle
    await self.app(scope, receive, send)
  File "c:\users\lucas\appdata\local\pypoetry\cache\virtualenvs\app-r1mvpay6-py3.8\lib\site-packages\starlette\routing.py", line 52, in app
    response = await func(request)
  File "c:\users\lucas\appdata\local\pypoetry\cache\virtualenvs\app-r1mvpay6-py3.8\lib\site-packages\fastapi\routing.py", line 201, in app
    raw_response = await run_endpoint_function(
  File "c:\users\lucas\appdata\local\pypoetry\cache\virtualenvs\app-r1mvpay6-py3.8\lib\site-packages\fastapi\routing.py", line 148, in run_endpoint_function
    return await dependant.call(**values)
  File ".\app\main.py", line 147, in update_cat
    cats.update(update_cat)
AttributeError: 'list' object has no attribute 'update'
2021-05-17 00:57:52,000 - INFO: Started server process [16680]
2021-05-17 00:57:52,001 - INFO: Waiting for application startup.
2021-05-17 00:57:52,001 - INFO: Application startup complete.
2021-05-17 00:58:36,710 - INFO: Started server process [17616]
2021-05-17 00:58:36,711 - INFO: Waiting for application startup.
2021-05-17 00:58:36,711 - INFO: Application startup complete.
2021-05-17 00:58:37,710 - ERROR: Exception in ASGI application
Traceback (most recent call last):
  File "c:\users\lucas\appdata\local\pypoetry\cache\virtualenvs\app-r1mvpay6-py3.8\lib\site-packages\uvicorn\protocols\http\h11_impl.py", line 396, in run_asgi
    result = await app(self.scope, self.receive, self.send)
  File "c:\users\lucas\appdata\local\pypoetry\cache\virtualenvs\app-r1mvpay6-py3.8\lib\site-packages\uvicorn\middleware\proxy_headers.py", line 45, in __call__
    return await self.app(scope, receive, send)
  File "c:\users\lucas\appdata\local\pypoetry\cache\virtualenvs\app-r1mvpay6-py3.8\lib\site-packages\fastapi\applications.py", line 199, in __call__
    await super().__call__(scope, receive, send)
  File "c:\users\lucas\appdata\local\pypoetry\cache\virtualenvs\app-r1mvpay6-py3.8\lib\site-packages\starlette\applications.py", line 112, in __call__
    await self.middleware_stack(scope, receive, send)
  File "c:\users\lucas\appdata\local\pypoetry\cache\virtualenvs\app-r1mvpay6-py3.8\lib\site-packages\starlette\middleware\errors.py", line 181, in __call__
    raise exc from None
  File "c:\users\lucas\appdata\local\pypoetry\cache\virtualenvs\app-r1mvpay6-py3.8\lib\site-packages\starlette\middleware\errors.py", line 159, in __call__
    await self.app(scope, receive, _send)
  File "c:\users\lucas\appdata\local\pypoetry\cache\virtualenvs\app-r1mvpay6-py3.8\lib\site-packages\starlette\exceptions.py", line 82, in __call__
    raise exc from None
  File "c:\users\lucas\appdata\local\pypoetry\cache\virtualenvs\app-r1mvpay6-py3.8\lib\site-packages\starlette\exceptions.py", line 71, in __call__
    await self.app(scope, receive, sender)
  File "c:\users\lucas\appdata\local\pypoetry\cache\virtualenvs\app-r1mvpay6-py3.8\lib\site-packages\starlette\routing.py", line 580, in __call__
    await route.handle(scope, receive, send)
  File "c:\users\lucas\appdata\local\pypoetry\cache\virtualenvs\app-r1mvpay6-py3.8\lib\site-packages\starlette\routing.py", line 241, in handle
    await self.app(scope, receive, send)
  File "c:\users\lucas\appdata\local\pypoetry\cache\virtualenvs\app-r1mvpay6-py3.8\lib\site-packages\starlette\routing.py", line 52, in app
    response = await func(request)
  File "c:\users\lucas\appdata\local\pypoetry\cache\virtualenvs\app-r1mvpay6-py3.8\lib\site-packages\fastapi\routing.py", line 201, in app
    raw_response = await run_endpoint_function(
  File "c:\users\lucas\appdata\local\pypoetry\cache\virtualenvs\app-r1mvpay6-py3.8\lib\site-packages\fastapi\routing.py", line 148, in run_endpoint_function
    return await dependant.call(**values)
  File ".\app\main.py", line 147, in update_cat
    cats.update(update_cat)
AttributeError: 'list' object has no attribute 'update'
2021-05-17 00:58:45,023 - INFO: Started server process [18028]
2021-05-17 00:58:45,023 - INFO: Waiting for application startup.
2021-05-17 00:58:45,023 - INFO: Application startup complete.
2021-05-17 01:00:08,170 - INFO: Started server process [17964]
2021-05-17 01:00:08,170 - INFO: Waiting for application startup.
2021-05-17 01:00:08,171 - INFO: Application startup complete.
2021-05-17 01:00:12,480 - ERROR: Exception in ASGI application
Traceback (most recent call last):
  File "c:\users\lucas\appdata\local\pypoetry\cache\virtualenvs\app-r1mvpay6-py3.8\lib\site-packages\uvicorn\protocols\http\h11_impl.py", line 396, in run_asgi
    result = await app(self.scope, self.receive, self.send)
  File "c:\users\lucas\appdata\local\pypoetry\cache\virtualenvs\app-r1mvpay6-py3.8\lib\site-packages\uvicorn\middleware\proxy_headers.py", line 45, in __call__
    return await self.app(scope, receive, send)
  File "c:\users\lucas\appdata\local\pypoetry\cache\virtualenvs\app-r1mvpay6-py3.8\lib\site-packages\fastapi\applications.py", line 199, in __call__
    await super().__call__(scope, receive, send)
  File "c:\users\lucas\appdata\local\pypoetry\cache\virtualenvs\app-r1mvpay6-py3.8\lib\site-packages\starlette\applications.py", line 112, in __call__
    await self.middleware_stack(scope, receive, send)
  File "c:\users\lucas\appdata\local\pypoetry\cache\virtualenvs\app-r1mvpay6-py3.8\lib\site-packages\starlette\middleware\errors.py", line 181, in __call__
    raise exc from None
  File "c:\users\lucas\appdata\local\pypoetry\cache\virtualenvs\app-r1mvpay6-py3.8\lib\site-packages\starlette\middleware\errors.py", line 159, in __call__
    await self.app(scope, receive, _send)
  File "c:\users\lucas\appdata\local\pypoetry\cache\virtualenvs\app-r1mvpay6-py3.8\lib\site-packages\starlette\exceptions.py", line 82, in __call__
    raise exc from None
  File "c:\users\lucas\appdata\local\pypoetry\cache\virtualenvs\app-r1mvpay6-py3.8\lib\site-packages\starlette\exceptions.py", line 71, in __call__
    await self.app(scope, receive, sender)
  File "c:\users\lucas\appdata\local\pypoetry\cache\virtualenvs\app-r1mvpay6-py3.8\lib\site-packages\starlette\routing.py", line 580, in __call__
    await route.handle(scope, receive, send)
  File "c:\users\lucas\appdata\local\pypoetry\cache\virtualenvs\app-r1mvpay6-py3.8\lib\site-packages\starlette\routing.py", line 241, in handle
    await self.app(scope, receive, send)
  File "c:\users\lucas\appdata\local\pypoetry\cache\virtualenvs\app-r1mvpay6-py3.8\lib\site-packages\starlette\routing.py", line 52, in app
    response = await func(request)
  File "c:\users\lucas\appdata\local\pypoetry\cache\virtualenvs\app-r1mvpay6-py3.8\lib\site-packages\fastapi\routing.py", line 201, in app
    raw_response = await run_endpoint_function(
  File "c:\users\lucas\appdata\local\pypoetry\cache\virtualenvs\app-r1mvpay6-py3.8\lib\site-packages\fastapi\routing.py", line 148, in run_endpoint_function
    return await dependant.call(**values)
  File ".\app\main.py", line 147, in update_cat
    cats.update(update_cat)
AttributeError: 'list' object has no attribute 'update'
2021-05-17 01:01:54,135 - INFO: Started server process [17452]
2021-05-17 01:01:54,135 - INFO: Waiting for application startup.
2021-05-17 01:01:54,136 - INFO: Application startup complete.
2021-05-17 01:01:55,559 - ERROR: Exception in ASGI application
Traceback (most recent call last):
  File "c:\users\lucas\appdata\local\pypoetry\cache\virtualenvs\app-r1mvpay6-py3.8\lib\site-packages\uvicorn\protocols\http\h11_impl.py", line 396, in run_asgi
    result = await app(self.scope, self.receive, self.send)
  File "c:\users\lucas\appdata\local\pypoetry\cache\virtualenvs\app-r1mvpay6-py3.8\lib\site-packages\uvicorn\middleware\proxy_headers.py", line 45, in __call__
    return await self.app(scope, receive, send)
  File "c:\users\lucas\appdata\local\pypoetry\cache\virtualenvs\app-r1mvpay6-py3.8\lib\site-packages\fastapi\applications.py", line 199, in __call__
    await super().__call__(scope, receive, send)
  File "c:\users\lucas\appdata\local\pypoetry\cache\virtualenvs\app-r1mvpay6-py3.8\lib\site-packages\starlette\applications.py", line 112, in __call__
    await self.middleware_stack(scope, receive, send)
  File "c:\users\lucas\appdata\local\pypoetry\cache\virtualenvs\app-r1mvpay6-py3.8\lib\site-packages\starlette\middleware\errors.py", line 181, in __call__
    raise exc from None
  File "c:\users\lucas\appdata\local\pypoetry\cache\virtualenvs\app-r1mvpay6-py3.8\lib\site-packages\starlette\middleware\errors.py", line 159, in __call__
    await self.app(scope, receive, _send)
  File "c:\users\lucas\appdata\local\pypoetry\cache\virtualenvs\app-r1mvpay6-py3.8\lib\site-packages\starlette\exceptions.py", line 82, in __call__
    raise exc from None
  File "c:\users\lucas\appdata\local\pypoetry\cache\virtualenvs\app-r1mvpay6-py3.8\lib\site-packages\starlette\exceptions.py", line 71, in __call__
    await self.app(scope, receive, sender)
  File "c:\users\lucas\appdata\local\pypoetry\cache\virtualenvs\app-r1mvpay6-py3.8\lib\site-packages\starlette\routing.py", line 580, in __call__
    await route.handle(scope, receive, send)
  File "c:\users\lucas\appdata\local\pypoetry\cache\virtualenvs\app-r1mvpay6-py3.8\lib\site-packages\starlette\routing.py", line 241, in handle
    await self.app(scope, receive, send)
  File "c:\users\lucas\appdata\local\pypoetry\cache\virtualenvs\app-r1mvpay6-py3.8\lib\site-packages\starlette\routing.py", line 52, in app
    response = await func(request)
  File "c:\users\lucas\appdata\local\pypoetry\cache\virtualenvs\app-r1mvpay6-py3.8\lib\site-packages\fastapi\routing.py", line 201, in app
    raw_response = await run_endpoint_function(
  File "c:\users\lucas\appdata\local\pypoetry\cache\virtualenvs\app-r1mvpay6-py3.8\lib\site-packages\fastapi\routing.py", line 148, in run_endpoint_function
    return await dependant.call(**values)
  File ".\app\main.py", line 148, in update_cat
    cats.update(update_cat)
AttributeError: 'list' object has no attribute 'update'
2021-05-17 01:02:57,042 - INFO: Started server process [14896]
2021-05-17 01:02:57,043 - INFO: Waiting for application startup.
2021-05-17 01:02:57,043 - INFO: Application startup complete.
2021-05-17 01:02:57,983 - ERROR: Exception in ASGI application
Traceback (most recent call last):
  File "c:\users\lucas\appdata\local\pypoetry\cache\virtualenvs\app-r1mvpay6-py3.8\lib\site-packages\uvicorn\protocols\http\h11_impl.py", line 396, in run_asgi
    result = await app(self.scope, self.receive, self.send)
  File "c:\users\lucas\appdata\local\pypoetry\cache\virtualenvs\app-r1mvpay6-py3.8\lib\site-packages\uvicorn\middleware\proxy_headers.py", line 45, in __call__
    return await self.app(scope, receive, send)
  File "c:\users\lucas\appdata\local\pypoetry\cache\virtualenvs\app-r1mvpay6-py3.8\lib\site-packages\fastapi\applications.py", line 199, in __call__
    await super().__call__(scope, receive, send)
  File "c:\users\lucas\appdata\local\pypoetry\cache\virtualenvs\app-r1mvpay6-py3.8\lib\site-packages\starlette\applications.py", line 112, in __call__
    await self.middleware_stack(scope, receive, send)
  File "c:\users\lucas\appdata\local\pypoetry\cache\virtualenvs\app-r1mvpay6-py3.8\lib\site-packages\starlette\middleware\errors.py", line 181, in __call__
    raise exc from None
  File "c:\users\lucas\appdata\local\pypoetry\cache\virtualenvs\app-r1mvpay6-py3.8\lib\site-packages\starlette\middleware\errors.py", line 159, in __call__
    await self.app(scope, receive, _send)
  File "c:\users\lucas\appdata\local\pypoetry\cache\virtualenvs\app-r1mvpay6-py3.8\lib\site-packages\starlette\exceptions.py", line 82, in __call__
    raise exc from None
  File "c:\users\lucas\appdata\local\pypoetry\cache\virtualenvs\app-r1mvpay6-py3.8\lib\site-packages\starlette\exceptions.py", line 71, in __call__
    await self.app(scope, receive, sender)
  File "c:\users\lucas\appdata\local\pypoetry\cache\virtualenvs\app-r1mvpay6-py3.8\lib\site-packages\starlette\routing.py", line 580, in __call__
    await route.handle(scope, receive, send)
  File "c:\users\lucas\appdata\local\pypoetry\cache\virtualenvs\app-r1mvpay6-py3.8\lib\site-packages\starlette\routing.py", line 241, in handle
    await self.app(scope, receive, send)
  File "c:\users\lucas\appdata\local\pypoetry\cache\virtualenvs\app-r1mvpay6-py3.8\lib\site-packages\starlette\routing.py", line 52, in app
    response = await func(request)
  File "c:\users\lucas\appdata\local\pypoetry\cache\virtualenvs\app-r1mvpay6-py3.8\lib\site-packages\fastapi\routing.py", line 209, in app
    response_data = await serialize_response(
  File "c:\users\lucas\appdata\local\pypoetry\cache\virtualenvs\app-r1mvpay6-py3.8\lib\site-packages\fastapi\routing.py", line 126, in serialize_response
    raise ValidationError(errors, field.type_)
pydantic.error_wrappers.ValidationError: 1 validation error for Cat
response
  value is not a valid list (type=type_error.list)
2021-05-17 01:03:19,983 - INFO: Started server process [17968]
2021-05-17 01:03:19,984 - INFO: Waiting for application startup.
2021-05-17 01:03:19,984 - INFO: Application startup complete.
2021-05-17 01:03:23,226 - WARNING: Cat not found.
2021-05-17 01:03:53,203 - INFO: Started server process [18288]
2021-05-17 01:03:53,204 - INFO: Waiting for application startup.
2021-05-17 01:03:53,204 - INFO: Application startup complete.
2021-05-17 01:03:55,077 - WARNING: Cat not found.
2021-05-17 01:04:16,741 - INFO: Started server process [2932]
2021-05-17 01:04:16,742 - INFO: Waiting for application startup.
2021-05-17 01:04:16,742 - INFO: Application startup complete.
2021-05-17 01:04:19,174 - ERROR: Exception in ASGI application
Traceback (most recent call last):
  File "c:\users\lucas\appdata\local\pypoetry\cache\virtualenvs\app-r1mvpay6-py3.8\lib\site-packages\uvicorn\protocols\http\h11_impl.py", line 396, in run_asgi
    result = await app(self.scope, self.receive, self.send)
  File "c:\users\lucas\appdata\local\pypoetry\cache\virtualenvs\app-r1mvpay6-py3.8\lib\site-packages\uvicorn\middleware\proxy_headers.py", line 45, in __call__
    return await self.app(scope, receive, send)
  File "c:\users\lucas\appdata\local\pypoetry\cache\virtualenvs\app-r1mvpay6-py3.8\lib\site-packages\fastapi\applications.py", line 199, in __call__
    await super().__call__(scope, receive, send)
  File "c:\users\lucas\appdata\local\pypoetry\cache\virtualenvs\app-r1mvpay6-py3.8\lib\site-packages\starlette\applications.py", line 112, in __call__
    await self.middleware_stack(scope, receive, send)
  File "c:\users\lucas\appdata\local\pypoetry\cache\virtualenvs\app-r1mvpay6-py3.8\lib\site-packages\starlette\middleware\errors.py", line 181, in __call__
    raise exc from None
  File "c:\users\lucas\appdata\local\pypoetry\cache\virtualenvs\app-r1mvpay6-py3.8\lib\site-packages\starlette\middleware\errors.py", line 159, in __call__
    await self.app(scope, receive, _send)
  File "c:\users\lucas\appdata\local\pypoetry\cache\virtualenvs\app-r1mvpay6-py3.8\lib\site-packages\starlette\exceptions.py", line 82, in __call__
    raise exc from None
  File "c:\users\lucas\appdata\local\pypoetry\cache\virtualenvs\app-r1mvpay6-py3.8\lib\site-packages\starlette\exceptions.py", line 71, in __call__
    await self.app(scope, receive, sender)
  File "c:\users\lucas\appdata\local\pypoetry\cache\virtualenvs\app-r1mvpay6-py3.8\lib\site-packages\starlette\routing.py", line 580, in __call__
    await route.handle(scope, receive, send)
  File "c:\users\lucas\appdata\local\pypoetry\cache\virtualenvs\app-r1mvpay6-py3.8\lib\site-packages\starlette\routing.py", line 241, in handle
    await self.app(scope, receive, send)
  File "c:\users\lucas\appdata\local\pypoetry\cache\virtualenvs\app-r1mvpay6-py3.8\lib\site-packages\starlette\routing.py", line 52, in app
    response = await func(request)
  File "c:\users\lucas\appdata\local\pypoetry\cache\virtualenvs\app-r1mvpay6-py3.8\lib\site-packages\fastapi\routing.py", line 201, in app
    raw_response = await run_endpoint_function(
  File "c:\users\lucas\appdata\local\pypoetry\cache\virtualenvs\app-r1mvpay6-py3.8\lib\site-packages\fastapi\routing.py", line 148, in run_endpoint_function
    return await dependant.call(**values)
  File ".\app\main.py", line 124, in update_cat
    location_of_origin = location_of_origin.capitalize()
UnboundLocalError: local variable 'location_of_origin' referenced before assignment
2021-05-17 01:04:43,784 - INFO: Started server process [17220]
2021-05-17 01:04:43,785 - INFO: Waiting for application startup.
2021-05-17 01:04:43,785 - INFO: Application startup complete.
2021-05-17 01:04:47,182 - WARNING: Cat not found.
2021-05-17 01:05:51,636 - INFO: Started server process [16812]
2021-05-17 01:05:51,636 - INFO: Waiting for application startup.
2021-05-17 01:05:51,636 - INFO: Application startup complete.
2021-05-17 01:05:58,410 - ERROR: Exception in ASGI application
Traceback (most recent call last):
  File "c:\users\lucas\appdata\local\pypoetry\cache\virtualenvs\app-r1mvpay6-py3.8\lib\site-packages\uvicorn\protocols\http\h11_impl.py", line 396, in run_asgi
    result = await app(self.scope, self.receive, self.send)
  File "c:\users\lucas\appdata\local\pypoetry\cache\virtualenvs\app-r1mvpay6-py3.8\lib\site-packages\uvicorn\middleware\proxy_headers.py", line 45, in __call__
    return await self.app(scope, receive, send)
  File "c:\users\lucas\appdata\local\pypoetry\cache\virtualenvs\app-r1mvpay6-py3.8\lib\site-packages\fastapi\applications.py", line 199, in __call__
    await super().__call__(scope, receive, send)
  File "c:\users\lucas\appdata\local\pypoetry\cache\virtualenvs\app-r1mvpay6-py3.8\lib\site-packages\starlette\applications.py", line 112, in __call__
    await self.middleware_stack(scope, receive, send)
  File "c:\users\lucas\appdata\local\pypoetry\cache\virtualenvs\app-r1mvpay6-py3.8\lib\site-packages\starlette\middleware\errors.py", line 181, in __call__
    raise exc from None
  File "c:\users\lucas\appdata\local\pypoetry\cache\virtualenvs\app-r1mvpay6-py3.8\lib\site-packages\starlette\middleware\errors.py", line 159, in __call__
    await self.app(scope, receive, _send)
  File "c:\users\lucas\appdata\local\pypoetry\cache\virtualenvs\app-r1mvpay6-py3.8\lib\site-packages\starlette\exceptions.py", line 82, in __call__
    raise exc from None
  File "c:\users\lucas\appdata\local\pypoetry\cache\virtualenvs\app-r1mvpay6-py3.8\lib\site-packages\starlette\exceptions.py", line 71, in __call__
    await self.app(scope, receive, sender)
  File "c:\users\lucas\appdata\local\pypoetry\cache\virtualenvs\app-r1mvpay6-py3.8\lib\site-packages\starlette\routing.py", line 580, in __call__
    await route.handle(scope, receive, send)
  File "c:\users\lucas\appdata\local\pypoetry\cache\virtualenvs\app-r1mvpay6-py3.8\lib\site-packages\starlette\routing.py", line 241, in handle
    await self.app(scope, receive, send)
  File "c:\users\lucas\appdata\local\pypoetry\cache\virtualenvs\app-r1mvpay6-py3.8\lib\site-packages\starlette\routing.py", line 52, in app
    response = await func(request)
  File "c:\users\lucas\appdata\local\pypoetry\cache\virtualenvs\app-r1mvpay6-py3.8\lib\site-packages\fastapi\routing.py", line 201, in app
    raw_response = await run_endpoint_function(
  File "c:\users\lucas\appdata\local\pypoetry\cache\virtualenvs\app-r1mvpay6-py3.8\lib\site-packages\fastapi\routing.py", line 148, in run_endpoint_function
    return await dependant.call(**values)
  File ".\app\main.py", line 116, in update_cat
    if (cat.breed == breed):
AttributeError: 'dict' object has no attribute 'breed'
2021-05-17 01:06:15,448 - ERROR: Exception in ASGI application
Traceback (most recent call last):
  File "c:\users\lucas\appdata\local\pypoetry\cache\virtualenvs\app-r1mvpay6-py3.8\lib\site-packages\uvicorn\protocols\http\h11_impl.py", line 396, in run_asgi
    result = await app(self.scope, self.receive, self.send)
  File "c:\users\lucas\appdata\local\pypoetry\cache\virtualenvs\app-r1mvpay6-py3.8\lib\site-packages\uvicorn\middleware\proxy_headers.py", line 45, in __call__
    return await self.app(scope, receive, send)
  File "c:\users\lucas\appdata\local\pypoetry\cache\virtualenvs\app-r1mvpay6-py3.8\lib\site-packages\fastapi\applications.py", line 199, in __call__
    await super().__call__(scope, receive, send)
  File "c:\users\lucas\appdata\local\pypoetry\cache\virtualenvs\app-r1mvpay6-py3.8\lib\site-packages\starlette\applications.py", line 112, in __call__
    await self.middleware_stack(scope, receive, send)
  File "c:\users\lucas\appdata\local\pypoetry\cache\virtualenvs\app-r1mvpay6-py3.8\lib\site-packages\starlette\middleware\errors.py", line 181, in __call__
    raise exc from None
  File "c:\users\lucas\appdata\local\pypoetry\cache\virtualenvs\app-r1mvpay6-py3.8\lib\site-packages\starlette\middleware\errors.py", line 159, in __call__
    await self.app(scope, receive, _send)
  File "c:\users\lucas\appdata\local\pypoetry\cache\virtualenvs\app-r1mvpay6-py3.8\lib\site-packages\starlette\exceptions.py", line 82, in __call__
    raise exc from None
  File "c:\users\lucas\appdata\local\pypoetry\cache\virtualenvs\app-r1mvpay6-py3.8\lib\site-packages\starlette\exceptions.py", line 71, in __call__
    await self.app(scope, receive, sender)
  File "c:\users\lucas\appdata\local\pypoetry\cache\virtualenvs\app-r1mvpay6-py3.8\lib\site-packages\starlette\routing.py", line 580, in __call__
    await route.handle(scope, receive, send)
  File "c:\users\lucas\appdata\local\pypoetry\cache\virtualenvs\app-r1mvpay6-py3.8\lib\site-packages\starlette\routing.py", line 241, in handle
    await self.app(scope, receive, send)
  File "c:\users\lucas\appdata\local\pypoetry\cache\virtualenvs\app-r1mvpay6-py3.8\lib\site-packages\starlette\routing.py", line 52, in app
    response = await func(request)
  File "c:\users\lucas\appdata\local\pypoetry\cache\virtualenvs\app-r1mvpay6-py3.8\lib\site-packages\fastapi\routing.py", line 201, in app
    raw_response = await run_endpoint_function(
  File "c:\users\lucas\appdata\local\pypoetry\cache\virtualenvs\app-r1mvpay6-py3.8\lib\site-packages\fastapi\routing.py", line 148, in run_endpoint_function
    return await dependant.call(**values)
  File ".\app\main.py", line 116, in update_cat
    if (cat.breed == breed):
AttributeError: 'dict' object has no attribute 'breed'
2021-05-17 01:12:16,311 - INFO: Started server process [17024]
2021-05-17 01:12:16,311 - INFO: Waiting for application startup.
2021-05-17 01:12:16,312 - INFO: Application startup complete.
2021-05-17 01:12:33,613 - ERROR: Exception in ASGI application
Traceback (most recent call last):
  File "c:\users\lucas\appdata\local\pypoetry\cache\virtualenvs\app-r1mvpay6-py3.8\lib\site-packages\uvicorn\protocols\http\h11_impl.py", line 396, in run_asgi
    result = await app(self.scope, self.receive, self.send)
  File "c:\users\lucas\appdata\local\pypoetry\cache\virtualenvs\app-r1mvpay6-py3.8\lib\site-packages\uvicorn\middleware\proxy_headers.py", line 45, in __call__
    return await self.app(scope, receive, send)
  File "c:\users\lucas\appdata\local\pypoetry\cache\virtualenvs\app-r1mvpay6-py3.8\lib\site-packages\fastapi\applications.py", line 199, in __call__
    await super().__call__(scope, receive, send)
  File "c:\users\lucas\appdata\local\pypoetry\cache\virtualenvs\app-r1mvpay6-py3.8\lib\site-packages\starlette\applications.py", line 112, in __call__
    await self.middleware_stack(scope, receive, send)
  File "c:\users\lucas\appdata\local\pypoetry\cache\virtualenvs\app-r1mvpay6-py3.8\lib\site-packages\starlette\middleware\errors.py", line 181, in __call__
    raise exc from None
  File "c:\users\lucas\appdata\local\pypoetry\cache\virtualenvs\app-r1mvpay6-py3.8\lib\site-packages\starlette\middleware\errors.py", line 159, in __call__
    await self.app(scope, receive, _send)
  File "c:\users\lucas\appdata\local\pypoetry\cache\virtualenvs\app-r1mvpay6-py3.8\lib\site-packages\starlette\exceptions.py", line 82, in __call__
    raise exc from None
  File "c:\users\lucas\appdata\local\pypoetry\cache\virtualenvs\app-r1mvpay6-py3.8\lib\site-packages\starlette\exceptions.py", line 71, in __call__
    await self.app(scope, receive, sender)
  File "c:\users\lucas\appdata\local\pypoetry\cache\virtualenvs\app-r1mvpay6-py3.8\lib\site-packages\starlette\routing.py", line 580, in __call__
    await route.handle(scope, receive, send)
  File "c:\users\lucas\appdata\local\pypoetry\cache\virtualenvs\app-r1mvpay6-py3.8\lib\site-packages\starlette\routing.py", line 241, in handle
    await self.app(scope, receive, send)
  File "c:\users\lucas\appdata\local\pypoetry\cache\virtualenvs\app-r1mvpay6-py3.8\lib\site-packages\starlette\routing.py", line 52, in app
    response = await func(request)
  File "c:\users\lucas\appdata\local\pypoetry\cache\virtualenvs\app-r1mvpay6-py3.8\lib\site-packages\fastapi\routing.py", line 201, in app
    raw_response = await run_endpoint_function(
  File "c:\users\lucas\appdata\local\pypoetry\cache\virtualenvs\app-r1mvpay6-py3.8\lib\site-packages\fastapi\routing.py", line 148, in run_endpoint_function
    return await dependant.call(**values)
  File ".\app\main.py", line 147, in update_cat
    cats.update(update_cat)
AttributeError: 'list' object has no attribute 'update'
2021-05-17 01:18:37,983 - INFO: Started server process [9484]
2021-05-17 01:18:37,984 - INFO: Waiting for application startup.
2021-05-17 01:18:37,984 - INFO: Application startup complete.
2021-05-17 01:20:30,050 - INFO: Started server process [18160]
2021-05-17 01:20:30,050 - INFO: Waiting for application startup.
2021-05-17 01:20:30,051 - INFO: Application startup complete.
2021-05-17 01:21:44,352 - INFO: Started server process [16640]
2021-05-17 01:21:44,353 - INFO: Waiting for application startup.
2021-05-17 01:21:44,353 - INFO: Application startup complete.
2021-05-17 01:21:48,305 - INFO: Started server process [11188]
2021-05-17 01:21:48,306 - INFO: Waiting for application startup.
2021-05-17 01:21:48,306 - INFO: Application startup complete.
2021-05-17 01:21:56,098 - INFO: Started server process [18304]
2021-05-17 01:21:56,098 - INFO: Waiting for application startup.
2021-05-17 01:21:56,098 - INFO: Application startup complete.
2021-05-17 01:22:16,182 - INFO: Started server process [13380]
2021-05-17 01:22:16,183 - INFO: Waiting for application startup.
2021-05-17 01:22:16,183 - INFO: Application startup complete.
2021-05-17 01:22:25,593 - WARNING: Cat not found.
2021-05-17 01:22:33,406 - ERROR: Body type must be Small, Medium or Large
2021-05-17 01:22:39,010 - ERROR: Exception in ASGI application
Traceback (most recent call last):
  File "c:\users\lucas\appdata\local\pypoetry\cache\virtualenvs\app-r1mvpay6-py3.8\lib\site-packages\uvicorn\protocols\http\h11_impl.py", line 396, in run_asgi
    result = await app(self.scope, self.receive, self.send)
  File "c:\users\lucas\appdata\local\pypoetry\cache\virtualenvs\app-r1mvpay6-py3.8\lib\site-packages\uvicorn\middleware\proxy_headers.py", line 45, in __call__
    return await self.app(scope, receive, send)
  File "c:\users\lucas\appdata\local\pypoetry\cache\virtualenvs\app-r1mvpay6-py3.8\lib\site-packages\fastapi\applications.py", line 199, in __call__
    await super().__call__(scope, receive, send)
  File "c:\users\lucas\appdata\local\pypoetry\cache\virtualenvs\app-r1mvpay6-py3.8\lib\site-packages\starlette\applications.py", line 112, in __call__
    await self.middleware_stack(scope, receive, send)
  File "c:\users\lucas\appdata\local\pypoetry\cache\virtualenvs\app-r1mvpay6-py3.8\lib\site-packages\starlette\middleware\errors.py", line 181, in __call__
    raise exc from None
  File "c:\users\lucas\appdata\local\pypoetry\cache\virtualenvs\app-r1mvpay6-py3.8\lib\site-packages\starlette\middleware\errors.py", line 159, in __call__
    await self.app(scope, receive, _send)
  File "c:\users\lucas\appdata\local\pypoetry\cache\virtualenvs\app-r1mvpay6-py3.8\lib\site-packages\starlette\exceptions.py", line 82, in __call__
    raise exc from None
  File "c:\users\lucas\appdata\local\pypoetry\cache\virtualenvs\app-r1mvpay6-py3.8\lib\site-packages\starlette\exceptions.py", line 71, in __call__
    await self.app(scope, receive, sender)
  File "c:\users\lucas\appdata\local\pypoetry\cache\virtualenvs\app-r1mvpay6-py3.8\lib\site-packages\starlette\routing.py", line 580, in __call__
    await route.handle(scope, receive, send)
  File "c:\users\lucas\appdata\local\pypoetry\cache\virtualenvs\app-r1mvpay6-py3.8\lib\site-packages\starlette\routing.py", line 241, in handle
    await self.app(scope, receive, send)
  File "c:\users\lucas\appdata\local\pypoetry\cache\virtualenvs\app-r1mvpay6-py3.8\lib\site-packages\starlette\routing.py", line 52, in app
    response = await func(request)
  File "c:\users\lucas\appdata\local\pypoetry\cache\virtualenvs\app-r1mvpay6-py3.8\lib\site-packages\fastapi\routing.py", line 201, in app
    raw_response = await run_endpoint_function(
  File "c:\users\lucas\appdata\local\pypoetry\cache\virtualenvs\app-r1mvpay6-py3.8\lib\site-packages\fastapi\routing.py", line 148, in run_endpoint_function
    return await dependant.call(**values)
  File ".\app\main.py", line 148, in update_cat
    cats.update(update_cat)
AttributeError: 'list' object has no attribute 'update'
2021-05-17 01:22:58,268 - INFO: Started server process [17020]
2021-05-17 01:22:58,269 - INFO: Waiting for application startup.
2021-05-17 01:22:58,269 - INFO: Application startup complete.
2021-05-17 01:23:33,147 - ERROR: Exception in ASGI application
Traceback (most recent call last):
  File "c:\users\lucas\appdata\local\pypoetry\cache\virtualenvs\app-r1mvpay6-py3.8\lib\site-packages\uvicorn\protocols\http\h11_impl.py", line 396, in run_asgi
    result = await app(self.scope, self.receive, self.send)
  File "c:\users\lucas\appdata\local\pypoetry\cache\virtualenvs\app-r1mvpay6-py3.8\lib\site-packages\uvicorn\middleware\proxy_headers.py", line 45, in __call__
    return await self.app(scope, receive, send)
  File "c:\users\lucas\appdata\local\pypoetry\cache\virtualenvs\app-r1mvpay6-py3.8\lib\site-packages\fastapi\applications.py", line 199, in __call__
    await super().__call__(scope, receive, send)
  File "c:\users\lucas\appdata\local\pypoetry\cache\virtualenvs\app-r1mvpay6-py3.8\lib\site-packages\starlette\applications.py", line 112, in __call__
    await self.middleware_stack(scope, receive, send)
  File "c:\users\lucas\appdata\local\pypoetry\cache\virtualenvs\app-r1mvpay6-py3.8\lib\site-packages\starlette\middleware\errors.py", line 181, in __call__
    raise exc from None
  File "c:\users\lucas\appdata\local\pypoetry\cache\virtualenvs\app-r1mvpay6-py3.8\lib\site-packages\starlette\middleware\errors.py", line 159, in __call__
    await self.app(scope, receive, _send)
  File "c:\users\lucas\appdata\local\pypoetry\cache\virtualenvs\app-r1mvpay6-py3.8\lib\site-packages\starlette\exceptions.py", line 82, in __call__
    raise exc from None
  File "c:\users\lucas\appdata\local\pypoetry\cache\virtualenvs\app-r1mvpay6-py3.8\lib\site-packages\starlette\exceptions.py", line 71, in __call__
    await self.app(scope, receive, sender)
  File "c:\users\lucas\appdata\local\pypoetry\cache\virtualenvs\app-r1mvpay6-py3.8\lib\site-packages\starlette\routing.py", line 580, in __call__
    await route.handle(scope, receive, send)
  File "c:\users\lucas\appdata\local\pypoetry\cache\virtualenvs\app-r1mvpay6-py3.8\lib\site-packages\starlette\routing.py", line 241, in handle
    await self.app(scope, receive, send)
  File "c:\users\lucas\appdata\local\pypoetry\cache\virtualenvs\app-r1mvpay6-py3.8\lib\site-packages\starlette\routing.py", line 52, in app
    response = await func(request)
  File "c:\users\lucas\appdata\local\pypoetry\cache\virtualenvs\app-r1mvpay6-py3.8\lib\site-packages\fastapi\routing.py", line 201, in app
    raw_response = await run_endpoint_function(
  File "c:\users\lucas\appdata\local\pypoetry\cache\virtualenvs\app-r1mvpay6-py3.8\lib\site-packages\fastapi\routing.py", line 148, in run_endpoint_function
    return await dependant.call(**values)
  File ".\app\main.py", line 148, in update_cat
    cats.update(update_cat)
AttributeError: 'list' object has no attribute 'update'
2021-05-17 01:24:02,177 - INFO: Started server process [9032]
2021-05-17 01:24:02,178 - INFO: Waiting for application startup.
2021-05-17 01:24:02,178 - INFO: Application startup complete.
2021-05-17 01:25:41,532 - INFO: Started server process [16504]
2021-05-17 01:25:41,533 - INFO: Waiting for application startup.
2021-05-17 01:25:41,533 - INFO: Application startup complete.
2021-05-17 01:25:49,945 - ERROR: Exception in ASGI application
Traceback (most recent call last):
  File "c:\users\lucas\appdata\local\pypoetry\cache\virtualenvs\app-r1mvpay6-py3.8\lib\site-packages\uvicorn\protocols\http\h11_impl.py", line 396, in run_asgi
    result = await app(self.scope, self.receive, self.send)
  File "c:\users\lucas\appdata\local\pypoetry\cache\virtualenvs\app-r1mvpay6-py3.8\lib\site-packages\uvicorn\middleware\proxy_headers.py", line 45, in __call__
    return await self.app(scope, receive, send)
  File "c:\users\lucas\appdata\local\pypoetry\cache\virtualenvs\app-r1mvpay6-py3.8\lib\site-packages\fastapi\applications.py", line 199, in __call__
    await super().__call__(scope, receive, send)
  File "c:\users\lucas\appdata\local\pypoetry\cache\virtualenvs\app-r1mvpay6-py3.8\lib\site-packages\starlette\applications.py", line 112, in __call__
    await self.middleware_stack(scope, receive, send)
  File "c:\users\lucas\appdata\local\pypoetry\cache\virtualenvs\app-r1mvpay6-py3.8\lib\site-packages\starlette\middleware\errors.py", line 181, in __call__
    raise exc from None
  File "c:\users\lucas\appdata\local\pypoetry\cache\virtualenvs\app-r1mvpay6-py3.8\lib\site-packages\starlette\middleware\errors.py", line 159, in __call__
    await self.app(scope, receive, _send)
  File "c:\users\lucas\appdata\local\pypoetry\cache\virtualenvs\app-r1mvpay6-py3.8\lib\site-packages\starlette\exceptions.py", line 82, in __call__
    raise exc from None
  File "c:\users\lucas\appdata\local\pypoetry\cache\virtualenvs\app-r1mvpay6-py3.8\lib\site-packages\starlette\exceptions.py", line 71, in __call__
    await self.app(scope, receive, sender)
  File "c:\users\lucas\appdata\local\pypoetry\cache\virtualenvs\app-r1mvpay6-py3.8\lib\site-packages\starlette\routing.py", line 580, in __call__
    await route.handle(scope, receive, send)
  File "c:\users\lucas\appdata\local\pypoetry\cache\virtualenvs\app-r1mvpay6-py3.8\lib\site-packages\starlette\routing.py", line 241, in handle
    await self.app(scope, receive, send)
  File "c:\users\lucas\appdata\local\pypoetry\cache\virtualenvs\app-r1mvpay6-py3.8\lib\site-packages\starlette\routing.py", line 52, in app
    response = await func(request)
  File "c:\users\lucas\appdata\local\pypoetry\cache\virtualenvs\app-r1mvpay6-py3.8\lib\site-packages\fastapi\routing.py", line 201, in app
    raw_response = await run_endpoint_function(
  File "c:\users\lucas\appdata\local\pypoetry\cache\virtualenvs\app-r1mvpay6-py3.8\lib\site-packages\fastapi\routing.py", line 148, in run_endpoint_function
    return await dependant.call(**values)
  File ".\app\main.py", line 129, in update_cat
    location_of_origin = location_of_origin.capitalize()
AttributeError: 'NoneType' object has no attribute 'capitalize'
2021-05-17 01:27:08,618 - INFO: Started server process [15116]
2021-05-17 01:27:08,619 - INFO: Waiting for application startup.
2021-05-17 01:27:08,619 - INFO: Application startup complete.
2021-05-17 01:27:14,645 - WARNING: Cat not found.
2021-05-17 01:27:21,462 - ERROR: Exception in ASGI application
Traceback (most recent call last):
  File "c:\users\lucas\appdata\local\pypoetry\cache\virtualenvs\app-r1mvpay6-py3.8\lib\site-packages\uvicorn\protocols\http\h11_impl.py", line 396, in run_asgi
    result = await app(self.scope, self.receive, self.send)
  File "c:\users\lucas\appdata\local\pypoetry\cache\virtualenvs\app-r1mvpay6-py3.8\lib\site-packages\uvicorn\middleware\proxy_headers.py", line 45, in __call__
    return await self.app(scope, receive, send)
  File "c:\users\lucas\appdata\local\pypoetry\cache\virtualenvs\app-r1mvpay6-py3.8\lib\site-packages\fastapi\applications.py", line 199, in __call__
    await super().__call__(scope, receive, send)
  File "c:\users\lucas\appdata\local\pypoetry\cache\virtualenvs\app-r1mvpay6-py3.8\lib\site-packages\starlette\applications.py", line 112, in __call__
    await self.middleware_stack(scope, receive, send)
  File "c:\users\lucas\appdata\local\pypoetry\cache\virtualenvs\app-r1mvpay6-py3.8\lib\site-packages\starlette\middleware\errors.py", line 181, in __call__
    raise exc from None
  File "c:\users\lucas\appdata\local\pypoetry\cache\virtualenvs\app-r1mvpay6-py3.8\lib\site-packages\starlette\middleware\errors.py", line 159, in __call__
    await self.app(scope, receive, _send)
  File "c:\users\lucas\appdata\local\pypoetry\cache\virtualenvs\app-r1mvpay6-py3.8\lib\site-packages\starlette\exceptions.py", line 82, in __call__
    raise exc from None
  File "c:\users\lucas\appdata\local\pypoetry\cache\virtualenvs\app-r1mvpay6-py3.8\lib\site-packages\starlette\exceptions.py", line 71, in __call__
    await self.app(scope, receive, sender)
  File "c:\users\lucas\appdata\local\pypoetry\cache\virtualenvs\app-r1mvpay6-py3.8\lib\site-packages\starlette\routing.py", line 580, in __call__
    await route.handle(scope, receive, send)
  File "c:\users\lucas\appdata\local\pypoetry\cache\virtualenvs\app-r1mvpay6-py3.8\lib\site-packages\starlette\routing.py", line 241, in handle
    await self.app(scope, receive, send)
  File "c:\users\lucas\appdata\local\pypoetry\cache\virtualenvs\app-r1mvpay6-py3.8\lib\site-packages\starlette\routing.py", line 52, in app
    response = await func(request)
  File "c:\users\lucas\appdata\local\pypoetry\cache\virtualenvs\app-r1mvpay6-py3.8\lib\site-packages\fastapi\routing.py", line 201, in app
    raw_response = await run_endpoint_function(
  File "c:\users\lucas\appdata\local\pypoetry\cache\virtualenvs\app-r1mvpay6-py3.8\lib\site-packages\fastapi\routing.py", line 148, in run_endpoint_function
    return await dependant.call(**values)
  File ".\app\main.py", line 135, in update_cat
    if coat_length < 0:
TypeError: '<' not supported between instances of 'NoneType' and 'int'
2021-05-17 01:27:42,523 - INFO: Started server process [16256]
2021-05-17 01:27:42,523 - INFO: Waiting for application startup.
2021-05-17 01:27:42,523 - INFO: Application startup complete.
2021-05-17 01:27:55,223 - ERROR: Body type must be Small, Medium or Large
2021-05-17 01:28:13,536 - INFO: Started server process [10452]
2021-05-17 01:28:13,537 - INFO: Waiting for application startup.
2021-05-17 01:28:13,537 - INFO: Application startup complete.
2021-05-17 01:28:19,169 - ERROR: Exception in ASGI application
Traceback (most recent call last):
  File "c:\users\lucas\appdata\local\pypoetry\cache\virtualenvs\app-r1mvpay6-py3.8\lib\site-packages\uvicorn\protocols\http\h11_impl.py", line 396, in run_asgi
    result = await app(self.scope, self.receive, self.send)
  File "c:\users\lucas\appdata\local\pypoetry\cache\virtualenvs\app-r1mvpay6-py3.8\lib\site-packages\uvicorn\middleware\proxy_headers.py", line 45, in __call__
    return await self.app(scope, receive, send)
  File "c:\users\lucas\appdata\local\pypoetry\cache\virtualenvs\app-r1mvpay6-py3.8\lib\site-packages\fastapi\applications.py", line 199, in __call__
    await super().__call__(scope, receive, send)
  File "c:\users\lucas\appdata\local\pypoetry\cache\virtualenvs\app-r1mvpay6-py3.8\lib\site-packages\starlette\applications.py", line 112, in __call__
    await self.middleware_stack(scope, receive, send)
  File "c:\users\lucas\appdata\local\pypoetry\cache\virtualenvs\app-r1mvpay6-py3.8\lib\site-packages\starlette\middleware\errors.py", line 181, in __call__
    raise exc from None
  File "c:\users\lucas\appdata\local\pypoetry\cache\virtualenvs\app-r1mvpay6-py3.8\lib\site-packages\starlette\middleware\errors.py", line 159, in __call__
    await self.app(scope, receive, _send)
  File "c:\users\lucas\appdata\local\pypoetry\cache\virtualenvs\app-r1mvpay6-py3.8\lib\site-packages\starlette\exceptions.py", line 82, in __call__
    raise exc from None
  File "c:\users\lucas\appdata\local\pypoetry\cache\virtualenvs\app-r1mvpay6-py3.8\lib\site-packages\starlette\exceptions.py", line 71, in __call__
    await self.app(scope, receive, sender)
  File "c:\users\lucas\appdata\local\pypoetry\cache\virtualenvs\app-r1mvpay6-py3.8\lib\site-packages\starlette\routing.py", line 580, in __call__
    await route.handle(scope, receive, send)
  File "c:\users\lucas\appdata\local\pypoetry\cache\virtualenvs\app-r1mvpay6-py3.8\lib\site-packages\starlette\routing.py", line 241, in handle
    await self.app(scope, receive, send)
  File "c:\users\lucas\appdata\local\pypoetry\cache\virtualenvs\app-r1mvpay6-py3.8\lib\site-packages\starlette\routing.py", line 52, in app
    response = await func(request)
  File "c:\users\lucas\appdata\local\pypoetry\cache\virtualenvs\app-r1mvpay6-py3.8\lib\site-packages\fastapi\routing.py", line 201, in app
    raw_response = await run_endpoint_function(
  File "c:\users\lucas\appdata\local\pypoetry\cache\virtualenvs\app-r1mvpay6-py3.8\lib\site-packages\fastapi\routing.py", line 148, in run_endpoint_function
    return await dependant.call(**values)
  File ".\app\main.py", line 153, in update_cat
    cats.update(update_cat)
AttributeError: 'list' object has no attribute 'update'
2021-05-17 01:28:33,391 - INFO: Started server process [4032]
2021-05-17 01:28:33,392 - INFO: Waiting for application startup.
2021-05-17 01:28:33,392 - INFO: Application startup complete.
2021-05-17 01:28:35,615 - ERROR: Exception in ASGI application
Traceback (most recent call last):
  File "c:\users\lucas\appdata\local\pypoetry\cache\virtualenvs\app-r1mvpay6-py3.8\lib\site-packages\uvicorn\protocols\http\h11_impl.py", line 396, in run_asgi
    result = await app(self.scope, self.receive, self.send)
  File "c:\users\lucas\appdata\local\pypoetry\cache\virtualenvs\app-r1mvpay6-py3.8\lib\site-packages\uvicorn\middleware\proxy_headers.py", line 45, in __call__
    return await self.app(scope, receive, send)
  File "c:\users\lucas\appdata\local\pypoetry\cache\virtualenvs\app-r1mvpay6-py3.8\lib\site-packages\fastapi\applications.py", line 199, in __call__
    await super().__call__(scope, receive, send)
  File "c:\users\lucas\appdata\local\pypoetry\cache\virtualenvs\app-r1mvpay6-py3.8\lib\site-packages\starlette\applications.py", line 112, in __call__
    await self.middleware_stack(scope, receive, send)
  File "c:\users\lucas\appdata\local\pypoetry\cache\virtualenvs\app-r1mvpay6-py3.8\lib\site-packages\starlette\middleware\errors.py", line 181, in __call__
    raise exc from None
  File "c:\users\lucas\appdata\local\pypoetry\cache\virtualenvs\app-r1mvpay6-py3.8\lib\site-packages\starlette\middleware\errors.py", line 159, in __call__
    await self.app(scope, receive, _send)
  File "c:\users\lucas\appdata\local\pypoetry\cache\virtualenvs\app-r1mvpay6-py3.8\lib\site-packages\starlette\exceptions.py", line 82, in __call__
    raise exc from None
  File "c:\users\lucas\appdata\local\pypoetry\cache\virtualenvs\app-r1mvpay6-py3.8\lib\site-packages\starlette\exceptions.py", line 71, in __call__
    await self.app(scope, receive, sender)
  File "c:\users\lucas\appdata\local\pypoetry\cache\virtualenvs\app-r1mvpay6-py3.8\lib\site-packages\starlette\routing.py", line 580, in __call__
    await route.handle(scope, receive, send)
  File "c:\users\lucas\appdata\local\pypoetry\cache\virtualenvs\app-r1mvpay6-py3.8\lib\site-packages\starlette\routing.py", line 241, in handle
    await self.app(scope, receive, send)
  File "c:\users\lucas\appdata\local\pypoetry\cache\virtualenvs\app-r1mvpay6-py3.8\lib\site-packages\starlette\routing.py", line 52, in app
    response = await func(request)
  File "c:\users\lucas\appdata\local\pypoetry\cache\virtualenvs\app-r1mvpay6-py3.8\lib\site-packages\fastapi\routing.py", line 201, in app
    raw_response = await run_endpoint_function(
  File "c:\users\lucas\appdata\local\pypoetry\cache\virtualenvs\app-r1mvpay6-py3.8\lib\site-packages\fastapi\routing.py", line 148, in run_endpoint_function
    return await dependant.call(**values)
  File ".\app\main.py", line 153, in update_cat
    cats.update(cat)
AttributeError: 'list' object has no attribute 'update'
2021-05-17 01:28:54,167 - INFO: Started server process [14252]
2021-05-17 01:28:54,167 - INFO: Waiting for application startup.
2021-05-17 01:28:54,168 - INFO: Application startup complete.
2021-05-17 01:29:05,739 - ERROR: Exception in ASGI application
Traceback (most recent call last):
  File "c:\users\lucas\appdata\local\pypoetry\cache\virtualenvs\app-r1mvpay6-py3.8\lib\site-packages\uvicorn\protocols\http\h11_impl.py", line 396, in run_asgi
    result = await app(self.scope, self.receive, self.send)
  File "c:\users\lucas\appdata\local\pypoetry\cache\virtualenvs\app-r1mvpay6-py3.8\lib\site-packages\uvicorn\middleware\proxy_headers.py", line 45, in __call__
    return await self.app(scope, receive, send)
  File "c:\users\lucas\appdata\local\pypoetry\cache\virtualenvs\app-r1mvpay6-py3.8\lib\site-packages\fastapi\applications.py", line 199, in __call__
    await super().__call__(scope, receive, send)
  File "c:\users\lucas\appdata\local\pypoetry\cache\virtualenvs\app-r1mvpay6-py3.8\lib\site-packages\starlette\applications.py", line 112, in __call__
    await self.middleware_stack(scope, receive, send)
  File "c:\users\lucas\appdata\local\pypoetry\cache\virtualenvs\app-r1mvpay6-py3.8\lib\site-packages\starlette\middleware\errors.py", line 181, in __call__
    raise exc from None
  File "c:\users\lucas\appdata\local\pypoetry\cache\virtualenvs\app-r1mvpay6-py3.8\lib\site-packages\starlette\middleware\errors.py", line 159, in __call__
    await self.app(scope, receive, _send)
  File "c:\users\lucas\appdata\local\pypoetry\cache\virtualenvs\app-r1mvpay6-py3.8\lib\site-packages\starlette\exceptions.py", line 82, in __call__
    raise exc from None
  File "c:\users\lucas\appdata\local\pypoetry\cache\virtualenvs\app-r1mvpay6-py3.8\lib\site-packages\starlette\exceptions.py", line 71, in __call__
    await self.app(scope, receive, sender)
  File "c:\users\lucas\appdata\local\pypoetry\cache\virtualenvs\app-r1mvpay6-py3.8\lib\site-packages\starlette\routing.py", line 580, in __call__
    await route.handle(scope, receive, send)
  File "c:\users\lucas\appdata\local\pypoetry\cache\virtualenvs\app-r1mvpay6-py3.8\lib\site-packages\starlette\routing.py", line 241, in handle
    await self.app(scope, receive, send)
  File "c:\users\lucas\appdata\local\pypoetry\cache\virtualenvs\app-r1mvpay6-py3.8\lib\site-packages\starlette\routing.py", line 52, in app
    response = await func(request)
  File "c:\users\lucas\appdata\local\pypoetry\cache\virtualenvs\app-r1mvpay6-py3.8\lib\site-packages\fastapi\routing.py", line 201, in app
    raw_response = await run_endpoint_function(
  File "c:\users\lucas\appdata\local\pypoetry\cache\virtualenvs\app-r1mvpay6-py3.8\lib\site-packages\fastapi\routing.py", line 148, in run_endpoint_function
    return await dependant.call(**values)
  File ".\app\main.py", line 153, in update_cat
    return cats.update(cat)
AttributeError: 'list' object has no attribute 'update'
2021-05-17 01:29:31,664 - INFO: Started server process [14456]
2021-05-17 01:29:31,664 - INFO: Waiting for application startup.
2021-05-17 01:29:31,665 - INFO: Application startup complete.
2021-05-17 01:29:36,870 - ERROR: Exception in ASGI application
Traceback (most recent call last):
  File "c:\users\lucas\appdata\local\pypoetry\cache\virtualenvs\app-r1mvpay6-py3.8\lib\site-packages\uvicorn\protocols\http\h11_impl.py", line 396, in run_asgi
    result = await app(self.scope, self.receive, self.send)
  File "c:\users\lucas\appdata\local\pypoetry\cache\virtualenvs\app-r1mvpay6-py3.8\lib\site-packages\uvicorn\middleware\proxy_headers.py", line 45, in __call__
    return await self.app(scope, receive, send)
  File "c:\users\lucas\appdata\local\pypoetry\cache\virtualenvs\app-r1mvpay6-py3.8\lib\site-packages\fastapi\applications.py", line 199, in __call__
    await super().__call__(scope, receive, send)
  File "c:\users\lucas\appdata\local\pypoetry\cache\virtualenvs\app-r1mvpay6-py3.8\lib\site-packages\starlette\applications.py", line 112, in __call__
    await self.middleware_stack(scope, receive, send)
  File "c:\users\lucas\appdata\local\pypoetry\cache\virtualenvs\app-r1mvpay6-py3.8\lib\site-packages\starlette\middleware\errors.py", line 181, in __call__
    raise exc from None
  File "c:\users\lucas\appdata\local\pypoetry\cache\virtualenvs\app-r1mvpay6-py3.8\lib\site-packages\starlette\middleware\errors.py", line 159, in __call__
    await self.app(scope, receive, _send)
  File "c:\users\lucas\appdata\local\pypoetry\cache\virtualenvs\app-r1mvpay6-py3.8\lib\site-packages\starlette\exceptions.py", line 82, in __call__
    raise exc from None
  File "c:\users\lucas\appdata\local\pypoetry\cache\virtualenvs\app-r1mvpay6-py3.8\lib\site-packages\starlette\exceptions.py", line 71, in __call__
    await self.app(scope, receive, sender)
  File "c:\users\lucas\appdata\local\pypoetry\cache\virtualenvs\app-r1mvpay6-py3.8\lib\site-packages\starlette\routing.py", line 580, in __call__
    await route.handle(scope, receive, send)
  File "c:\users\lucas\appdata\local\pypoetry\cache\virtualenvs\app-r1mvpay6-py3.8\lib\site-packages\starlette\routing.py", line 241, in handle
    await self.app(scope, receive, send)
  File "c:\users\lucas\appdata\local\pypoetry\cache\virtualenvs\app-r1mvpay6-py3.8\lib\site-packages\starlette\routing.py", line 52, in app
    response = await func(request)
  File "c:\users\lucas\appdata\local\pypoetry\cache\virtualenvs\app-r1mvpay6-py3.8\lib\site-packages\fastapi\routing.py", line 201, in app
    raw_response = await run_endpoint_function(
  File "c:\users\lucas\appdata\local\pypoetry\cache\virtualenvs\app-r1mvpay6-py3.8\lib\site-packages\fastapi\routing.py", line 148, in run_endpoint_function
    return await dependant.call(**values)
  File ".\app\main.py", line 153, in update_cat
    return cats.update(cat)
AttributeError: 'list' object has no attribute 'update'
2021-05-17 01:29:52,554 - INFO: Started server process [13116]
2021-05-17 01:29:52,555 - INFO: Waiting for application startup.
2021-05-17 01:29:52,555 - INFO: Application startup complete.
2021-05-17 01:29:52,557 - ERROR: Exception in ASGI application
Traceback (most recent call last):
  File "c:\users\lucas\appdata\local\pypoetry\cache\virtualenvs\app-r1mvpay6-py3.8\lib\site-packages\uvicorn\protocols\http\h11_impl.py", line 396, in run_asgi
    result = await app(self.scope, self.receive, self.send)
  File "c:\users\lucas\appdata\local\pypoetry\cache\virtualenvs\app-r1mvpay6-py3.8\lib\site-packages\uvicorn\middleware\proxy_headers.py", line 45, in __call__
    return await self.app(scope, receive, send)
  File "c:\users\lucas\appdata\local\pypoetry\cache\virtualenvs\app-r1mvpay6-py3.8\lib\site-packages\fastapi\applications.py", line 199, in __call__
    await super().__call__(scope, receive, send)
  File "c:\users\lucas\appdata\local\pypoetry\cache\virtualenvs\app-r1mvpay6-py3.8\lib\site-packages\starlette\applications.py", line 112, in __call__
    await self.middleware_stack(scope, receive, send)
  File "c:\users\lucas\appdata\local\pypoetry\cache\virtualenvs\app-r1mvpay6-py3.8\lib\site-packages\starlette\middleware\errors.py", line 181, in __call__
    raise exc from None
  File "c:\users\lucas\appdata\local\pypoetry\cache\virtualenvs\app-r1mvpay6-py3.8\lib\site-packages\starlette\middleware\errors.py", line 159, in __call__
    await self.app(scope, receive, _send)
  File "c:\users\lucas\appdata\local\pypoetry\cache\virtualenvs\app-r1mvpay6-py3.8\lib\site-packages\starlette\exceptions.py", line 82, in __call__
    raise exc from None
  File "c:\users\lucas\appdata\local\pypoetry\cache\virtualenvs\app-r1mvpay6-py3.8\lib\site-packages\starlette\exceptions.py", line 71, in __call__
    await self.app(scope, receive, sender)
  File "c:\users\lucas\appdata\local\pypoetry\cache\virtualenvs\app-r1mvpay6-py3.8\lib\site-packages\starlette\routing.py", line 580, in __call__
    await route.handle(scope, receive, send)
  File "c:\users\lucas\appdata\local\pypoetry\cache\virtualenvs\app-r1mvpay6-py3.8\lib\site-packages\starlette\routing.py", line 241, in handle
    await self.app(scope, receive, send)
  File "c:\users\lucas\appdata\local\pypoetry\cache\virtualenvs\app-r1mvpay6-py3.8\lib\site-packages\starlette\routing.py", line 52, in app
    response = await func(request)
  File "c:\users\lucas\appdata\local\pypoetry\cache\virtualenvs\app-r1mvpay6-py3.8\lib\site-packages\fastapi\routing.py", line 201, in app
    raw_response = await run_endpoint_function(
  File "c:\users\lucas\appdata\local\pypoetry\cache\virtualenvs\app-r1mvpay6-py3.8\lib\site-packages\fastapi\routing.py", line 148, in run_endpoint_function
    return await dependant.call(**values)
  File ".\app\main.py", line 153, in update_cat
    return cats.update(cat)
AttributeError: 'list' object has no attribute 'update'
2021-05-17 01:29:53,730 - ERROR: Exception in ASGI application
Traceback (most recent call last):
  File "c:\users\lucas\appdata\local\pypoetry\cache\virtualenvs\app-r1mvpay6-py3.8\lib\site-packages\uvicorn\protocols\http\h11_impl.py", line 396, in run_asgi
    result = await app(self.scope, self.receive, self.send)
  File "c:\users\lucas\appdata\local\pypoetry\cache\virtualenvs\app-r1mvpay6-py3.8\lib\site-packages\uvicorn\middleware\proxy_headers.py", line 45, in __call__
    return await self.app(scope, receive, send)
  File "c:\users\lucas\appdata\local\pypoetry\cache\virtualenvs\app-r1mvpay6-py3.8\lib\site-packages\fastapi\applications.py", line 199, in __call__
    await super().__call__(scope, receive, send)
  File "c:\users\lucas\appdata\local\pypoetry\cache\virtualenvs\app-r1mvpay6-py3.8\lib\site-packages\starlette\applications.py", line 112, in __call__
    await self.middleware_stack(scope, receive, send)
  File "c:\users\lucas\appdata\local\pypoetry\cache\virtualenvs\app-r1mvpay6-py3.8\lib\site-packages\starlette\middleware\errors.py", line 181, in __call__
    raise exc from None
  File "c:\users\lucas\appdata\local\pypoetry\cache\virtualenvs\app-r1mvpay6-py3.8\lib\site-packages\starlette\middleware\errors.py", line 159, in __call__
    await self.app(scope, receive, _send)
  File "c:\users\lucas\appdata\local\pypoetry\cache\virtualenvs\app-r1mvpay6-py3.8\lib\site-packages\starlette\exceptions.py", line 82, in __call__
    raise exc from None
  File "c:\users\lucas\appdata\local\pypoetry\cache\virtualenvs\app-r1mvpay6-py3.8\lib\site-packages\starlette\exceptions.py", line 71, in __call__
    await self.app(scope, receive, sender)
  File "c:\users\lucas\appdata\local\pypoetry\cache\virtualenvs\app-r1mvpay6-py3.8\lib\site-packages\starlette\routing.py", line 580, in __call__
    await route.handle(scope, receive, send)
  File "c:\users\lucas\appdata\local\pypoetry\cache\virtualenvs\app-r1mvpay6-py3.8\lib\site-packages\starlette\routing.py", line 241, in handle
    await self.app(scope, receive, send)
  File "c:\users\lucas\appdata\local\pypoetry\cache\virtualenvs\app-r1mvpay6-py3.8\lib\site-packages\starlette\routing.py", line 52, in app
    response = await func(request)
  File "c:\users\lucas\appdata\local\pypoetry\cache\virtualenvs\app-r1mvpay6-py3.8\lib\site-packages\fastapi\routing.py", line 201, in app
    raw_response = await run_endpoint_function(
  File "c:\users\lucas\appdata\local\pypoetry\cache\virtualenvs\app-r1mvpay6-py3.8\lib\site-packages\fastapi\routing.py", line 148, in run_endpoint_function
    return await dependant.call(**values)
  File ".\app\main.py", line 153, in update_cat
    return cats.update(cat)
AttributeError: 'list' object has no attribute 'update'
2021-05-17 01:30:02,367 - ERROR: Exception in ASGI application
Traceback (most recent call last):
  File "c:\users\lucas\appdata\local\pypoetry\cache\virtualenvs\app-r1mvpay6-py3.8\lib\site-packages\uvicorn\protocols\http\h11_impl.py", line 396, in run_asgi
    result = await app(self.scope, self.receive, self.send)
  File "c:\users\lucas\appdata\local\pypoetry\cache\virtualenvs\app-r1mvpay6-py3.8\lib\site-packages\uvicorn\middleware\proxy_headers.py", line 45, in __call__
    return await self.app(scope, receive, send)
  File "c:\users\lucas\appdata\local\pypoetry\cache\virtualenvs\app-r1mvpay6-py3.8\lib\site-packages\fastapi\applications.py", line 199, in __call__
    await super().__call__(scope, receive, send)
  File "c:\users\lucas\appdata\local\pypoetry\cache\virtualenvs\app-r1mvpay6-py3.8\lib\site-packages\starlette\applications.py", line 112, in __call__
    await self.middleware_stack(scope, receive, send)
  File "c:\users\lucas\appdata\local\pypoetry\cache\virtualenvs\app-r1mvpay6-py3.8\lib\site-packages\starlette\middleware\errors.py", line 181, in __call__
    raise exc from None
  File "c:\users\lucas\appdata\local\pypoetry\cache\virtualenvs\app-r1mvpay6-py3.8\lib\site-packages\starlette\middleware\errors.py", line 159, in __call__
    await self.app(scope, receive, _send)
  File "c:\users\lucas\appdata\local\pypoetry\cache\virtualenvs\app-r1mvpay6-py3.8\lib\site-packages\starlette\exceptions.py", line 82, in __call__
    raise exc from None
  File "c:\users\lucas\appdata\local\pypoetry\cache\virtualenvs\app-r1mvpay6-py3.8\lib\site-packages\starlette\exceptions.py", line 71, in __call__
    await self.app(scope, receive, sender)
  File "c:\users\lucas\appdata\local\pypoetry\cache\virtualenvs\app-r1mvpay6-py3.8\lib\site-packages\starlette\routing.py", line 580, in __call__
    await route.handle(scope, receive, send)
  File "c:\users\lucas\appdata\local\pypoetry\cache\virtualenvs\app-r1mvpay6-py3.8\lib\site-packages\starlette\routing.py", line 241, in handle
    await self.app(scope, receive, send)
  File "c:\users\lucas\appdata\local\pypoetry\cache\virtualenvs\app-r1mvpay6-py3.8\lib\site-packages\starlette\routing.py", line 52, in app
    response = await func(request)
  File "c:\users\lucas\appdata\local\pypoetry\cache\virtualenvs\app-r1mvpay6-py3.8\lib\site-packages\fastapi\routing.py", line 201, in app
    raw_response = await run_endpoint_function(
  File "c:\users\lucas\appdata\local\pypoetry\cache\virtualenvs\app-r1mvpay6-py3.8\lib\site-packages\fastapi\routing.py", line 148, in run_endpoint_function
    return await dependant.call(**values)
  File ".\app\main.py", line 153, in update_cat
    return cats.update(cat)
AttributeError: 'list' object has no attribute 'update'
2021-05-17 01:30:45,202 - INFO: Started server process [18276]
2021-05-17 01:30:45,203 - INFO: Waiting for application startup.
2021-05-17 01:30:45,203 - INFO: Application startup complete.
2021-05-17 01:30:49,860 - ERROR: Exception in ASGI application
Traceback (most recent call last):
  File "c:\users\lucas\appdata\local\pypoetry\cache\virtualenvs\app-r1mvpay6-py3.8\lib\site-packages\uvicorn\protocols\http\h11_impl.py", line 396, in run_asgi
    result = await app(self.scope, self.receive, self.send)
  File "c:\users\lucas\appdata\local\pypoetry\cache\virtualenvs\app-r1mvpay6-py3.8\lib\site-packages\uvicorn\middleware\proxy_headers.py", line 45, in __call__
    return await self.app(scope, receive, send)
  File "c:\users\lucas\appdata\local\pypoetry\cache\virtualenvs\app-r1mvpay6-py3.8\lib\site-packages\fastapi\applications.py", line 199, in __call__
    await super().__call__(scope, receive, send)
  File "c:\users\lucas\appdata\local\pypoetry\cache\virtualenvs\app-r1mvpay6-py3.8\lib\site-packages\starlette\applications.py", line 112, in __call__
    await self.middleware_stack(scope, receive, send)
  File "c:\users\lucas\appdata\local\pypoetry\cache\virtualenvs\app-r1mvpay6-py3.8\lib\site-packages\starlette\middleware\errors.py", line 181, in __call__
    raise exc from None
  File "c:\users\lucas\appdata\local\pypoetry\cache\virtualenvs\app-r1mvpay6-py3.8\lib\site-packages\starlette\middleware\errors.py", line 159, in __call__
    await self.app(scope, receive, _send)
  File "c:\users\lucas\appdata\local\pypoetry\cache\virtualenvs\app-r1mvpay6-py3.8\lib\site-packages\starlette\exceptions.py", line 82, in __call__
    raise exc from None
  File "c:\users\lucas\appdata\local\pypoetry\cache\virtualenvs\app-r1mvpay6-py3.8\lib\site-packages\starlette\exceptions.py", line 71, in __call__
    await self.app(scope, receive, sender)
  File "c:\users\lucas\appdata\local\pypoetry\cache\virtualenvs\app-r1mvpay6-py3.8\lib\site-packages\starlette\routing.py", line 580, in __call__
    await route.handle(scope, receive, send)
  File "c:\users\lucas\appdata\local\pypoetry\cache\virtualenvs\app-r1mvpay6-py3.8\lib\site-packages\starlette\routing.py", line 241, in handle
    await self.app(scope, receive, send)
  File "c:\users\lucas\appdata\local\pypoetry\cache\virtualenvs\app-r1mvpay6-py3.8\lib\site-packages\starlette\routing.py", line 52, in app
    response = await func(request)
  File "c:\users\lucas\appdata\local\pypoetry\cache\virtualenvs\app-r1mvpay6-py3.8\lib\site-packages\fastapi\routing.py", line 201, in app
    raw_response = await run_endpoint_function(
  File "c:\users\lucas\appdata\local\pypoetry\cache\virtualenvs\app-r1mvpay6-py3.8\lib\site-packages\fastapi\routing.py", line 148, in run_endpoint_function
    return await dependant.call(**values)
  File ".\app\main.py", line 149, in update_cat
    return cats.update(cat)
AttributeError: 'list' object has no attribute 'update'
2021-05-17 01:31:07,154 - INFO: Started server process [16500]
2021-05-17 01:31:07,154 - INFO: Waiting for application startup.
2021-05-17 01:31:07,154 - INFO: Application startup complete.
2021-05-17 01:31:12,653 - WARNING: Cat not found.
2021-05-17 01:32:04,427 - INFO: Started server process [17872]
2021-05-17 01:32:04,427 - INFO: Waiting for application startup.
2021-05-17 01:32:04,428 - INFO: Application startup complete.
2021-05-17 01:35:08,720 - INFO: Shutting down
2021-05-17 01:35:08,831 - INFO: Waiting for application shutdown.
2021-05-17 01:35:08,831 - INFO: Application shutdown complete.
2021-05-17 01:35:08,831 - INFO: Finished server process [17872]
2021-05-17 11:06:55,173 - INFO: Started server process [11020]
2021-05-17 11:06:55,173 - INFO: Waiting for application startup.
2021-05-17 11:06:55,174 - INFO: Application startup complete.
2021-05-17 11:45:30,204 - ERROR: Exception in ASGI application
Traceback (most recent call last):
  File "c:\users\lucas\appdata\local\pypoetry\cache\virtualenvs\app-r1mvpay6-py3.8\lib\site-packages\uvicorn\protocols\http\h11_impl.py", line 396, in run_asgi
    result = await app(self.scope, self.receive, self.send)
  File "c:\users\lucas\appdata\local\pypoetry\cache\virtualenvs\app-r1mvpay6-py3.8\lib\site-packages\uvicorn\middleware\proxy_headers.py", line 45, in __call__
    return await self.app(scope, receive, send)
  File "c:\users\lucas\appdata\local\pypoetry\cache\virtualenvs\app-r1mvpay6-py3.8\lib\site-packages\fastapi\applications.py", line 199, in __call__
    await super().__call__(scope, receive, send)
  File "c:\users\lucas\appdata\local\pypoetry\cache\virtualenvs\app-r1mvpay6-py3.8\lib\site-packages\starlette\applications.py", line 112, in __call__
    await self.middleware_stack(scope, receive, send)
  File "c:\users\lucas\appdata\local\pypoetry\cache\virtualenvs\app-r1mvpay6-py3.8\lib\site-packages\starlette\middleware\errors.py", line 181, in __call__
    raise exc from None
  File "c:\users\lucas\appdata\local\pypoetry\cache\virtualenvs\app-r1mvpay6-py3.8\lib\site-packages\starlette\middleware\errors.py", line 159, in __call__
    await self.app(scope, receive, _send)
  File "c:\users\lucas\appdata\local\pypoetry\cache\virtualenvs\app-r1mvpay6-py3.8\lib\site-packages\starlette\exceptions.py", line 82, in __call__
    raise exc from None
  File "c:\users\lucas\appdata\local\pypoetry\cache\virtualenvs\app-r1mvpay6-py3.8\lib\site-packages\starlette\exceptions.py", line 71, in __call__
    await self.app(scope, receive, sender)
  File "c:\users\lucas\appdata\local\pypoetry\cache\virtualenvs\app-r1mvpay6-py3.8\lib\site-packages\starlette\routing.py", line 580, in __call__
    await route.handle(scope, receive, send)
  File "c:\users\lucas\appdata\local\pypoetry\cache\virtualenvs\app-r1mvpay6-py3.8\lib\site-packages\starlette\routing.py", line 241, in handle
    await self.app(scope, receive, send)
  File "c:\users\lucas\appdata\local\pypoetry\cache\virtualenvs\app-r1mvpay6-py3.8\lib\site-packages\starlette\routing.py", line 52, in app
    response = await func(request)
  File "c:\users\lucas\appdata\local\pypoetry\cache\virtualenvs\app-r1mvpay6-py3.8\lib\site-packages\fastapi\routing.py", line 201, in app
    raw_response = await run_endpoint_function(
  File "c:\users\lucas\appdata\local\pypoetry\cache\virtualenvs\app-r1mvpay6-py3.8\lib\site-packages\fastapi\routing.py", line 148, in run_endpoint_function
    return await dependant.call(**values)
  File ".\app\main.py", line 149, in update_cat
    return cats.update(cat)
AttributeError: 'list' object has no attribute 'update'
2021-05-17 11:46:31,100 - INFO: Started server process [7420]
2021-05-17 11:46:31,101 - INFO: Waiting for application startup.
2021-05-17 11:46:31,101 - INFO: Application startup complete.
2021-05-17 11:46:33,437 - ERROR: Exception in ASGI application
Traceback (most recent call last):
  File "c:\users\lucas\appdata\local\pypoetry\cache\virtualenvs\app-r1mvpay6-py3.8\lib\site-packages\uvicorn\protocols\http\h11_impl.py", line 396, in run_asgi
    result = await app(self.scope, self.receive, self.send)
  File "c:\users\lucas\appdata\local\pypoetry\cache\virtualenvs\app-r1mvpay6-py3.8\lib\site-packages\uvicorn\middleware\proxy_headers.py", line 45, in __call__
    return await self.app(scope, receive, send)
  File "c:\users\lucas\appdata\local\pypoetry\cache\virtualenvs\app-r1mvpay6-py3.8\lib\site-packages\fastapi\applications.py", line 199, in __call__
    await super().__call__(scope, receive, send)
  File "c:\users\lucas\appdata\local\pypoetry\cache\virtualenvs\app-r1mvpay6-py3.8\lib\site-packages\starlette\applications.py", line 112, in __call__
    await self.middleware_stack(scope, receive, send)
  File "c:\users\lucas\appdata\local\pypoetry\cache\virtualenvs\app-r1mvpay6-py3.8\lib\site-packages\starlette\middleware\errors.py", line 181, in __call__
    raise exc from None
  File "c:\users\lucas\appdata\local\pypoetry\cache\virtualenvs\app-r1mvpay6-py3.8\lib\site-packages\starlette\middleware\errors.py", line 159, in __call__
    await self.app(scope, receive, _send)
  File "c:\users\lucas\appdata\local\pypoetry\cache\virtualenvs\app-r1mvpay6-py3.8\lib\site-packages\starlette\exceptions.py", line 82, in __call__
    raise exc from None
  File "c:\users\lucas\appdata\local\pypoetry\cache\virtualenvs\app-r1mvpay6-py3.8\lib\site-packages\starlette\exceptions.py", line 71, in __call__
    await self.app(scope, receive, sender)
  File "c:\users\lucas\appdata\local\pypoetry\cache\virtualenvs\app-r1mvpay6-py3.8\lib\site-packages\starlette\routing.py", line 580, in __call__
    await route.handle(scope, receive, send)
  File "c:\users\lucas\appdata\local\pypoetry\cache\virtualenvs\app-r1mvpay6-py3.8\lib\site-packages\starlette\routing.py", line 241, in handle
    await self.app(scope, receive, send)
  File "c:\users\lucas\appdata\local\pypoetry\cache\virtualenvs\app-r1mvpay6-py3.8\lib\site-packages\starlette\routing.py", line 52, in app
    response = await func(request)
  File "c:\users\lucas\appdata\local\pypoetry\cache\virtualenvs\app-r1mvpay6-py3.8\lib\site-packages\fastapi\routing.py", line 201, in app
    raw_response = await run_endpoint_function(
  File "c:\users\lucas\appdata\local\pypoetry\cache\virtualenvs\app-r1mvpay6-py3.8\lib\site-packages\fastapi\routing.py", line 148, in run_endpoint_function
    return await dependant.call(**values)
  File ".\app\main.py", line 126, in update_cat
    update_cat = cat.dict()
AttributeError: 'dict' object has no attribute 'dict'
2021-05-17 11:48:27,317 - INFO: Started server process [4340]
2021-05-17 11:48:27,317 - INFO: Waiting for application startup.
2021-05-17 11:48:27,317 - INFO: Application startup complete.
2021-05-17 11:48:36,633 - ERROR: Exception in ASGI application
Traceback (most recent call last):
  File "c:\users\lucas\appdata\local\pypoetry\cache\virtualenvs\app-r1mvpay6-py3.8\lib\site-packages\uvicorn\protocols\http\h11_impl.py", line 396, in run_asgi
    result = await app(self.scope, self.receive, self.send)
  File "c:\users\lucas\appdata\local\pypoetry\cache\virtualenvs\app-r1mvpay6-py3.8\lib\site-packages\uvicorn\middleware\proxy_headers.py", line 45, in __call__
    return await self.app(scope, receive, send)
  File "c:\users\lucas\appdata\local\pypoetry\cache\virtualenvs\app-r1mvpay6-py3.8\lib\site-packages\fastapi\applications.py", line 199, in __call__
    await super().__call__(scope, receive, send)
  File "c:\users\lucas\appdata\local\pypoetry\cache\virtualenvs\app-r1mvpay6-py3.8\lib\site-packages\starlette\applications.py", line 112, in __call__
    await self.middleware_stack(scope, receive, send)
  File "c:\users\lucas\appdata\local\pypoetry\cache\virtualenvs\app-r1mvpay6-py3.8\lib\site-packages\starlette\middleware\errors.py", line 181, in __call__
    raise exc from None
  File "c:\users\lucas\appdata\local\pypoetry\cache\virtualenvs\app-r1mvpay6-py3.8\lib\site-packages\starlette\middleware\errors.py", line 159, in __call__
    await self.app(scope, receive, _send)
  File "c:\users\lucas\appdata\local\pypoetry\cache\virtualenvs\app-r1mvpay6-py3.8\lib\site-packages\starlette\exceptions.py", line 82, in __call__
    raise exc from None
  File "c:\users\lucas\appdata\local\pypoetry\cache\virtualenvs\app-r1mvpay6-py3.8\lib\site-packages\starlette\exceptions.py", line 71, in __call__
    await self.app(scope, receive, sender)
  File "c:\users\lucas\appdata\local\pypoetry\cache\virtualenvs\app-r1mvpay6-py3.8\lib\site-packages\starlette\routing.py", line 580, in __call__
    await route.handle(scope, receive, send)
  File "c:\users\lucas\appdata\local\pypoetry\cache\virtualenvs\app-r1mvpay6-py3.8\lib\site-packages\starlette\routing.py", line 241, in handle
    await self.app(scope, receive, send)
  File "c:\users\lucas\appdata\local\pypoetry\cache\virtualenvs\app-r1mvpay6-py3.8\lib\site-packages\starlette\routing.py", line 52, in app
    response = await func(request)
  File "c:\users\lucas\appdata\local\pypoetry\cache\virtualenvs\app-r1mvpay6-py3.8\lib\site-packages\fastapi\routing.py", line 201, in app
    raw_response = await run_endpoint_function(
  File "c:\users\lucas\appdata\local\pypoetry\cache\virtualenvs\app-r1mvpay6-py3.8\lib\site-packages\fastapi\routing.py", line 148, in run_endpoint_function
    return await dependant.call(**values)
  File ".\app\main.py", line 123, in update_cat
    return cats.update(cat)
AttributeError: 'list' object has no attribute 'update'
2021-05-17 11:49:03,464 - INFO: Started server process [13964]
2021-05-17 11:49:03,464 - INFO: Waiting for application startup.
2021-05-17 11:49:03,465 - INFO: Application startup complete.
2021-05-17 11:49:04,697 - ERROR: Exception in ASGI application
Traceback (most recent call last):
  File "c:\users\lucas\appdata\local\pypoetry\cache\virtualenvs\app-r1mvpay6-py3.8\lib\site-packages\uvicorn\protocols\http\h11_impl.py", line 396, in run_asgi
    result = await app(self.scope, self.receive, self.send)
  File "c:\users\lucas\appdata\local\pypoetry\cache\virtualenvs\app-r1mvpay6-py3.8\lib\site-packages\uvicorn\middleware\proxy_headers.py", line 45, in __call__
    return await self.app(scope, receive, send)
  File "c:\users\lucas\appdata\local\pypoetry\cache\virtualenvs\app-r1mvpay6-py3.8\lib\site-packages\fastapi\applications.py", line 199, in __call__
    await super().__call__(scope, receive, send)
  File "c:\users\lucas\appdata\local\pypoetry\cache\virtualenvs\app-r1mvpay6-py3.8\lib\site-packages\starlette\applications.py", line 112, in __call__
    await self.middleware_stack(scope, receive, send)
  File "c:\users\lucas\appdata\local\pypoetry\cache\virtualenvs\app-r1mvpay6-py3.8\lib\site-packages\starlette\middleware\errors.py", line 181, in __call__
    raise exc from None
  File "c:\users\lucas\appdata\local\pypoetry\cache\virtualenvs\app-r1mvpay6-py3.8\lib\site-packages\starlette\middleware\errors.py", line 159, in __call__
    await self.app(scope, receive, _send)
  File "c:\users\lucas\appdata\local\pypoetry\cache\virtualenvs\app-r1mvpay6-py3.8\lib\site-packages\starlette\exceptions.py", line 82, in __call__
    raise exc from None
  File "c:\users\lucas\appdata\local\pypoetry\cache\virtualenvs\app-r1mvpay6-py3.8\lib\site-packages\starlette\exceptions.py", line 71, in __call__
    await self.app(scope, receive, sender)
  File "c:\users\lucas\appdata\local\pypoetry\cache\virtualenvs\app-r1mvpay6-py3.8\lib\site-packages\starlette\routing.py", line 580, in __call__
    await route.handle(scope, receive, send)
  File "c:\users\lucas\appdata\local\pypoetry\cache\virtualenvs\app-r1mvpay6-py3.8\lib\site-packages\starlette\routing.py", line 241, in handle
    await self.app(scope, receive, send)
  File "c:\users\lucas\appdata\local\pypoetry\cache\virtualenvs\app-r1mvpay6-py3.8\lib\site-packages\starlette\routing.py", line 52, in app
    response = await func(request)
  File "c:\users\lucas\appdata\local\pypoetry\cache\virtualenvs\app-r1mvpay6-py3.8\lib\site-packages\fastapi\routing.py", line 201, in app
    raw_response = await run_endpoint_function(
  File "c:\users\lucas\appdata\local\pypoetry\cache\virtualenvs\app-r1mvpay6-py3.8\lib\site-packages\fastapi\routing.py", line 148, in run_endpoint_function
    return await dependant.call(**values)
  File ".\app\main.py", line 122, in update_cat
    if cats['breed'] == breed:
TypeError: list indices must be integers or slices, not str
2021-05-17 11:49:26,304 - INFO: Started server process [16616]
2021-05-17 11:49:26,305 - INFO: Waiting for application startup.
2021-05-17 11:49:26,305 - INFO: Application startup complete.
2021-05-17 11:49:27,260 - ERROR: Exception in ASGI application
Traceback (most recent call last):
  File "c:\users\lucas\appdata\local\pypoetry\cache\virtualenvs\app-r1mvpay6-py3.8\lib\site-packages\uvicorn\protocols\http\h11_impl.py", line 396, in run_asgi
    result = await app(self.scope, self.receive, self.send)
  File "c:\users\lucas\appdata\local\pypoetry\cache\virtualenvs\app-r1mvpay6-py3.8\lib\site-packages\uvicorn\middleware\proxy_headers.py", line 45, in __call__
    return await self.app(scope, receive, send)
  File "c:\users\lucas\appdata\local\pypoetry\cache\virtualenvs\app-r1mvpay6-py3.8\lib\site-packages\fastapi\applications.py", line 199, in __call__
    await super().__call__(scope, receive, send)
  File "c:\users\lucas\appdata\local\pypoetry\cache\virtualenvs\app-r1mvpay6-py3.8\lib\site-packages\starlette\applications.py", line 112, in __call__
    await self.middleware_stack(scope, receive, send)
  File "c:\users\lucas\appdata\local\pypoetry\cache\virtualenvs\app-r1mvpay6-py3.8\lib\site-packages\starlette\middleware\errors.py", line 181, in __call__
    raise exc from None
  File "c:\users\lucas\appdata\local\pypoetry\cache\virtualenvs\app-r1mvpay6-py3.8\lib\site-packages\starlette\middleware\errors.py", line 159, in __call__
    await self.app(scope, receive, _send)
  File "c:\users\lucas\appdata\local\pypoetry\cache\virtualenvs\app-r1mvpay6-py3.8\lib\site-packages\starlette\exceptions.py", line 82, in __call__
    raise exc from None
  File "c:\users\lucas\appdata\local\pypoetry\cache\virtualenvs\app-r1mvpay6-py3.8\lib\site-packages\starlette\exceptions.py", line 71, in __call__
    await self.app(scope, receive, sender)
  File "c:\users\lucas\appdata\local\pypoetry\cache\virtualenvs\app-r1mvpay6-py3.8\lib\site-packages\starlette\routing.py", line 580, in __call__
    await route.handle(scope, receive, send)
  File "c:\users\lucas\appdata\local\pypoetry\cache\virtualenvs\app-r1mvpay6-py3.8\lib\site-packages\starlette\routing.py", line 241, in handle
    await self.app(scope, receive, send)
  File "c:\users\lucas\appdata\local\pypoetry\cache\virtualenvs\app-r1mvpay6-py3.8\lib\site-packages\starlette\routing.py", line 52, in app
    response = await func(request)
  File "c:\users\lucas\appdata\local\pypoetry\cache\virtualenvs\app-r1mvpay6-py3.8\lib\site-packages\fastapi\routing.py", line 201, in app
    raw_response = await run_endpoint_function(
  File "c:\users\lucas\appdata\local\pypoetry\cache\virtualenvs\app-r1mvpay6-py3.8\lib\site-packages\fastapi\routing.py", line 148, in run_endpoint_function
    return await dependant.call(**values)
  File ".\app\main.py", line 124, in update_cat
    return cats.update(cat)
AttributeError: 'list' object has no attribute 'update'
2021-05-17 11:49:58,818 - INFO: Started server process [12200]
2021-05-17 11:49:58,818 - INFO: Waiting for application startup.
2021-05-17 11:49:58,819 - INFO: Application startup complete.
2021-05-17 11:50:00,233 - ERROR: Exception in ASGI application
Traceback (most recent call last):
  File "c:\users\lucas\appdata\local\pypoetry\cache\virtualenvs\app-r1mvpay6-py3.8\lib\site-packages\uvicorn\protocols\http\h11_impl.py", line 396, in run_asgi
    result = await app(self.scope, self.receive, self.send)
  File "c:\users\lucas\appdata\local\pypoetry\cache\virtualenvs\app-r1mvpay6-py3.8\lib\site-packages\uvicorn\middleware\proxy_headers.py", line 45, in __call__
    return await self.app(scope, receive, send)
  File "c:\users\lucas\appdata\local\pypoetry\cache\virtualenvs\app-r1mvpay6-py3.8\lib\site-packages\fastapi\applications.py", line 199, in __call__
    await super().__call__(scope, receive, send)
  File "c:\users\lucas\appdata\local\pypoetry\cache\virtualenvs\app-r1mvpay6-py3.8\lib\site-packages\starlette\applications.py", line 112, in __call__
    await self.middleware_stack(scope, receive, send)
  File "c:\users\lucas\appdata\local\pypoetry\cache\virtualenvs\app-r1mvpay6-py3.8\lib\site-packages\starlette\middleware\errors.py", line 181, in __call__
    raise exc from None
  File "c:\users\lucas\appdata\local\pypoetry\cache\virtualenvs\app-r1mvpay6-py3.8\lib\site-packages\starlette\middleware\errors.py", line 159, in __call__
    await self.app(scope, receive, _send)
  File "c:\users\lucas\appdata\local\pypoetry\cache\virtualenvs\app-r1mvpay6-py3.8\lib\site-packages\starlette\exceptions.py", line 82, in __call__
    raise exc from None
  File "c:\users\lucas\appdata\local\pypoetry\cache\virtualenvs\app-r1mvpay6-py3.8\lib\site-packages\starlette\exceptions.py", line 71, in __call__
    await self.app(scope, receive, sender)
  File "c:\users\lucas\appdata\local\pypoetry\cache\virtualenvs\app-r1mvpay6-py3.8\lib\site-packages\starlette\routing.py", line 580, in __call__
    await route.handle(scope, receive, send)
  File "c:\users\lucas\appdata\local\pypoetry\cache\virtualenvs\app-r1mvpay6-py3.8\lib\site-packages\starlette\routing.py", line 241, in handle
    await self.app(scope, receive, send)
  File "c:\users\lucas\appdata\local\pypoetry\cache\virtualenvs\app-r1mvpay6-py3.8\lib\site-packages\starlette\routing.py", line 52, in app
    response = await func(request)
  File "c:\users\lucas\appdata\local\pypoetry\cache\virtualenvs\app-r1mvpay6-py3.8\lib\site-packages\fastapi\routing.py", line 201, in app
    raw_response = await run_endpoint_function(
  File "c:\users\lucas\appdata\local\pypoetry\cache\virtualenvs\app-r1mvpay6-py3.8\lib\site-packages\fastapi\routing.py", line 148, in run_endpoint_function
    return await dependant.call(**values)
  File ".\app\main.py", line 119, in update_cat
    return cats.update(cat)
AttributeError: 'list' object has no attribute 'update'
2021-05-17 11:52:29,644 - INFO: Started server process [8220]
2021-05-17 11:52:29,645 - INFO: Waiting for application startup.
2021-05-17 11:52:29,645 - INFO: Application startup complete.
2021-05-17 11:52:31,912 - ERROR: Exception in ASGI application
Traceback (most recent call last):
  File "c:\users\lucas\appdata\local\pypoetry\cache\virtualenvs\app-r1mvpay6-py3.8\lib\site-packages\uvicorn\protocols\http\h11_impl.py", line 396, in run_asgi
    result = await app(self.scope, self.receive, self.send)
  File "c:\users\lucas\appdata\local\pypoetry\cache\virtualenvs\app-r1mvpay6-py3.8\lib\site-packages\uvicorn\middleware\proxy_headers.py", line 45, in __call__
    return await self.app(scope, receive, send)
  File "c:\users\lucas\appdata\local\pypoetry\cache\virtualenvs\app-r1mvpay6-py3.8\lib\site-packages\fastapi\applications.py", line 199, in __call__
    await super().__call__(scope, receive, send)
  File "c:\users\lucas\appdata\local\pypoetry\cache\virtualenvs\app-r1mvpay6-py3.8\lib\site-packages\starlette\applications.py", line 112, in __call__
    await self.middleware_stack(scope, receive, send)
  File "c:\users\lucas\appdata\local\pypoetry\cache\virtualenvs\app-r1mvpay6-py3.8\lib\site-packages\starlette\middleware\errors.py", line 181, in __call__
    raise exc from None
  File "c:\users\lucas\appdata\local\pypoetry\cache\virtualenvs\app-r1mvpay6-py3.8\lib\site-packages\starlette\middleware\errors.py", line 159, in __call__
    await self.app(scope, receive, _send)
  File "c:\users\lucas\appdata\local\pypoetry\cache\virtualenvs\app-r1mvpay6-py3.8\lib\site-packages\starlette\exceptions.py", line 82, in __call__
    raise exc from None
  File "c:\users\lucas\appdata\local\pypoetry\cache\virtualenvs\app-r1mvpay6-py3.8\lib\site-packages\starlette\exceptions.py", line 71, in __call__
    await self.app(scope, receive, sender)
  File "c:\users\lucas\appdata\local\pypoetry\cache\virtualenvs\app-r1mvpay6-py3.8\lib\site-packages\starlette\routing.py", line 580, in __call__
    await route.handle(scope, receive, send)
  File "c:\users\lucas\appdata\local\pypoetry\cache\virtualenvs\app-r1mvpay6-py3.8\lib\site-packages\starlette\routing.py", line 241, in handle
    await self.app(scope, receive, send)
  File "c:\users\lucas\appdata\local\pypoetry\cache\virtualenvs\app-r1mvpay6-py3.8\lib\site-packages\starlette\routing.py", line 52, in app
    response = await func(request)
  File "c:\users\lucas\appdata\local\pypoetry\cache\virtualenvs\app-r1mvpay6-py3.8\lib\site-packages\fastapi\routing.py", line 201, in app
    raw_response = await run_endpoint_function(
  File "c:\users\lucas\appdata\local\pypoetry\cache\virtualenvs\app-r1mvpay6-py3.8\lib\site-packages\fastapi\routing.py", line 148, in run_endpoint_function
    return await dependant.call(**values)
  File ".\app\main.py", line 119, in update_cat
    return cats[cat].update(cat)
TypeError: list indices must be integers or slices, not dict
2021-05-17 11:53:17,579 - INFO: Started server process [16084]
2021-05-17 11:53:17,580 - INFO: Waiting for application startup.
2021-05-17 11:53:17,580 - INFO: Application startup complete.
2021-05-17 11:53:19,303 - WARNING: Cat not found.
2021-05-17 11:54:15,382 - INFO: Started server process [1832]
2021-05-17 11:54:15,382 - INFO: Waiting for application startup.
2021-05-17 11:54:15,383 - INFO: Application startup complete.
2021-05-17 11:54:45,311 - INFO: Started server process [15208]
2021-05-17 11:54:45,311 - INFO: Waiting for application startup.
2021-05-17 11:54:45,312 - INFO: Application startup complete.
2021-05-17 11:54:48,739 - WARNING: Cat not found.
2021-05-17 11:55:05,844 - WARNING: Cat not found.
2021-05-17 11:55:32,904 - INFO: Started server process [11436]
2021-05-17 11:55:32,905 - INFO: Waiting for application startup.
2021-05-17 11:55:32,905 - INFO: Application startup complete.
2021-05-17 11:56:46,006 - INFO: Started server process [18128]
2021-05-17 11:56:46,006 - INFO: Waiting for application startup.
2021-05-17 11:56:46,007 - INFO: Application startup complete.
2021-05-17 11:56:56,883 - ERROR: Exception in ASGI application
Traceback (most recent call last):
  File "c:\users\lucas\appdata\local\pypoetry\cache\virtualenvs\app-r1mvpay6-py3.8\lib\site-packages\uvicorn\protocols\http\h11_impl.py", line 396, in run_asgi
    result = await app(self.scope, self.receive, self.send)
  File "c:\users\lucas\appdata\local\pypoetry\cache\virtualenvs\app-r1mvpay6-py3.8\lib\site-packages\uvicorn\middleware\proxy_headers.py", line 45, in __call__
    return await self.app(scope, receive, send)
  File "c:\users\lucas\appdata\local\pypoetry\cache\virtualenvs\app-r1mvpay6-py3.8\lib\site-packages\fastapi\applications.py", line 199, in __call__
    await super().__call__(scope, receive, send)
  File "c:\users\lucas\appdata\local\pypoetry\cache\virtualenvs\app-r1mvpay6-py3.8\lib\site-packages\starlette\applications.py", line 112, in __call__
    await self.middleware_stack(scope, receive, send)
  File "c:\users\lucas\appdata\local\pypoetry\cache\virtualenvs\app-r1mvpay6-py3.8\lib\site-packages\starlette\middleware\errors.py", line 181, in __call__
    raise exc from None
  File "c:\users\lucas\appdata\local\pypoetry\cache\virtualenvs\app-r1mvpay6-py3.8\lib\site-packages\starlette\middleware\errors.py", line 159, in __call__
    await self.app(scope, receive, _send)
  File "c:\users\lucas\appdata\local\pypoetry\cache\virtualenvs\app-r1mvpay6-py3.8\lib\site-packages\starlette\exceptions.py", line 82, in __call__
    raise exc from None
  File "c:\users\lucas\appdata\local\pypoetry\cache\virtualenvs\app-r1mvpay6-py3.8\lib\site-packages\starlette\exceptions.py", line 71, in __call__
    await self.app(scope, receive, sender)
  File "c:\users\lucas\appdata\local\pypoetry\cache\virtualenvs\app-r1mvpay6-py3.8\lib\site-packages\starlette\routing.py", line 580, in __call__
    await route.handle(scope, receive, send)
  File "c:\users\lucas\appdata\local\pypoetry\cache\virtualenvs\app-r1mvpay6-py3.8\lib\site-packages\starlette\routing.py", line 241, in handle
    await self.app(scope, receive, send)
  File "c:\users\lucas\appdata\local\pypoetry\cache\virtualenvs\app-r1mvpay6-py3.8\lib\site-packages\starlette\routing.py", line 52, in app
    response = await func(request)
  File "c:\users\lucas\appdata\local\pypoetry\cache\virtualenvs\app-r1mvpay6-py3.8\lib\site-packages\fastapi\routing.py", line 201, in app
    raw_response = await run_endpoint_function(
  File "c:\users\lucas\appdata\local\pypoetry\cache\virtualenvs\app-r1mvpay6-py3.8\lib\site-packages\fastapi\routing.py", line 148, in run_endpoint_function
    return await dependant.call(**values)
  File ".\app\main.py", line 123, in update_cat
    update_cat = cat.dict()
AttributeError: 'dict' object has no attribute 'dict'
2021-05-17 11:57:58,245 - ERROR: Exception in ASGI application
Traceback (most recent call last):
  File "c:\users\lucas\appdata\local\pypoetry\cache\virtualenvs\app-r1mvpay6-py3.8\lib\site-packages\uvicorn\protocols\http\h11_impl.py", line 396, in run_asgi
    result = await app(self.scope, self.receive, self.send)
  File "c:\users\lucas\appdata\local\pypoetry\cache\virtualenvs\app-r1mvpay6-py3.8\lib\site-packages\uvicorn\middleware\proxy_headers.py", line 45, in __call__
    return await self.app(scope, receive, send)
  File "c:\users\lucas\appdata\local\pypoetry\cache\virtualenvs\app-r1mvpay6-py3.8\lib\site-packages\fastapi\applications.py", line 199, in __call__
    await super().__call__(scope, receive, send)
  File "c:\users\lucas\appdata\local\pypoetry\cache\virtualenvs\app-r1mvpay6-py3.8\lib\site-packages\starlette\applications.py", line 112, in __call__
    await self.middleware_stack(scope, receive, send)
  File "c:\users\lucas\appdata\local\pypoetry\cache\virtualenvs\app-r1mvpay6-py3.8\lib\site-packages\starlette\middleware\errors.py", line 181, in __call__
    raise exc from None
  File "c:\users\lucas\appdata\local\pypoetry\cache\virtualenvs\app-r1mvpay6-py3.8\lib\site-packages\starlette\middleware\errors.py", line 159, in __call__
    await self.app(scope, receive, _send)
  File "c:\users\lucas\appdata\local\pypoetry\cache\virtualenvs\app-r1mvpay6-py3.8\lib\site-packages\starlette\exceptions.py", line 82, in __call__
    raise exc from None
  File "c:\users\lucas\appdata\local\pypoetry\cache\virtualenvs\app-r1mvpay6-py3.8\lib\site-packages\starlette\exceptions.py", line 71, in __call__
    await self.app(scope, receive, sender)
  File "c:\users\lucas\appdata\local\pypoetry\cache\virtualenvs\app-r1mvpay6-py3.8\lib\site-packages\starlette\routing.py", line 580, in __call__
    await route.handle(scope, receive, send)
  File "c:\users\lucas\appdata\local\pypoetry\cache\virtualenvs\app-r1mvpay6-py3.8\lib\site-packages\starlette\routing.py", line 241, in handle
    await self.app(scope, receive, send)
  File "c:\users\lucas\appdata\local\pypoetry\cache\virtualenvs\app-r1mvpay6-py3.8\lib\site-packages\starlette\routing.py", line 52, in app
    response = await func(request)
  File "c:\users\lucas\appdata\local\pypoetry\cache\virtualenvs\app-r1mvpay6-py3.8\lib\site-packages\fastapi\routing.py", line 201, in app
    raw_response = await run_endpoint_function(
  File "c:\users\lucas\appdata\local\pypoetry\cache\virtualenvs\app-r1mvpay6-py3.8\lib\site-packages\fastapi\routing.py", line 148, in run_endpoint_function
    return await dependant.call(**values)
  File ".\app\main.py", line 123, in update_cat
    update_cat = cat.dict()
AttributeError: 'dict' object has no attribute 'dict'
2021-05-17 11:59:23,234 - INFO: Started server process [13200]
2021-05-17 11:59:23,234 - INFO: Waiting for application startup.
2021-05-17 11:59:23,235 - INFO: Application startup complete.
2021-05-17 11:59:31,437 - ERROR: Exception in ASGI application
Traceback (most recent call last):
  File "c:\users\lucas\appdata\local\pypoetry\cache\virtualenvs\app-r1mvpay6-py3.8\lib\site-packages\uvicorn\protocols\http\h11_impl.py", line 396, in run_asgi
    result = await app(self.scope, self.receive, self.send)
  File "c:\users\lucas\appdata\local\pypoetry\cache\virtualenvs\app-r1mvpay6-py3.8\lib\site-packages\uvicorn\middleware\proxy_headers.py", line 45, in __call__
    return await self.app(scope, receive, send)
  File "c:\users\lucas\appdata\local\pypoetry\cache\virtualenvs\app-r1mvpay6-py3.8\lib\site-packages\fastapi\applications.py", line 199, in __call__
    await super().__call__(scope, receive, send)
  File "c:\users\lucas\appdata\local\pypoetry\cache\virtualenvs\app-r1mvpay6-py3.8\lib\site-packages\starlette\applications.py", line 112, in __call__
    await self.middleware_stack(scope, receive, send)
  File "c:\users\lucas\appdata\local\pypoetry\cache\virtualenvs\app-r1mvpay6-py3.8\lib\site-packages\starlette\middleware\errors.py", line 181, in __call__
    raise exc from None
  File "c:\users\lucas\appdata\local\pypoetry\cache\virtualenvs\app-r1mvpay6-py3.8\lib\site-packages\starlette\middleware\errors.py", line 159, in __call__
    await self.app(scope, receive, _send)
  File "c:\users\lucas\appdata\local\pypoetry\cache\virtualenvs\app-r1mvpay6-py3.8\lib\site-packages\starlette\exceptions.py", line 82, in __call__
    raise exc from None
  File "c:\users\lucas\appdata\local\pypoetry\cache\virtualenvs\app-r1mvpay6-py3.8\lib\site-packages\starlette\exceptions.py", line 71, in __call__
    await self.app(scope, receive, sender)
  File "c:\users\lucas\appdata\local\pypoetry\cache\virtualenvs\app-r1mvpay6-py3.8\lib\site-packages\starlette\routing.py", line 580, in __call__
    await route.handle(scope, receive, send)
  File "c:\users\lucas\appdata\local\pypoetry\cache\virtualenvs\app-r1mvpay6-py3.8\lib\site-packages\starlette\routing.py", line 241, in handle
    await self.app(scope, receive, send)
  File "c:\users\lucas\appdata\local\pypoetry\cache\virtualenvs\app-r1mvpay6-py3.8\lib\site-packages\starlette\routing.py", line 52, in app
    response = await func(request)
  File "c:\users\lucas\appdata\local\pypoetry\cache\virtualenvs\app-r1mvpay6-py3.8\lib\site-packages\fastapi\routing.py", line 201, in app
    raw_response = await run_endpoint_function(
  File "c:\users\lucas\appdata\local\pypoetry\cache\virtualenvs\app-r1mvpay6-py3.8\lib\site-packages\fastapi\routing.py", line 148, in run_endpoint_function
    return await dependant.call(**values)
  File ".\app\main.py", line 122, in update_cat
    if cat.breed == breed:
AttributeError: 'dict' object has no attribute 'breed'
2021-05-17 11:59:50,344 - INFO: Started server process [14688]
2021-05-17 11:59:50,345 - INFO: Waiting for application startup.
2021-05-17 11:59:50,345 - INFO: Application startup complete.
2021-05-17 11:59:57,236 - ERROR: Exception in ASGI application
Traceback (most recent call last):
  File "c:\users\lucas\appdata\local\pypoetry\cache\virtualenvs\app-r1mvpay6-py3.8\lib\site-packages\uvicorn\protocols\http\h11_impl.py", line 396, in run_asgi
    result = await app(self.scope, self.receive, self.send)
  File "c:\users\lucas\appdata\local\pypoetry\cache\virtualenvs\app-r1mvpay6-py3.8\lib\site-packages\uvicorn\middleware\proxy_headers.py", line 45, in __call__
    return await self.app(scope, receive, send)
  File "c:\users\lucas\appdata\local\pypoetry\cache\virtualenvs\app-r1mvpay6-py3.8\lib\site-packages\fastapi\applications.py", line 199, in __call__
    await super().__call__(scope, receive, send)
  File "c:\users\lucas\appdata\local\pypoetry\cache\virtualenvs\app-r1mvpay6-py3.8\lib\site-packages\starlette\applications.py", line 112, in __call__
    await self.middleware_stack(scope, receive, send)
  File "c:\users\lucas\appdata\local\pypoetry\cache\virtualenvs\app-r1mvpay6-py3.8\lib\site-packages\starlette\middleware\errors.py", line 181, in __call__
    raise exc from None
  File "c:\users\lucas\appdata\local\pypoetry\cache\virtualenvs\app-r1mvpay6-py3.8\lib\site-packages\starlette\middleware\errors.py", line 159, in __call__
    await self.app(scope, receive, _send)
  File "c:\users\lucas\appdata\local\pypoetry\cache\virtualenvs\app-r1mvpay6-py3.8\lib\site-packages\starlette\exceptions.py", line 82, in __call__
    raise exc from None
  File "c:\users\lucas\appdata\local\pypoetry\cache\virtualenvs\app-r1mvpay6-py3.8\lib\site-packages\starlette\exceptions.py", line 71, in __call__
    await self.app(scope, receive, sender)
  File "c:\users\lucas\appdata\local\pypoetry\cache\virtualenvs\app-r1mvpay6-py3.8\lib\site-packages\starlette\routing.py", line 580, in __call__
    await route.handle(scope, receive, send)
  File "c:\users\lucas\appdata\local\pypoetry\cache\virtualenvs\app-r1mvpay6-py3.8\lib\site-packages\starlette\routing.py", line 241, in handle
    await self.app(scope, receive, send)
  File "c:\users\lucas\appdata\local\pypoetry\cache\virtualenvs\app-r1mvpay6-py3.8\lib\site-packages\starlette\routing.py", line 52, in app
    response = await func(request)
  File "c:\users\lucas\appdata\local\pypoetry\cache\virtualenvs\app-r1mvpay6-py3.8\lib\site-packages\fastapi\routing.py", line 201, in app
    raw_response = await run_endpoint_function(
  File "c:\users\lucas\appdata\local\pypoetry\cache\virtualenvs\app-r1mvpay6-py3.8\lib\site-packages\fastapi\routing.py", line 148, in run_endpoint_function
    return await dependant.call(**values)
  File ".\app\main.py", line 123, in update_cat
    return cats.update(cat)
AttributeError: 'list' object has no attribute 'update'
2021-05-17 12:00:24,867 - INFO: Started server process [6268]
2021-05-17 12:00:24,867 - INFO: Waiting for application startup.
2021-05-17 12:00:24,867 - INFO: Application startup complete.
2021-05-17 12:00:33,332 - WARNING: Cat not found.
2021-05-17 12:06:07,629 - INFO: Started server process [18552]
2021-05-17 12:06:07,630 - INFO: Waiting for application startup.
2021-05-17 12:06:07,630 - INFO: Application startup complete.
2021-05-17 12:06:46,659 - ERROR: Body type must be Small, Medium or Large
2021-05-17 12:07:08,695 - ERROR: Breed already exists.
2021-05-17 12:07:48,523 - WARNING: Cat not found.
2021-05-17 12:07:56,396 - ERROR: Exception in ASGI application
Traceback (most recent call last):
  File "c:\users\lucas\appdata\local\pypoetry\cache\virtualenvs\app-r1mvpay6-py3.8\lib\site-packages\uvicorn\protocols\http\h11_impl.py", line 396, in run_asgi
    result = await app(self.scope, self.receive, self.send)
  File "c:\users\lucas\appdata\local\pypoetry\cache\virtualenvs\app-r1mvpay6-py3.8\lib\site-packages\uvicorn\middleware\proxy_headers.py", line 45, in __call__
    return await self.app(scope, receive, send)
  File "c:\users\lucas\appdata\local\pypoetry\cache\virtualenvs\app-r1mvpay6-py3.8\lib\site-packages\fastapi\applications.py", line 199, in __call__
    await super().__call__(scope, receive, send)
  File "c:\users\lucas\appdata\local\pypoetry\cache\virtualenvs\app-r1mvpay6-py3.8\lib\site-packages\starlette\applications.py", line 112, in __call__
    await self.middleware_stack(scope, receive, send)
  File "c:\users\lucas\appdata\local\pypoetry\cache\virtualenvs\app-r1mvpay6-py3.8\lib\site-packages\starlette\middleware\errors.py", line 181, in __call__
    raise exc from None
  File "c:\users\lucas\appdata\local\pypoetry\cache\virtualenvs\app-r1mvpay6-py3.8\lib\site-packages\starlette\middleware\errors.py", line 159, in __call__
    await self.app(scope, receive, _send)
  File "c:\users\lucas\appdata\local\pypoetry\cache\virtualenvs\app-r1mvpay6-py3.8\lib\site-packages\starlette\exceptions.py", line 82, in __call__
    raise exc from None
  File "c:\users\lucas\appdata\local\pypoetry\cache\virtualenvs\app-r1mvpay6-py3.8\lib\site-packages\starlette\exceptions.py", line 71, in __call__
    await self.app(scope, receive, sender)
  File "c:\users\lucas\appdata\local\pypoetry\cache\virtualenvs\app-r1mvpay6-py3.8\lib\site-packages\starlette\routing.py", line 580, in __call__
    await route.handle(scope, receive, send)
  File "c:\users\lucas\appdata\local\pypoetry\cache\virtualenvs\app-r1mvpay6-py3.8\lib\site-packages\starlette\routing.py", line 241, in handle
    await self.app(scope, receive, send)
  File "c:\users\lucas\appdata\local\pypoetry\cache\virtualenvs\app-r1mvpay6-py3.8\lib\site-packages\starlette\routing.py", line 52, in app
    response = await func(request)
  File "c:\users\lucas\appdata\local\pypoetry\cache\virtualenvs\app-r1mvpay6-py3.8\lib\site-packages\fastapi\routing.py", line 201, in app
    raw_response = await run_endpoint_function(
  File "c:\users\lucas\appdata\local\pypoetry\cache\virtualenvs\app-r1mvpay6-py3.8\lib\site-packages\fastapi\routing.py", line 148, in run_endpoint_function
    return await dependant.call(**values)
  File ".\app\main.py", line 125, in update_cat
    update_cat = cat.dict()
AttributeError: 'dict' object has no attribute 'dict'
2021-05-17 12:09:03,305 - INFO: Started server process [12556]
2021-05-17 12:09:03,305 - INFO: Waiting for application startup.
2021-05-17 12:09:03,305 - INFO: Application startup complete.
2021-05-17 12:09:03,307 - ERROR: Exception in ASGI application
Traceback (most recent call last):
  File "c:\users\lucas\appdata\local\pypoetry\cache\virtualenvs\app-r1mvpay6-py3.8\lib\site-packages\uvicorn\protocols\http\h11_impl.py", line 396, in run_asgi
    result = await app(self.scope, self.receive, self.send)
  File "c:\users\lucas\appdata\local\pypoetry\cache\virtualenvs\app-r1mvpay6-py3.8\lib\site-packages\uvicorn\middleware\proxy_headers.py", line 45, in __call__
    return await self.app(scope, receive, send)
  File "c:\users\lucas\appdata\local\pypoetry\cache\virtualenvs\app-r1mvpay6-py3.8\lib\site-packages\fastapi\applications.py", line 199, in __call__
    await super().__call__(scope, receive, send)
  File "c:\users\lucas\appdata\local\pypoetry\cache\virtualenvs\app-r1mvpay6-py3.8\lib\site-packages\starlette\applications.py", line 112, in __call__
    await self.middleware_stack(scope, receive, send)
  File "c:\users\lucas\appdata\local\pypoetry\cache\virtualenvs\app-r1mvpay6-py3.8\lib\site-packages\starlette\middleware\errors.py", line 181, in __call__
    raise exc from None
  File "c:\users\lucas\appdata\local\pypoetry\cache\virtualenvs\app-r1mvpay6-py3.8\lib\site-packages\starlette\middleware\errors.py", line 159, in __call__
    await self.app(scope, receive, _send)
  File "c:\users\lucas\appdata\local\pypoetry\cache\virtualenvs\app-r1mvpay6-py3.8\lib\site-packages\starlette\exceptions.py", line 82, in __call__
    raise exc from None
  File "c:\users\lucas\appdata\local\pypoetry\cache\virtualenvs\app-r1mvpay6-py3.8\lib\site-packages\starlette\exceptions.py", line 71, in __call__
    await self.app(scope, receive, sender)
  File "c:\users\lucas\appdata\local\pypoetry\cache\virtualenvs\app-r1mvpay6-py3.8\lib\site-packages\starlette\routing.py", line 580, in __call__
    await route.handle(scope, receive, send)
  File "c:\users\lucas\appdata\local\pypoetry\cache\virtualenvs\app-r1mvpay6-py3.8\lib\site-packages\starlette\routing.py", line 241, in handle
    await self.app(scope, receive, send)
  File "c:\users\lucas\appdata\local\pypoetry\cache\virtualenvs\app-r1mvpay6-py3.8\lib\site-packages\starlette\routing.py", line 52, in app
    response = await func(request)
  File "c:\users\lucas\appdata\local\pypoetry\cache\virtualenvs\app-r1mvpay6-py3.8\lib\site-packages\fastapi\routing.py", line 201, in app
    raw_response = await run_endpoint_function(
  File "c:\users\lucas\appdata\local\pypoetry\cache\virtualenvs\app-r1mvpay6-py3.8\lib\site-packages\fastapi\routing.py", line 148, in run_endpoint_function
    return await dependant.call(**values)
  File ".\app\main.py", line 125, in update_cat
    update_cat = cat.dict()
AttributeError: 'dict' object has no attribute 'dict'
2021-05-17 12:09:05,826 - ERROR: Exception in ASGI application
Traceback (most recent call last):
  File "c:\users\lucas\appdata\local\pypoetry\cache\virtualenvs\app-r1mvpay6-py3.8\lib\site-packages\uvicorn\protocols\http\h11_impl.py", line 396, in run_asgi
    result = await app(self.scope, self.receive, self.send)
  File "c:\users\lucas\appdata\local\pypoetry\cache\virtualenvs\app-r1mvpay6-py3.8\lib\site-packages\uvicorn\middleware\proxy_headers.py", line 45, in __call__
    return await self.app(scope, receive, send)
  File "c:\users\lucas\appdata\local\pypoetry\cache\virtualenvs\app-r1mvpay6-py3.8\lib\site-packages\fastapi\applications.py", line 199, in __call__
    await super().__call__(scope, receive, send)
  File "c:\users\lucas\appdata\local\pypoetry\cache\virtualenvs\app-r1mvpay6-py3.8\lib\site-packages\starlette\applications.py", line 112, in __call__
    await self.middleware_stack(scope, receive, send)
  File "c:\users\lucas\appdata\local\pypoetry\cache\virtualenvs\app-r1mvpay6-py3.8\lib\site-packages\starlette\middleware\errors.py", line 181, in __call__
    raise exc from None
  File "c:\users\lucas\appdata\local\pypoetry\cache\virtualenvs\app-r1mvpay6-py3.8\lib\site-packages\starlette\middleware\errors.py", line 159, in __call__
    await self.app(scope, receive, _send)
  File "c:\users\lucas\appdata\local\pypoetry\cache\virtualenvs\app-r1mvpay6-py3.8\lib\site-packages\starlette\exceptions.py", line 82, in __call__
    raise exc from None
  File "c:\users\lucas\appdata\local\pypoetry\cache\virtualenvs\app-r1mvpay6-py3.8\lib\site-packages\starlette\exceptions.py", line 71, in __call__
    await self.app(scope, receive, sender)
  File "c:\users\lucas\appdata\local\pypoetry\cache\virtualenvs\app-r1mvpay6-py3.8\lib\site-packages\starlette\routing.py", line 580, in __call__
    await route.handle(scope, receive, send)
  File "c:\users\lucas\appdata\local\pypoetry\cache\virtualenvs\app-r1mvpay6-py3.8\lib\site-packages\starlette\routing.py", line 241, in handle
    await self.app(scope, receive, send)
  File "c:\users\lucas\appdata\local\pypoetry\cache\virtualenvs\app-r1mvpay6-py3.8\lib\site-packages\starlette\routing.py", line 52, in app
    response = await func(request)
  File "c:\users\lucas\appdata\local\pypoetry\cache\virtualenvs\app-r1mvpay6-py3.8\lib\site-packages\fastapi\routing.py", line 201, in app
    raw_response = await run_endpoint_function(
  File "c:\users\lucas\appdata\local\pypoetry\cache\virtualenvs\app-r1mvpay6-py3.8\lib\site-packages\fastapi\routing.py", line 148, in run_endpoint_function
    return await dependant.call(**values)
  File ".\app\main.py", line 125, in update_cat
    update_cat = cat.dict()
AttributeError: 'dict' object has no attribute 'dict'
2021-05-17 12:09:15,615 - INFO: Started server process [2088]
2021-05-17 12:09:15,615 - INFO: Waiting for application startup.
2021-05-17 12:09:15,616 - INFO: Application startup complete.
2021-05-17 12:10:23,955 - INFO: Started server process [10532]
2021-05-17 12:10:23,956 - INFO: Waiting for application startup.
2021-05-17 12:10:23,956 - INFO: Application startup complete.
2021-05-17 12:12:05,342 - INFO: Started server process [16692]
2021-05-17 12:12:05,343 - INFO: Waiting for application startup.
2021-05-17 12:12:05,343 - INFO: Application startup complete.
2021-05-17 12:12:10,641 - ERROR: Body type must be Small, Medium or Large
2021-05-17 12:14:29,343 - INFO: Started server process [17848]
2021-05-17 12:14:29,344 - INFO: Waiting for application startup.
2021-05-17 12:14:29,344 - INFO: Application startup complete.
2021-05-17 12:16:06,726 - INFO: Started server process [6328]
2021-05-17 12:16:06,726 - INFO: Waiting for application startup.
2021-05-17 12:16:06,726 - INFO: Application startup complete.
2021-05-17 12:16:50,156 - INFO: Started server process [9452]
2021-05-17 12:16:50,156 - INFO: Waiting for application startup.
2021-05-17 12:16:50,157 - INFO: Application startup complete.
2021-05-17 12:19:03,818 - INFO: Started server process [2920]
2021-05-17 12:19:03,819 - INFO: Waiting for application startup.
2021-05-17 12:19:03,819 - INFO: Application startup complete.
2021-05-17 12:19:16,256 - ERROR: Exception in ASGI application
Traceback (most recent call last):
  File "c:\users\lucas\appdata\local\pypoetry\cache\virtualenvs\app-r1mvpay6-py3.8\lib\site-packages\uvicorn\protocols\http\h11_impl.py", line 396, in run_asgi
    result = await app(self.scope, self.receive, self.send)
  File "c:\users\lucas\appdata\local\pypoetry\cache\virtualenvs\app-r1mvpay6-py3.8\lib\site-packages\uvicorn\middleware\proxy_headers.py", line 45, in __call__
    return await self.app(scope, receive, send)
  File "c:\users\lucas\appdata\local\pypoetry\cache\virtualenvs\app-r1mvpay6-py3.8\lib\site-packages\fastapi\applications.py", line 199, in __call__
    await super().__call__(scope, receive, send)
  File "c:\users\lucas\appdata\local\pypoetry\cache\virtualenvs\app-r1mvpay6-py3.8\lib\site-packages\starlette\applications.py", line 112, in __call__
    await self.middleware_stack(scope, receive, send)
  File "c:\users\lucas\appdata\local\pypoetry\cache\virtualenvs\app-r1mvpay6-py3.8\lib\site-packages\starlette\middleware\errors.py", line 181, in __call__
    raise exc from None
  File "c:\users\lucas\appdata\local\pypoetry\cache\virtualenvs\app-r1mvpay6-py3.8\lib\site-packages\starlette\middleware\errors.py", line 159, in __call__
    await self.app(scope, receive, _send)
  File "c:\users\lucas\appdata\local\pypoetry\cache\virtualenvs\app-r1mvpay6-py3.8\lib\site-packages\starlette\exceptions.py", line 82, in __call__
    raise exc from None
  File "c:\users\lucas\appdata\local\pypoetry\cache\virtualenvs\app-r1mvpay6-py3.8\lib\site-packages\starlette\exceptions.py", line 71, in __call__
    await self.app(scope, receive, sender)
  File "c:\users\lucas\appdata\local\pypoetry\cache\virtualenvs\app-r1mvpay6-py3.8\lib\site-packages\starlette\routing.py", line 580, in __call__
    await route.handle(scope, receive, send)
  File "c:\users\lucas\appdata\local\pypoetry\cache\virtualenvs\app-r1mvpay6-py3.8\lib\site-packages\starlette\routing.py", line 241, in handle
    await self.app(scope, receive, send)
  File "c:\users\lucas\appdata\local\pypoetry\cache\virtualenvs\app-r1mvpay6-py3.8\lib\site-packages\starlette\routing.py", line 52, in app
    response = await func(request)
  File "c:\users\lucas\appdata\local\pypoetry\cache\virtualenvs\app-r1mvpay6-py3.8\lib\site-packages\fastapi\routing.py", line 201, in app
    raw_response = await run_endpoint_function(
  File "c:\users\lucas\appdata\local\pypoetry\cache\virtualenvs\app-r1mvpay6-py3.8\lib\site-packages\fastapi\routing.py", line 148, in run_endpoint_function
    return await dependant.call(**values)
  File ".\app\main.py", line 155, in update_cat
    return update_cat
UnboundLocalError: local variable 'update_cat' referenced before assignment
2021-05-17 12:19:52,487 - INFO: Started server process [16336]
2021-05-17 12:19:52,488 - INFO: Waiting for application startup.
2021-05-17 12:19:52,488 - INFO: Application startup complete.
2021-05-17 12:20:45,702 - INFO: Started server process [728]
2021-05-17 12:20:45,702 - INFO: Waiting for application startup.
2021-05-17 12:20:45,702 - INFO: Application startup complete.
2021-05-17 12:21:05,446 - INFO: Cat of Siamese breed - Updated location of origin: Lol
2021-05-17 12:22:53,489 - INFO: Started server process [13664]
2021-05-17 12:22:53,490 - INFO: Waiting for application startup.
2021-05-17 12:22:53,490 - INFO: Application startup complete.
